Workbook

Sheet Questionnaire
E2: L2-2.0.8
C3: Cleveland Clinic Product Cybersecurity Level-2 Preliminary Risk Assessment Form | E3: Date Submitted
C4: Please fill out all boxes that are shaded in green, if not known, indicate NA or unknown
B6: Contact Information: | D6: Number | E6: CC ATID
B7: CC BRM Contact | D7: 50 | E7: 6658
B8: CC Engineering Contact | D8: 51 | E8: 6597
B9: CC Business Owner | D9: 52 | E9: 6399
B10: CC Business Contact | D10: 53 | E10: 6386
B11: Vendor Business Contact | C11: Michelle Flowers: michelle.flowers@perigen.com | D11: 54 | E11: 6659
B12: Vendor Technical Contact | C12: Bruno Bendavid: bruno.bendavid@perigen.com | D12: 55 | E12: 6660
B14: Product Information:
B15: Manufacturer Name | C15: PeriGen | D15: 56 | E15: 6661
B16: Model Name - Number | C16: PeriWatch Surveillance & Vigilance | D16: 57 | E16: 6381
B17: Product Website | C17: www.perigen.com | D17: 58 | E17: 6662
B18: Product Description | C18: Fetal/Maternal suiveillance and early warning system for obstetrics - Software Only. Product already live and if only being upgraded | D18: 59 | E18: 6387
B19: Hardware and Software Versions | C19: 2021.1 | D19: 61 | E19: 6664
B20: US FDA NLM DI Number | C20: [Surveillance] 00860003483510 [Vigilance HUB] B087HUB21011/$$72101001 [Vigilance Cues] B087PATT21011/$$7210100 [Vigilance Curve] B087CURV21011/$$72101000 | D20: 62 | E20: 6392
B21: MDS2 attached? | C21: Yes | D21: 63 | E21: 6665
B22: UK NHS DSPT | C22: NA | D22: 64 | E22: 6667
B23: UK Cyber Essential/Plus | C23: NA | D23: 65 | E23: 6668
B26: Please answer all green-box questions. If selecting Other, or Multiple for an answer enter the reason or explanation below the dropdown.
B29: Number | C29: Question | D29: Answer | E29: CC ATID
B30: 1 | C30: Is the product connected to an wired Ethernet network? | D30: Yes - wired Ethernet 100MB | E30: 6420
C31: Explain / Other: | D31: software only
B33: 2 | C33: Is the product connected to an wireless Ethernet network? | D33: Other - explain below | E33: 6421
C34: Explain / Other: | D34: Could be if mobile workstations/laptop used
B36: 3 | C36: If the product uses Wifi for communication, what authentication methods are supported? | D36: Other - explain below | E36: 6424
C37: Explain / Other: | D37: CC standard
B39: 4 | C39: Does this product use any wired communications protocols besides Ethernet? | D39: None | E39: 6422
C40: Explain / Other:
B42: 5 | C42: Does this product use any wireless communications protocols besides Ethernet? | D42: None | E42: 6423
C43: Explain / Other:
B45: 6 | C45: For mobile products, what type of MDM (Mobile product Mangement) is supported? | D45: None - Not a mobile device (NA) | E45: 6450
C46: Explain / Other:
B48: 7 | C48: What operating system(s) does this product use? | D48: Microsoft Windows 10 (specify version details below) | E48: 6509
C49: Explain / Other: | D49: CC supported and provided
B51: 8 | C51: Does this product store PHI, or PII or other proprietary/confidential information (including credit-card type data)? | D51: PHI is stored raw (without encryption) | E51: 6641
C52: Explain / Other: | D52: Stored on MS SQL provided/hosted by CC. MS TDE supposted for encryption at rest.
B54: 9 | C54: Does this product transmit or receive PHI, or PII or other proprietary/confidential information (including credit-card type data)? | D54: PHI is transmitted or received raw (without encryption) | E54: 6640
C55: Explain / Other: | D55: Presently received over HL7 from the EMR
...

Sheet _answers
A1: 1 | B1: 2 | C1: 3 | D1: 4 | E1: 5 | F1: 6 | G1: 7 | H1: 8 | I1: 9 | J1: 10 | K1: 11 | L1: 12 | M1: 13 | N1: 14 | O1: 15 | P1: 16 | Q1: 17 | R1: 18 | S1: 19 | T1: 20 | U1: 21 | V1: 22 | W1: 23 | X1: 24 | Y1: 25 | Z1: 26 | AA1: 27 | AB1: 28 | AC1: 29
A2: None | B2: None | C2: NA, device does not use wireless | D2: None | E2: None | F2: None - Not a mobile device (NA) | G2: NA - the device does not have an operating system | H2: There is not any PHI or PII stored | I2: There is not any PHI or PII transmitted or received | J2: No, the devices does not log any data | K2: No, there is not any data transmitted off-site | L2: No, encryption is not used for data transmission | M2: OS Patching is not supported | N2: Application software does not support patching | O2: None | P2: There is not any support after integration | Q2: No user or group support available | R2: No, outbound access is not needed | S2: No, inbound access is not needed | T2: None | U2: No or NA | V2: No, none - because the product does not support them | W2: None | X2: No, none | Y2: None | Z2: None | AA2: There is no PHI, PII, PBI, or customer sensitive configuration or data stored | AB2: No, SSO is NOT supported | AC2: No, there is not any support for 802.1x (device network authentication)
A3: Yes - wired Ethernet 10MB | B3: Yes - Wifi - 801.11b | C3: None | D3: Parallel port communication | E3: IR-DA communication | F3: None - Using an MDM is not supported | G3: Microsoft Windows 9x (specify version details below) | H3: PHI is stored raw (without encryption) | I3: PHI is transmitted or received raw (without encryption) | J3: Yes, the device logs basic operations (indicate below) | K3: Yes, the device shares PHI with a vendor server (indicate below) | L3: Yes, ALL data encrypted in compliance with industry standard (explain below) | M3: CC CAN install OS patches without vendor approval | N3: CC CAN install mfg.-issued app. patches without vendor approval | O3: Yes, required read-write to/from Epic EMR | P3: Remote monitoring (push from client to server only) | Q3: There is a single, local shared user account | R3: Yes, Outbound un-proxied(direct) traffic is needed (explain below) | S3: Yes, VPN - always connected bridged network (explain below) | T3: Mechanisms to verify Confidentiality are in place (explain below) | U3: Yes - Point of Care | V3: No, none - because the product already comes with them (explain them, how they are updated) | W3: ISO 27001 | X3: Yes, automated data-retention policy enforcement (explain policy) | Y3: The device is configured to use OS software white-listing to only allow approved apps to run | Z3: The device supports hardware change detection (explain below) | AA3: CC is responsible to manually sanitize sensitive data (is process documented?) | AB3: Yes, SAML supported (Ping Federate) - Preferred | AC3: Yes CCF can install and use a certificate on the device (explain process below)
A4: Yes - wired Ethernet 100MB | B4: Yes - Wifi - 801.11g | C4: Wireless Preshared Key (PSK) | D4: Serial/PS2 port communication | E4: Bluetooth communication | F4: The device can be managed by the CC MDM | G4: Microsoft Windows XP (specify version details below) | H4: PHI is stored using standard encryption (specify standard below) | I4: PHI is transmitted or received using standard encryption (specify standard below) | J4: Yes, the device logs detailed diagnostics | K4: Yes, the device shares PHI with a cloud server (specify provider below) | L4: Yes, configuration/secure data is encrypted in compliance with industry standard (explain below) | M4: CC CAN'T install OS patches without vendor review/approval | N4: CC CAN'T install mfg.-issued app. patches without vendor approval | O4: Yes, required read from Epic EMR | P4: Remote monitoring and patching (push and pull) | Q4: There are multiple local user accounts | R4: Yes, Outbound proxied, inspected traffic is supported | S4: Yes, VPN - always connected tunnel between device+server (explain below) | T4: Mechanisms to verify Integrity are in place (explain below) | U4: Yes - Robotic | V4: Yes, CC can install AV / anti-malware monitoring and protection | W4: ISO 27002 | X4: Yes, automated failed-authentication lockdowns (explain policy) | Y4: The device OS only allows a single specific app to be run, but needs to be configured by CC | Z4: The device supports disabling unused ports | AA4: CC will use device functions to sanitize sensitive data | AB4: Yes, Oauth supported | AC4: Yes, via supplicant software installed on the device (windows only) (explain updates in the notes)
A5: Yes - wired Ethernet 1GB | B5: Yes - Wifi - 801.11n | C5: WPA2 Enterprise/Certificate Security | D5: USB port communication | E5: NFC communication | F5: The device requires a vendor-hosted MDM (explain below) | G5: Microsoft Windows NT (specify version details below) | H5: PHI is stored using proprietary encryption (explain below) | I5: PHI is transmitted or received using proprietary encryption (explain below) | J5: Yes, the device logs login and logout events | K5: Yes, the device shares PII with a vendor server | L5: Yes, encryption handled only through secure communications channel (i.e. HTTPS, TLS, SSH, etc..) (explain below) | M5: Vendor will install OS patches (remote-push) | N5: Vendor will install approved app. patches automatically (remote-push) (app-store) | O5: Yes, optional read-write to/from Epic EMR | P5: Remote desktop required | Q5: There are multiple local user and group/role accounts | R5: Yes, Outbound access is only needed for TLS (443) 'pings' | S5: Yes, VPN - connect on demand, CC pre-approved instance (explain below) | T5: Mechanisms to verify Availability are in place (explain below) | U5: Yes - Vitals Monitor | V5: Yes, CC can install Application monitoring | W5: ISO 9001 Quality Management | X5: Yes, automated event escalation to logging-alerting (SIEM) (explain) | Y5: Other - explain below | Z5: The device supports disabling unused expansions or storage connections | AA5: CC should use a Third-party sanitization service | AB5: Yes, OpenID Connect supported | AC5: Yes, the device is wireless and should use WPA2-Enterprise/RADIUS authentication
A6: Other - explain below | B6: Yes - Wifi - 801.11af | C6: WPA3 Enterprise/Certificate Security | D6: 4-20ma | E6: 3G/4G non-ethernet | G6: Microsoft Windows 2000 (specify version details below) | H6: PII is stored raw (without encryption) | I6: PII is transmitted or received raw (without encryption) | J6: Yes, the device logs everything | K6: Yes, the device shared PII with a cloud server (specify provider below) | L6: Yes, other - explain below | M6: Vendor will install OS patches (local maintenance) | N6: Vendor will install approved app. patches on-site only (local maintenance) | O6: Yes, optional read from Epic EMR | P6: On-site contract support | Q6: There is a local administrative account only | R6: Yes, Email sending outbound only (explain SMTP requirements below) | S6: Yes, VPN - connect on demand (explain below) | T6: Mechanisms to verify Safety are in place (explain below) | U6: Yes - Implanted | V6: Yes, CC can install other endpoint protection | W6: ISO 80001 Risk Management Documentation | X6: Yes, automated safe-shutdown triggered (explain) | Z6: Multiple are supported (explain below) | AA6: Sensitive data remains and is not removed when leaving CC | AB6: Yes, other - explain below | AC6: Yes, the device supports passive mac authentication and can use RADIUS (explain below)
B7: Yes - Wifi - 801.11ac | C7: Other - explain below | D7: Industrial Control (BAC, ProfiBus, etc.) | E7: LiFi | G7: Microsoft Windows CE (specify version details below) | H7: PII is stored using standard encryption (specify standard below) | I7: PII is transmitted or received using standard encryption (specify standard below) | J7: All of the above | K7: Yes, the device shares diagnostic data with vendor server | M7: Other - explain below | N7: Other - explain below | O7: Yes, required read-write to/from PACS | P7: On-site mfg. support | Q7: Support for Active Directory-integrated users | R7: Yes, Other - explain below | S7: Yes, Internally-initiated bi-directional secure session - CC pre-approved (explain below) | T7: Mechanisms in place to verify multiple parts of CIAS (explain below) | U7: Yes - Interventional | V7: Yes, Multiple above (explain below) | W7: GDPR | X7: Yes, automated safe-mode transition of the application (explain) | Z7: Other - explain below | AA7: Other - explain below | AC7: Yes, other - explain below
B8: Yes - 4G or LTE Cellular | D8: Firewire | E8: General Audio-Signal | G8: Microsoft Windows 7 (specify version details below) | H8: PII is stored using proprietary encryption (explain below) | I8: PII is transmitted or received using proprietary encryption (explain below) | J8: Yes, other - explain below | K8: Yes, the device shares diagnostic data with cloud server (specify provider below) | O8: Yes, optional read-write to/from PACS | P8: Remote chat/phone support | Q8: Support for above + Active Directory groups or roles | S8: Yes, Internally-initiated bi-directional secure session (explain below) | U8: Yes - Direct Imagery | V8: Yes, Other - explain below | W8: NIST SP 800-53 | X8: Yes, multiple - explain below
B9: Yes - 5G Cellular | D9: Proprietary over new or existing cable | E9: General Light-Signal | G9: Microsoft Windows 7 Embedded (specify version details below) | H9: Protected business information is stored without encryption | I9: Protected business information is transmitted/received without encryption | K9: Yes, other - explain below | O9: Yes, both of the above (explain below) | P9: Other - explain below | Q9: Support for above + Active Directory policies and roles | S9: Yes, Externally-initiated bi-directional secure session - CC pre-approved (explain below) | W9: NIST Framework for Improving Critical Infrastructure | X9: Yes, other - explain below
B10: Wired AND Wireless (Failover, explain below) | D10: Signal modulation on existing infrastructure | E10: 900/1400MHz | G10: Microsoft Windows Server 2008+ (specify version details below) | H10: Protected business information is stored encrypted (explain method below) | I10: Protected business information is transmitted/received encrypted | O10: Yes, other - explain below | Q10: Support for LDAP-compliant users | S10: Yes, Externally-initiated bi-directional secure session (explain below) | W10: HIPAA Security Rule
B11: More than one | D11: Other - explain below | E11: Other - explain below | G11: Microsoft Windows 10 (specify version details below) | H11: Other - explain below | I11: Other - explain below | Q11: Support for LDAP-compliant groups or roles | S11: Yes, Other - explain below | W11: HIPAA Privacy Rule
B12: Other - explain below | G12: Microsoft Windows 10 IoT or Embedded (specify version details below) | Q12: Yes, support for other federation (explain below) | W12: Hi-Trust Deidentificiation
G13: Microsoft Windows (Other) (specify version details below) | W13: Multiple - explain below
G14: Linux - Redhat (specify version details below) | W14: Other - explain below
A15: IMPORTANT NOTE!!! | G15: Linux - Debian/Ubuntu LTS (specify version details below)
A16: DO NOT CHANGE THE CONTENT IN THIS SHEET WITHOUT PERMISSION FROM THE RISK MANAGEMENT SERVICE OWNER. RE: Synced to the Taxonomy: February 2021 | G16: Linux - BSD (specify version details below)
G17: Linux - Arch, Gentoo, etc. (specify version details below)
G18: Linux - other (specify distro and version details below)
A19: medical | G19: Unix (specify version details below)
A20: industrial | G20: Apple OSX (specify version details below)
A21: iot | G21: RTOS (Real-time Operating System) (specify OS and version details below)
A22: enterprise | G22: Apple iOS (specify version details below)
A23: other | G23: Android OS (specify version details below)
G24: Other - explain below

Sheet _tblResponses
A1: AttributeUID | B1: Q | C1: RelativeID | D1: AttributeResponse | E1: FreeText
A2: 6657 | B2: 40 | C2: 0 | D2: =Questionnaire!E3 -> Date Submitted | E2: =Questionnaire!E4 -> 0
A3: 6666 | B3: 41 | C3: 0 | D3: Version | E3: =Questionnaire!E2 -> L2-2.0.8
A4: =Questionnaire!E7 -> 6658 | B4: =Questionnaire!D7 -> 50 | C4: 0 | D4: =Questionnaire!B7 -> CC BRM Contact | E4: =Questionnaire!C7 -> 0
A5: =Questionnaire!E8 -> 6597 | B5: =Questionnaire!D8 -> 51 | C5: 0 | D5: =Questionnaire!B8 -> CC Engineering Contact | E5: =Questionnaire!C8 -> 0
A6: =Questionnaire!E9 -> 6399 | B6: =Questionnaire!D9 -> 52 | C6: 0 | D6: =Questionnaire!B9 -> CC Business Owner | E6: =Questionnaire!C9 -> 0
A7: =Questionnaire!E10 -> 6386 | B7: =Questionnaire!D10 -> 53 | C7: 0 | D7: =Questionnaire!B10 -> CC Business Contact | E7: =Questionnaire!C10 -> 0
A8: =Questionnaire!E11 -> 6659 | B8: =Questionnaire!D11 -> 54 | C8: 0 | D8: =Questionnaire!B11 -> Vendor Business Contact | E8: =Questionnaire!C11 -> Michelle Flowers: michelle.flowers@perigen.com
A9: =Questionnaire!E12 -> 6660 | B9: =Questionnaire!D12 -> 55 | C9: 0 | D9: =Questionnaire!B12 -> Vendor Technical Contact | E9: =Questionnaire!C12 -> Bruno Bendavid: bruno.bendavid@perigen.com
A10: =Questionnaire!E15 -> 6661 | B10: =Questionnaire!D15 -> 56 | C10: 0 | D10: =Questionnaire!B15 -> Manufacturer Name | E10: =Questionnaire!C15 -> PeriGen
A11: =Questionnaire!E16 -> 6381 | B11: =Questionnaire!D16 -> 57 | C11: 0 | D11: =Questionnaire!B16 -> Model Name - Number | E11: =Questionnaire!C16 -> PeriWatch Surveillance & Vigilance
A12: =Questionnaire!E17 -> 6662 | B12: =Questionnaire!D17 -> 58 | C12: 0 | D12: =Questionnaire!B17 -> Product Website | E12: =Questionnaire!C17 -> www.perigen.com
A13: =Questionnaire!E18 -> 6387 | B13: =Questionnaire!D18 -> 59 | C13: 0 | D13: =Questionnaire!B18 -> Product Description | E13: =Questionnaire!C18 -> Fetal/Maternal suiveillance and early warning system for obstetrics - Software Only. Product already live and if only being upgraded
A14: =Questionnaire!E19 -> 6664 | B14: =Questionnaire!D19 -> 61 | C14: 0 | D14: =Questionnaire!B19 -> Hardware and Software Versions | E14: =Questionnaire!C19 -> 2021.1
A15: =Questionnaire!E20 -> 6392 | B15: =Questionnaire!D20 -> 62 | C15: 0 | D15: =Questionnaire!B20 -> US FDA NLM DI Number | E15: =Questionnaire!C20 -> [Surveillance] 00860003483510 [Vigilance HUB] B087HUB21011/$$72101001 [Vigilance Cues] B087PATT21011/$$7210100 [Vigilance Curve] B087CURV21011/$$72101000
A16: =Questionnaire!E21 -> 6665 | B16: =Questionnaire!D21 -> 63 | C16: 0 | D16: =Questionnaire!B21 -> MDS2 attached? | E16: =Questionnaire!C21 -> Yes
A17: =Questionnaire!E22 -> 6667 | B17: =Questionnaire!D22 -> 64 | C17: 0 | D17: =Questionnaire!B22 -> UK NHS DSPT | E17: =Questionnaire!C22 -> NA
A18: =Questionnaire!E23 -> 6668 | B18: =Questionnaire!D23 -> 65 | C18: 0 | D18: =Questionnaire!B23 -> UK Cyber Essential/Plus | E18: =Questionnaire!C23 -> NA
A19: =Questionnaire!E30 -> 6420 | B19: =Questionnaire!B30 -> 1 | C19: =MATCH($D19,_answers!A$2:A$24,0)-1 -> 2 | D19: =Questionnaire!D30 -> Yes - wired Ethernet 100MB | E19: =Questionnaire!D31 -> software only
A20: =Questionnaire!E33 -> 6421 | B20: =Questionnaire!B33 -> 2 | C20: =MATCH($D20,_answers!B$2:B$24,0)-1 -> 10 | D20: =Questionnaire!D33 -> Other - explain below | E20: =Questionnaire!D34 -> Could be if mobile workstations/laptop used
A21: =Questionnaire!E36 -> 6424 | B21: =Questionnaire!B36 -> 3 | C21: =MATCH($D21,_answers!C$2:C$24,0)-1 -> 5 | D21: =Questionnaire!D36 -> Other - explain below | E21: =Questionnaire!D37 -> CC standard
A22: =Questionnaire!E39 -> 6422 | B22: =Questionnaire!B39 -> 4 | C22: =MATCH($D22,_answers!D$2:D$24,0)-1 -> 0 | D22: =Questionnaire!D39 -> None | E22: =Questionnaire!D40 -> 0
A23: =Questionnaire!E42 -> 6423 | B23: =Questionnaire!B42 -> 5 | C23: =MATCH($D23,_answers!E$2:E$24,0)-1 -> 0 | D23: =Questionnaire!D42 -> None | E23: =Questionnaire!D43 -> 0
A24: =Questionnaire!E45 -> 6450 | B24: =Questionnaire!B45 -> 6 | C24: =MATCH($D24,_answers!F$2:F$24,0)-1 -> 0 | D24: =Questionnaire!D45 -> None - Not a mobile device (NA) | E24: =Questionnaire!D46 -> 0
A25: =Questionnaire!E48 -> 6509 | B25: =Questionnaire!B48 -> 7 | C25: =MATCH($D25,_answers!G$2:G$24,0)-1 -> 9 | D25: =Questionnaire!D48 -> Microsoft Windows 10 (specify version details below) | E25: =Questionnaire!D49 -> CC supported and provided
A26: =Questionnaire!E51 -> 6641 | B26: =Questionnaire!B51 -> 8 | C26: =MATCH($D26,_answers!H$2:H$24,0)-1 -> 1 | D26: =Questionnaire!D51 -> PHI is stored raw (without encryption) | E26: =Questionnaire!D52 -> Stored on MS SQL provided/hosted by CC. MS TDE supposted for encryption at rest.
A27: =Questionnaire!E54 -> 6640 | B27: =Questionnaire!B54 -> 9 | C27: =MATCH($D27,_answers!I$2:I$24,0)-1 -> 1 | D27: =Questionnaire!D54 -> PHI is transmitted or received raw (without encryption) | E27: =Questionnaire!D55 -> Presently received over HL7 from the EMR
A28: =Questionnaire!E57 -> 6476 | B28: =Questionnaire!B57 -> 10 | C28: =MATCH($D28,_answers!J$2:J$24,0)-1 -> 5 | D28: =Questionnaire!D57 -> All of the above | E28: =Questionnaire!D58 -> All logs are stored in the SQL DB
A29: =Questionnaire!E60 -> 6647 | B29: =Questionnaire!B60 -> 11 | C29: =MATCH($D29,_answers!K$2:K$24,0)-1 -> 0 | D29: =Questionnaire!D60 -> No, there is not any data transmitted off-site | E29: =Questionnaire!D61 -> 0
A30: =Questionnaire!E63 -> 6637 | B30: =Questionnaire!B63 -> 12 | C30: =MATCH($D30,_answers!L$2:L$24,0)-1 -> 3 | D30: =Questionnaire!D63 -> Yes, encryption handled only through secure communications channel (i.e. HTTPS, TLS, SSH, etc..) (explain below) | E30: =Questionnaire!D64 -> 0
A31: =Questionnaire!E66 -> 6616 | B31: =Questionnaire!B66 -> 13 | C31: =MATCH($D31,_answers!M$2:M$24,0)-1 -> 1 | D31: =Questionnaire!D66 -> CC CAN install OS patches without vendor approval | E31: =Questionnaire!D67 -> 0
A32: =Questionnaire!E69 -> 6651 | B32: =Questionnaire!B69 -> 14 | C32: =MATCH($D32,_answers!N$2:N$24,0)-1 -> 4 | D32: =Questionnaire!D69 -> Vendor will install approved app. patches on-site only (local maintenance) | E32: =Questionnaire!D70 -> Coordinated with the customer
A33: =Questionnaire!E72 -> 6590 | B33: =Questionnaire!B72 -> 15 | C33: =MATCH($D33,_answers!O$2:O$24,0)-1 -> 1 | D33: =Questionnaire!D72 -> Yes, required read-write to/from Epic EMR | E33: =Questionnaire!D73 -> Only using HL7 interface
A34: =Questionnaire!E75 -> 6558 | B34: =Questionnaire!B75 -> 16 | C34: =MATCH($D34,_answers!P$2:P$24,0)-1 -> 2 | D34: =Questionnaire!D75 -> Remote monitoring and patching (push and pull) | E34: =Questionnaire!D76 -> Already present
A35: =Questionnaire!E78 -> 6513 | B35: =Questionnaire!B78 -> 17 | C35: =MATCH($D35,_answers!Q$2:Q$24,0)-1 -> 5 | D35: =Questionnaire!D78 -> Support for Active Directory-integrated users | E35: =Questionnaire!D79 -> 0
A36: =Questionnaire!E81 -> 6563 | B36: =Questionnaire!B81 -> 18 | C36: =MATCH($D36,_answers!R$2:R$24,0)-1 -> 0 | D36: =Questionnaire!D81 -> No, outbound access is not needed | E36: =Questionnaire!D85 -> Other than secure remote access
A37: =Questionnaire!E84 -> 6565 | B37: =Questionnaire!B84 -> 19 | C37: =MATCH($D37,_answers!S$2:S$24,0)-1 -> 0 | D37: =Questionnaire!D84 -> No, inbound access is not needed | E37: =Questionnaire!#REF! -> #REF!
A38: =Questionnaire!E87 -> 6389 | B38: =Questionnaire!B87 -> 20 | C38: =MATCH($D38,_answers!T$2:T$24,0)-1 -> 5 | D38: =Questionnaire!D87 -> Mechanisms in place to verify multiple parts of CIAS (explain below) | E38: =Questionnaire!D88 -> Controls are built-into the system to address some of the above including, accessc control, authorization and relying on transactional systems like MS SQL for ensure data integrity. Availability is leveraged by utilizing technologies like MS-SQL clustering, VMWare.
A39: =Questionnaire!E90 -> 6576 | B39: =Questionnaire!B90 -> 21 | C39: =MATCH($D39,_answers!U$2:U$24,0)-1 -> 1 | D39: =Questionnaire!D90 -> Yes - Point of Care | E39: =Questionnaire!D91 -> 0
A40: =Questionnaire!E93 -> 6506 | B40: =Questionnaire!B93 -> 22 | C40: =MATCH($D40,_answers!V$2:V$24,0)-1 -> 5 | D40: =Questionnaire!D93 -> Yes, Multiple above (explain below) | E40: =Questionnaire!D94 -> Workstation using the PeriGen product are CC workstations with all standard CC security methods.
...
