Workbook
Name CORL: [1]Sheet1!$A$1:$A$2
Name Risk: [2]Sheet2!$A$3:$A$7

Sheet Cover Page
A1: Vendor Security Assessment Toolkit by CORL Technologies On behalf of Saint Luke's Health System This document is PROPRIETARY and CONFIDENTIAL Information. It may not be used, disclosed or reproduced, in whole or in part, without the express written permission of CORL Technologies, LLC
A12: Version 2.14

Sheet Instructions
A1: "VPQ" - Vendor Profile Questionnaire - Vendor to Complete
B2: Please complete this questionnaire as it relates to the business relationship between your organization and Saint Luke's Health System. In the "Disclosure Permitted?" column, please indicate if CORL Technologies may disclose the responses provided herein to other CORL Technologies clients who also utilize your organization as a vendor. Allowing such disclosure may expedite future assessments.
A4: Scope
B5: Please identify all environments that will handle, process, transmit, or store Saint Luke's Health System data. Please provided a response to all questions for each identified environment.
A7: "VSQ" - Vendor Security Questionnaire - Excel worksheets 1, 2, 8, 9, 13 herein - Vendor to Complete
B8: Saint Luke's Health System is obligated by regulations and internal risk management policies to gain reasonable assurance that its vendors are protecting Saint Luke's Health System data. To meet this obligation, Saint Luke's Health System is requiring vendors to complete this Vendor Security Questionnaire (VSQ) within 15 business days of receiving it. Any questions should be directed to clientengagement@corltech.com.
A10: "Required Evidence" - Evidence and Assurances specific to Saint Luke's Health System - Vendor to Provide
B11: Upon completion of this questionnaire, CORL and Saint Luke's Health System will obtain evidence and assurances relating to the key controls as defined by the Saint Luke's Health System team. Please indicate within the "Required Evidence" sheet whether you have provided the documentation requested by CORL and Saint Luke's Health System. Instructions surrounding Evidence and Assurances: The Vendor Profile Questions (VPQ) & Scope sections include questions that relate to information about your organization and the products and services provided to Saint Luke's Health System. The Vendor Security Questionnaire (worksheets 1, 2, 8, 9, 13) section relates to questions about overall security controls at the vendor level and product level. All responses require references to documents that provide evidence of the control. If your organization has received a current security certification, please provide documentation in lieu of evidence. Relevant security certifications include, SOC 2 Type 2 (must include Security TSP), HITRUST and/or ISO 27001. Please provide certification and/or evidence documents along with this completed questionnaire to CORL Technologies within 15 business days.

Sheet Data Validation Key
A1: Response Questions | B1: Data Classifications | C1: Types of Data: | D1: Type of Access | E1: Method of Access | F1: Volume of Records | G1: Financial Value | H1: Breah Business Impact | I1: Geographic Scope | J1: Size of Organization (# of Employees) | K1: How data is stored, hosted | L1: App / Product? | M1: Vendor Age / Business Relationship Length | N1: Overrides
A2: Yes | B2: Company Data | C2: PHI | D2: Intentionally Shared | E2: Electronic | F2: Most of our patients | G2: High | H2: High | I2: International | J2: > 100,000 | K2: In the Cloud | L2: Yes | M2: < 5 Years | N2: No Override
A3: No | B3: Restricted Data | C3: PII | D3: Incidental Access | E3: Physical | F3: Most our employees | G3: Medium High | H3: Medium High | I3: National | J3: > 10,001 | K3: On our Network | L3: No | M3: 5 - 10 Years | N3: Adequate
A4: Partial | B4: Sensitive Data | C4: PCI | D4: No Access | E4: Electronic and Physical | F4: Data related to a specific business unit or division | G4: Medium | H4: Medium | I4: Single-State | J4: > 1001 | K4: At the Vendor's Location | M4: 11 - 20 Years | N4: Inadequate
A5: N/A | B5: Internal Data | C5: Intellectual property | F5: Data related to a specific service line or facility | G5: Medium Low | H5: Medium Low | J5: > 501 | M5: > 20 Years | N5: N/A
B6: Public Data | C6: PHI, PII | F6: Very specific and limited focus | G6: Low | H6: Low | J6: > 51
C7: PHI, PCI | G7: None | H7: None | J7: > 1
C8: PHI, Intellectual property
C9: PCI, PII
C10: PCI, Intellectual property
C11: PII, Intellectual property
C12: All Data types

Sheet Key Controls
A1: Key Control Question Reference # | B1: Key Control: | C1: Control Area # | D1: Example Evidence Requested:
A2: 1 | B2: Anti-virus/Malware Protection | C2: SI-3 | D2: Example evidence: malware protection program documentation
A3: 2 | B3: Encryption of Data | C3: SC-13 | D3: Please provide information on Encryption algorithms
A4: 3 | B4: Remote Access | C4: AC-17 | D4: Example evidence: procedures for reviewing and approving remote control software and remote access
A5: 4 | B5: Patch Management | C5: N/A | D5: Example evidence: documented patch management program
A6: 5 | B6: Vulnerability Management | C6: RA-5 | D6: Example evidence: vulnerability management program documentation
A7: 6 | B7: Vulnerability Management | C7: SI-2.1 | D7: Example evidence: recent vulnerability assessment results

Sheet IRQ
A1: Inherent Risk Questionnaire ("IRQ")
A2: Business Owner Name:
A3: Business Owner Title:
A4: Business Owner Email:
A5: Business Owner Phone #:
A6: Official Name of Vendor: | D6: Vendor POC Name:
A7: Vendor-specific business unit / division, if applicable: | D7: Vendor POC Title:
A8: Vendor Website Domain(s): | D8: Vendor POC Email:
A9: Date IRQ Completed: | D9: Vendor POC Phone #:
A10: Control Question # | B10: Control Name | C10: Control Questions | D10: Response | E10: Notes
A11: Inherent Risk Questions:
A12: 1 | B12: Products and Applications | C12: Does your organization use a vendor specific service/product(s)? (if "Yes" please list the names of the services/products in "Notes")
A13: 2 | B13: Accessible Data | C13: Type of data vendor will have access to:
A14: 3 | B14: Data Storage | C14: Where will the data of your organization be stored, hosted?
A15: 4 | B15: Remote Support | C15: Does vendor provide remote support?
A16: 5 | B16: Records | C16: Volume of your organization's records accessible by vendor:
A17: 6 | B17: Vendor Business Operations | C17: Geographic scope of the vendor (if vendor has international operations, please list country name(s) in "Notes"):
A18: 7 | B18: Business Relationship Length | C18: How long has the vendor been in business with your organization?
A19: 8 | B19: Annual Spend | C19: What is the annual spend on the vendor?
A20: 9 | B20: Business Associate Agreement (BAA) | C20: Is there an executed Business Associate Agreement between your organization and the vendor?
A21: 10 | B21: Information Security Agreement (ISA) | C21: Is there an executed Information Security Agreement between your organization and the vendor?
A22: 11 | B22: Security Assessment Activities | C22: Has your organization completed security assessment activities on the vendor in the past? (if "Yes" please describe the assessment scope and approximate timeframe in "Notes"):
A23: 12 | B23: Security/Performance issues | C23: Has your organization had any security findings and/or performance issues during the contract tenure with the vendor? (if "Yes" please explain in the "Notes" Column)

Sheet Vendor Profile Questionnaire
A1: Instructions: Please complete this questionnaire as it relates to the business relationship between your organization and Saint Luke's Health System. In the "Disclosure Permitted?" column, please indicate if CORL Technologies may disclose the responses provided herein to other CORL Technologies clients who also utilize PeriGen. Allowing such disclosure may expedite future assessments.
A2: Initial Vendor Profile Questionnaire - on behalf of Saint Luke's Health System
A3: Vendor Name: | B3: PeriGen Inc. | D3: Name: | E3: Bruno Bendavid
A4: Service(s) / Product(s) provided: | B4: PeriCALM Tracings | D4: Title: | E4: SVP Product Management
A5: Vendor Website Domain(s): | B5: www.perigen.com | D5: Email: | E5: bruno.bendavid@perigen.com
A6: Date Completed: | B6: 43371 | D6: Phone: | E6: 514-978-0611
A7: Vendor Discovery Questions:
A8: Questions | B8: Response | C8: Disclosure Permitted? | D8: Comments
A10: Does PeriGen have a designated leader responsible for information security? | B10: Yes | C10: Yes
A11: Name of Information Security leader? | B11: Bruno Bendavid | C11: Yes
A12: Title | B12: SVP Product Management | C12: Yes
A13: Role | B13: Product management | C13: Yes
A14: Does PeriGen employ an information security team? | B14: No | C14: Yes
A15: Number of full-time information security personnel? | C15: Yes
A16: Does PeriGen outsource information security functions to a third party? If yes, please provide the name and scope of services provided in the comments section. | B16: No | C16: Yes
A17: Does PeriGen maintain cyber liability insurance in addition to general liability insurance? If Yes, please explain how much in the comments section. | B17: Yes | C17: Yes | D17: Liability insurance is set to $5 million (both general and cyber)
A18: Does PeriGen have any employees or physical office locations outside of the United States? | B18: Yes | C18: Yes
A19: Is any Saint Luke's Health System data accessed, transmitted, or stored outside of the United States? | B19: Yes | C19: Yes | D19: (Cannot resize cell. Please read entire comment) PeriGen has technical resources residing outside the United States; Montreal, Canada and Tel Aviv, Israel. These resources may from time to time analyze and troubleshoot the solution which may require access to ePHI data via approved connections. ePHI is never copied or stored outside the US.
A20: What year was PeriGen founded? | B20: 36164 | C20: Yes
A21: Approximately how many people does PeriGen employ? | B21: <100 | C21: Yes
A22: Has PeriGen ever experienced a data breach? If so, please explain in the comments section. | B22: No | C22: Yes
A23: Is there a current BAA in place? | B23: Yes | C23: Yes
A24: Does PeriGen utilize any subcontractors with access Saint Luke's Health System data? If yes, please provide the name of the subcontractor(s) in the comments section. | B24: No | C24: Yes
A25: Please describe how your organization obtains data from Saint Luke's Health System. Include file type(s) and the medium(s) utilized to transmit the data (e.g., SFTP, Encrypted email). | B25: No data collected outside the servers hosted by the SLHS | C25: N/A

Sheet Scope
A1: Vendor Scope Questions
A2: Instructions: Please identify all environments that will handle, process, transmit, or store Saint Luke's Health System data. Please provided a response to all questions for each identified environment. | B2: Environment 1 | D2: Environment 2 | F2: Environment 3
B3: Response | C3: Comments | D3: Response | E3: Comments | F3: Response | G3: Comments
A4: Please identity the environment and provide a brief description in the comments section: | B4: PeriCALM Tracings Fetal monitoring application | C4: Dedicated and fully hospital hosted fetal monitoring, documentation, alerts, archiving and decision support
A5: Is the identified environment either of the following:
A6: Service | B6: No
A7: Product | B7: Yes
A8: What is the scope of Saint Luke's Health System records that the identified environment will transmit, process, or store? | B8: Data is only stored on hospital hosted servers. An estimate of volume of data stored on hospital servers including long term archive files is ~10GB (steady state) + 5GB per year as continuous archive files per pregnancy
A9: Please indicate if the identified environment will: | B9: If "yes", please provide details in the comments section.
A10: have access into the Saint Luke's Health System's network for remote Support | B10: Yes | C10: All access to the PeriGen servers is done via SecureLink approved infrastructure for 24/7/365 support
A11: have access into the Saint Luke's Health System's network to provide onsite support | B11: Yes | C11: PeriGen support staff have user access credentials to PeriGen server(s) only. This can be used for onsite support/operations if required by the customer
A12: Have access to infrastructure that stores or transmits Saint Luke's Health System data: | B12: No | C12: No if the question pertains to physical access
A13: Have access to a database or application that stores or transmits Saint Luke's Health System data: | B13: Yes | C13: Only to the PeriGen application DB and ADT/EMR HL7 data interfaces
A14: Receive transmitted data from Saint Luke's Health System | B14: Yes | C14: Only ADT inbound
A15: Not access Saint Luke's Health System's information | B15: No
A16: What types of Saint Luke's Health System information will the identified environment have access to: | B16: If "yes", please provide details in the comments section.
A17: PHI (Protected Health Information) | B17: Yes | C17: Only data supplied via the ADT inbound interface
A18: PII (Personally Identifiable Information) | B18: No
A19: PCI (Payment Card Industry) | B19: No
A20: Employee Information | B20: No
A21: Saint Luke's Health System Internal/Proprietary Information | B21: No
A22: Please indicate if the identified environment will utilize the following device(s) to access and/or transmit Saint Luke's Health System data: | B22: If "yes", please provide details in the comments section.
A23: Workstation | B23: Yes | C23: The PeriCALM application is installed on workstation at the bedside and nursing stations. Data is communicated between workstations and server. Not data is cached or saved on the workstation.
A24: Mobile Device | B24: No
A25: Medical Device | B25: Yes | C25: The system interfaces to fetal monitor to collect the fetal tracing, trasmit it to the main server which publishes it to all open client application instances on the network
A26: Other Method? Please explain in the comments section | B26: No
A27: Please indicate all locations where the data will be stored for the identified environment: | B27: If "yes", please provide details in the comments section.
A28: Saint Luke's Health System Data Center | B28: Yes | C28: All data is stored on the main DB/App server and possibly on the long term data archival system used by the customer at the data center. No data is stored on client workstations
A29: PeriGen Data Center | B29: No
A30: 3rd Party Data Center | B30: No
A31: Workstation | B31: No
A32: Mobile Device | B32: No
A33: Medical Device | B33: No
A34: Other? Please explain in the comments section | B34: No
A35: Does the identified environment maintain any of the following security assurances:
A36: SSAE 16 / SOC 1 Type 1 | B36: No
A37: SSAE 16 / SOC 1 Type 2 | B37: No
A38: SOC 2 Type 1 | B38: No
A39: SOC 2 Type 2 | B39: No
A40: SOC 3 | B40: No
...

Sheet Network_Architecture_Diagrams
A1: Objective: | B1: Summary/Explanation (if diagrams are not available): | C1: Evidence/Assurance
A2: Please provide any and all network architecture diagram(s) within this worksheet: | B2: See the attached document: "St Lukes Preliminary System Architecture FINAL.pdf" | C2: Please attach network architecture diagram(s) or provide screenshots below:

Sheet Connectivity Mapping
A1: Objective: | B1: Summary/Explanation: | C1: Evidence/Assurance
A2: Please provide a summary of how you will be connecting to the Saint Luke's Health System network (if applicable) | B2: Connectivity is perfromed by SecureLink which is already approved and operational. | C2: If necessary please provide supporting documentation

Sheet Required Evidence
A1: Key Control Question Reference # | B1: Key Control: | C1: Control Area # | D1: Evidence Requested: | E1: Provided to CORL? | F1: Vendor Comments
A2: MA-4.1 - MA-4.5 | B2: Non-local Maintenance | C2: MA-4 | D2: Provide policy and procedures surrounding secure remote support of the information system.

Sheet 1. Access Controls
A1: Control Question # | B1: NIST SP800-53 R4: Control # | C1: HIPAA CFR Control Reference(s) | D1: COBiT 5.0 | E1: Control Name | F1: Security Questions: | G1: Environment 1 Response: | H1: Environment 1 Comments: | I1: Environment 2 Response: | J1: Environment 2 Comments: | K1: Environment 3 Response: | L1: Environment 3 Comments:
A2: Access Control
A3: AC-3.2 | B3: N/A | E3: Access Enforcement | F3: Does the information system support role-based account management and access controls (RBAC)? | G3: Yes
A4: AC-3.3 | B4: N/A | F4: If RBAC is supported, can a customer administrator create/customize unique roles and permissions. | G4: Yes

Sheet 2. Awareness and Training
A1: Control Question # | B1: NIST SP800-53 R4: Control # | C1: HIPAA CFR Control Reference(s) | D1: TSP | E1: ISO 27001 | F1: PCI 3.0 | G1: COBiT 5.0 | H1: Control Name | I1: Security Questions: | J1: Environment 1 Response: | K1: Environment 1 Comments: | L1: Environment 2 Response: | M1: Environment 2 Comments: | N1: Environment 3 Response: | O1: Environment 3 Comments:
A2: Awareness and Training
A3: AT-1.1 | B3: AT-1 | C3: 164.308(a)(5)(i) | D3: CC3.2 | H3: Privacy, Security Awareness and Training Policy and Procedures | I3: Are there formally documented procedures for security awareness and training for this information system? If yes, please attach. | J3: Yes
A4: AT-2.1 | B4: AT-2 | C4: 164.308(a)(5)(i) 164.308(a)(5)(ii)(A) 164.308(a)(5)(ii)(B) | D4: CC2.3 CC1.3 CC2.5 | E4: A.7.2.2 A12.2.1 | H4: Privacy, Security Awareness | I4: Is basic security awareness training performed for all personnel as a part of the onboarding process? | J4: Yes
A5: AT-2.2 | F5: 6.5 9.9 9.9.3 12.6 12.6.1 12.6.2 | I5: Is it periodically performed for all users? | J5: Yes
A6: AT-3.1 | B6: AT-3 | C6: 164.308(a)(5)(i) | D6: CC2.3 CC1.3 | E6: A.7.2.2 | F6: 6.5 9.9 9.9.3 12.6 12.6.1 12.6.2 | H6: Role-Based Privacy, Security Training | I6: Is there role-based security training for personnel with assigned security roles and responsibilities for this information system before access is granted and when required by information system changes? | J6: No
A7: AT-4.1 | B7: AT-4 | C7: 164.308(a)(5)(i) | D7: CC2.3 | F7: 6.5 9.9 9.9.3 12.6 12.6.1 12.6.2 | H7: Privacy, Security Training Records | I7: Do you document and monitor information system security training activities for individuals? | J7: Yes

Sheet 8. Incident Response
A1: Control Question # | B1: NIST SP800-53 R4: Control # | C1: HIPAA CFR Control Reference(s) | D1: TSP | E1: ISO 27001 | F1: PCI 3.0 | G1: COBiT 5.0 | H1: Control Name | I1: Security Questions: | J1: Environment 1 Response: | K1: Environment 1 Comments: | L1: Environment 2 Response: | M1: Environment 2 Comments: | N1: Environment 3 Response: | O1: Environment 3 Comments:
A2: Incident Response
A3: IR-1.1 | B3: IR-1 | C3: 164.308(a)(6)(i) | D3: CC3.2 | F3: 11.1.2 12.1.1 12.10 12.10.1 12.10.2 12.10.3 12.10.4 12.10.5 | G3: DSS02.02 DSS02.04 | H3: Incident Response Policies and Procedures | I3: Are there formally documented policies and procedures for Incident Response? If yes, please attach. | J3: Yes
A4: IR-2.1 | B4: IR-2 | C4: 164.308(a)(6)(i) | D4: CC1.3 | E4: A.7.2.2 | F4: 6.5 9.9 9.9.3 12.6 12.6.1 12.6.2 | G4: DSS02.02 DSS02.04 DSS02.05 | H4: Incident Response Training | I4: Are staff provided with incident response training? | J4: Yes
A5: IR-2.2 | I5: Is incident response training unique based on the role of the individual? | J5: No
A6: IR-3.1 | B6: IR-3 | C6: 164.308(a)(6)(i) | D6: CC6.2 | F6: 11.1.2 12.10 12.10.1 12.10.2 12.10.4 | G6: DSS02.02 DSS02.04 DSS02.05 | H6: Incident Response Testing and Exercises | I6: Are incident response tests conducted? | J6: No
A7: IR-3.2 | I7: Are the incident response test results analyzed? | J7: No
A8: IR-5.1 | B8: IR-5 | C8: 164.308(a)(1)(ii)(D) 164.308(a)(6)(ii) | D8: CC6.2 | F8: 11.1.2 12.10 12.10.1 12.10.2 12.10.4 12.10.6 | G8: DSS02.02 DSS02.04 DSS02.05 DSS04.07 | H8: Incident Monitoring | I8: Are security incidents tracked and documented? | J8: Yes
A9: IR-6.1 | B9: IR-6 | C9: 164.308(a)(1)(ii)(D) 164.308(a)(6)(ii) 164.314(a)(2)(i) | D9: CC6.1 CC6.2 | E9: A.6.1.3 A.16.1.2 | F9: 12.1 | H9: Incident Reporting | I9: Are security incidents timely reported to appropriate personnel/ government authorities? | J9: Yes

Sheet 9. Maintenance
A1: Control Question # | B1: NIST SP800-53 R4: Control # | C1: HIPAA CFR Control Reference(s) | D1: TSP | E1: ISO 27001 | F1: PCI 3.0 | G1: COBiT 5.0 | H1: Control Name | I1: Security Questions: | J1: Environment 1 Response: | K1: Environment 1 Comments: | L1: Environment 2 Response: | M1: Environment 2 Comments: | N1: Environment 3 Response: | O1: Environment 3 Comments:
A2: Maintenance
A3: MA-1.1 | B3: MA-1 | C3: 164.310(a)(2)(iv) | D3: CC3.2 | F3: 12.1.1 | G3: DSS05.05 | H3: System Maintenance Policy and Procedures | I3: Are there formally documented policies and procedures for Maintenance? If yes, please attach. | J3: Yes | K3: Maintenance procedures are part of corporate QMS and are propriatary
A4: MA-2.1 | B4: MA-2 | C4: 164.310(a)(2)(iv) | D4: CC7.1 CC5.6 | E4: A.11.2.4 A.11.2.5 | G4: DSS05.05 | H4: Controlled Maintenance | I4: Are maintenance and repairs on the information system scheduled, performed, documented, and reviewed? | J4: Yes
A5: MA-2.2 | I5: Do you approve and monitor all maintenance activities? | J5: Partial | K5: By maintenance we assume two main parts: 1) Patches and enhancements to the product. This is fully monitored and controlled by our SDLC. 2) Help-desk activities. Although all processes and proceudres are approved, the actual activities by support are controlled by severity where minor issues are closed by support while higher severity items are escalated and closely controlled
A6: MA-2.3 | I6: Is management's approval required for the removal of the information system or its components for off-site maintenance and repairs? | J6: N/A | K6: PeriGen does not move, copy or remove data/systems from customer controlled instances of our system
A7: MA-2.4 | I7: Do you sanitize equipment to remove all information from associated media (e.g., hard drives) prior to removal from the facilities for off-site maintenance or repairs? | J7: N/A | K7: PeriGen does not move, copy or remove data/systems from customer controlled instances of our system
A8: MA-2.5 | I8: Do you check all potentially impacted security controls to verify that the controls are still functioning properly following maintenance or repair actions? (E.g., verify that audit logs are still functioning properly, user level of access is still appropriate.) | J8: Partial | K8: Upon update, Operations staff perfroms a validation of installation to ensure the update was perromed correctly. Logs are reviewed for errors and authentication is confirmed implicitly is order to perform this check. The user aspect of the validation is the responsibility of the customer.
A9: MA-3.1 | B9: MA-3 | D9: CC7.1CC5.6 | G9: DSS05.02 DSS05.03 DSS05.05 | H9: Maintenance Tools | I9: Does the organization approve, control and monitor information system maintenance tools? | J9: Yes
A10: MA-4.3 | B10: MA-4 | I10: Are strong authenticators/passwords used in the establishment of nonlocal maintenance and diagnostic sessions? | J10: Yes | K10: Access is perfromed via SecureLink where passowrd control and policies are enforced.
A11: MA-4.4 | I11: Do you maintain records for nonlocal maintenance and diagnostic activities? | J11: Yes | K11: We only maintain records of support incidences that were called in and where support connected to the site instance remotely.
A12: MA-4.5 | I12: Are the sessions and network connections terminated after the nonlocal maintenance has been completed? | J12: Yes
A13: MA-5.1 | B13: MA-5 | C13: 164.308(a)(3)(ii)(A) | D13: CC1.4 CC5.6 CC7.4 | G13: DSS05.02 DSS05.03 DSS05.05 | H13: Maintenance Personnel | I13: Do you authorize and maintain a list of authorized maintenance personnel? | J13: Yes | K13: Access to hospital is goverend by individual account / profile in SecureLink.
A14: MA-6.1 | B14: MA-6 | C14: 164.310(a)(2)(iv) | D14: A1.2 | H14: Timely Maintenance | I14: Is there a maintenance contract with the vendor to provide timely maintenance in the event of a failure of the information system? (E.g., spare parts on hand, response times from the vendor or other personnel, documented in OLA/SLA agreements.) | J14: Yes | K14: Only for software support services

Sheet 13. Personnel Security
A1: Control Question # | B1: NIST SP800-53 R4: Control # | C1: HIPAA CFR Control Reference(s) | D1: TSP | E1: ISO 27001 | F1: PCI 3.0 | G1: COBiT 5.0 | H1: Control Name | I1: Security Questions: | J1: Environment 1 Response: | K1: Environment 1 Comments: | L1: Environment 2 Response: | M1: Environment 2 Comments: | N1: Environment 3 Response: | O1: Environment 3 Comments:
A2: Personnel Security
A3: PS-1.1 | B3: PS-1 | C3: 164.308(a)(3)(ii)(A) 164.308(a)(3)(ii)(B) 164.308(a)(3)(ii)(C) | D3: CC3.2 | F3: 12.1.1 | H3: Personnel Security Policies and Procedures | I3: Are there formally documented policies and procedures for Personnel Security? If yes, please attach. | J3: Yes
A4: PS-2.1 | B4: PS-2 | C4: 164.308(a)(3)(ii)(B) | D4: CC1.4 | H4: Position Risk Designation | I4: Does the organization assign risk designations to all positions? | J4: No
A5: PS-2.2 | I5: Does the organization establish screening criteria for individuals filling those positions? | J5: Yes | K5: All employees are screened during job interviews
A6: PS-2.3 | I6: Does the organization review and revise position risk designations at least every three years? | J6: No
A7: PS-3.1 | B7: PS-3 | C7: 164.308(a)(3)(ii)(B) | D7: CC1.4 CC1.3 | E7: A.7.1.1 | F7: 12.7 | H7: Personnel Screening | I7: Does the organization screen individuals prior to authorizing access to the information system? | J7: Yes | K7: All employees are screened during job interviews
A8: PS-3.2 | I8: Does the organization re-screen individuals with access to the information system? | J8: No
A9: PS-4.1 | B9: PS-4 | C9: 164.308(a)(3)(ii)(C) | D9: CC5.4 CC5.2 CC5.6 A1.2 CC2.3 CC5.5 | E9: A.7.3.1 A.8.1.4 | F9: 8.1.3 | H9: Personnel Termination | I9: Does the organization have appropriate termination procedures in place to those with access to the information system? | J9: Yes
A10: PS-5.1 | B10: PS-5 | C10: 164.308(a)(3)(ii)(C) | D10: CC5.4 CC5.5 | E10: A.7.3.1 A.8.1.4 | F10: 8.1.3 | G10: DSS05.04 | H10: Personnel Transfer | I10: Does the organization have appropriate transfer procedures in place to those with access to the information system? | J10: No
A11: PS-6.1 | B11: PS-6 | C11: 164.308(a)(3)(ii)(A) 164.308(a)(3)(ii)(B) 164.308(a)(4)(ii)(B) 164.310(b) 164.310(d)(2)(iii) 164.314(a)(1) 164.314(a)(2)(i) 164.314(a)(2)(ii) | D11: CC1.4 CC5.4 CC2.3 | F11: 12.3.10 | H11: Access Agreements | I11: Does the organization have access agreements (reviewed annually) for individuals with access to the information system? | J11: Partial
A12: PS-7.1 | B12: PS-7 | C12: 164.308(a)(3)(ii)(A) 164.308(a)(4)(ii)(B) 164.308(b)(1) 164.314(a)(1) 164.314(a)(2)(i) 164.314(a)(2)(ii) | D12: CC1.4 CC1.2 CC5.5 CC4.1 | F12: 12.3 12.3.1 12.3.2 12.3.5 12.3.7 12.8.2 12.8.5 | H12: Third Party Personnel Security | I12: Does the organization have appropriate third-party access control procedures for external parties granted access to the information system? | J12: Yes
A13: PS-8.1 | B13: PS-8 | C13: 164.308(a)(1)(ii)(C) | D13: CC1.1 | F13: 12.3.1 | H13: Personnel Sanctions | I13: Does the organization have appropriate personnel sanctions policies and procedures? | J13: Yes

Sheet Override Control Env1
A1: Tier | B1: Client Tier | C1: Calc Tier | D1: Control Family | E1: Control Question # | F1: Control Name | G1: Security Question | H1: Comment | I1: Response | J1: Calc Response | K1: Override | L1: Final Response | M1: FindOverrideChanges | N1: Response: | O1: Comments/ Notes: | P1: FinalResponse | Q1: Overrides | R1: OverrideTier | S1: CheckOverrideChanges
A2: 4 | B2: 1 | C2: =IF($B2="",$A2,$B2) -> 1 | D2: Access Controls | E2: AC-3.2 | F2: Access Enforcement | G2: Does the information system support role-based account management and access controls (RBAC)? | H2: ='1. Access Controls'!$H3 -> 0 | I2: ='1. Access Controls'!$G3 -> Yes | J2: =IF($I2="Yes","Adequate",IF($I2="No","Inadequate",IF($I2="Partial","Inadequate",IF($I2="N/A","Inadequate",IF(OR($I2="",$I2=0),"Blank","Error"))))) -> Adequate | K2: No Override | L2: =IF($K2="No Override",$J2,$K2) -> Adequate | M2: =IF($J2=$L2,"","***") | N2: =IF(OR($I2="",$I2=0),"",$I2) -> Yes | O2: =IF(OR($H2="",$H2=0),"",$H2) | P2: =$L2 -> Adequate | Q2: =$K2 -> No Override | R2: =$C2 -> 1 | S2: =IF($L2=$P2,"","***")
A3: 4 | C3: =IF($B3="",$A3,$B3) -> 4 | D3: Access Controls | E3: AC-3.3 | F3: Access Enforcement | G3: If RBAC is supported, can a customer administrator create/customize unique roles and permissions. | H3: ='1. Access Controls'!$H4 -> 0 | I3: ='1. Access Controls'!$G4 -> Yes | J3: =IF($I3="Yes","Adequate",IF($I3="No","Inadequate",IF($I3="Partial","Inadequate",IF($I3="N/A","Inadequate",IF(OR($I3="",$I3=0),"Blank","Error"))))) -> Adequate | K3: No Override | L3: =IF($K3="No Override",$J3,$K3) -> Adequate | M3: =IF($J3=$L3,"","***") | N3: =IF(OR($I3="",$I3=0),"",$I3) -> Yes | O3: =IF(OR($H3="",$H3=0),"",$H3) | P3: =$L3 -> Adequate | Q3: =$K3 -> No Override | R3: =$C3 -> 4 | S3: =IF($L3=$P3,"","***")
A4: 2 | C4: =IF($B4="",$A4,$B4) -> 2 | D4: Awareness and Training | E4: AT-1.1 | F4: Security Awareness and Training Policy and Procedures | G4: Are there formally documented procedures for security awareness and training for this information system? If yes, please attach. | H4: ='2. Awareness and Training'!$K3 -> 0 | I4: ='2. Awareness and Training'!$J3 -> Yes | J4: =IF($I4="Yes","Adequate",IF($I4="No","Inadequate",IF($I4="Partial","Inadequate",IF($I4="N/A","Inadequate",IF(OR($I4="",$I4=0),"Blank","Error"))))) -> Adequate | K4: No Override | L4: =IF($K4="No Override",$J4,$K4) -> Adequate | M4: =IF($J4=$L4,"","***") | N4: =IF(OR($I4="",$I4=0),"",$I4) -> Yes | O4: =IF(OR($H4="",$H4=0),"",$H4) | P4: =$L4 -> Adequate | Q4: =$K4 -> No Override | R4: =$C4 -> 2 | S4: =IF($L4=$P4,"","***")
A5: 2 | C5: =IF($B5="",$A5,$B5) -> 2 | D5: Awareness and Training | E5: AT-2.1 | F5: Security Awareness | G5: Is basic security awareness training performed for all personnel as a part of the onboarding process? | H5: ='2. Awareness and Training'!$K4 -> 0 | I5: ='2. Awareness and Training'!$J4 -> Yes | J5: =IF($I5="Yes","Adequate",IF($I5="No","Inadequate",IF($I5="Partial","Inadequate",IF($I5="N/A","Inadequate",IF(OR($I5="",$I5=0),"Blank","Error"))))) -> Adequate | K5: No Override | L5: =IF($K5="No Override",$J5,$K5) -> Adequate | M5: =IF($J5=$L5,"","***") | N5: =IF(OR($I5="",$I5=0),"",$I5) -> Yes | O5: =IF(OR($H5="",$H5=0),"",$H5) | P5: =$L5 -> Adequate | Q5: =$K5 -> No Override | R5: =$C5 -> 2 | S5: =IF($L5=$P5,"","***")
A6: 2 | C6: =IF($B6="",$A6,$B6) -> 2 | D6: Awareness and Training | E6: AT-2.2 | F6: Security Awareness | G6: Is it periodically performed for all users? | H6: ='2. Awareness and Training'!$K5 -> 0 | I6: ='2. Awareness and Training'!$J5 -> Yes | J6: =IF($I6="Yes","Adequate",IF($I6="No","Inadequate",IF($I6="Partial","Inadequate",IF($I6="N/A","Inadequate",IF(OR($I6="",$I6=0),"Blank","Error"))))) -> Adequate | K6: No Override | L6: =IF($K6="No Override",$J6,$K6) -> Adequate | M6: =IF($J6=$L6,"","***") | N6: =IF(OR($I6="",$I6=0),"",$I6) -> Yes | O6: =IF(OR($H6="",$H6=0),"",$H6) | P6: =$L6 -> Adequate | Q6: =$K6 -> No Override | R6: =$C6 -> 2 | S6: =IF($L6=$P6,"","***")
A7: 2 | C7: =IF($B7="",$A7,$B7) -> 2 | D7: Awareness and Training | E7: AT-3.1 | F7: Role-Based Security Training | G7: Is there role-based security training for personnel with assigned security roles and responsibilities for this information system before access is granted and when required by information system changes? | H7: ='2. Awareness and Training'!$K6 -> 0 | I7: ='2. Awareness and Training'!$J6 -> No | J7: =IF($I7="Yes","Adequate",IF($I7="No","Inadequate",IF($I7="Partial","Inadequate",IF($I7="N/A","Inadequate",IF(OR($I7="",$I7=0),"Blank","Error"))))) -> Inadequate | K7: No Override | L7: =IF($K7="No Override",$J7,$K7) -> Inadequate | M7: =IF($J7=$L7,"","***") | N7: =IF(OR($I7="",$I7=0),"",$I7) -> No | O7: =IF(OR($H7="",$H7=0),"",$H7) | P7: =$L7 -> Inadequate | Q7: =$K7 -> No Override | R7: =$C7 -> 2 | S7: =IF($L7=$P7,"","***")
A8: 2 | C8: =IF($B8="",$A8,$B8) -> 2 | D8: Awareness and Training | E8: AT-4.1 | F8: Security Training Records | G8: Do you document and monitor information system security training activities for individuals? | H8: ='2. Awareness and Training'!$K7 -> 0 | I8: ='2. Awareness and Training'!$J7 -> Yes | J8: =IF($I8="Yes","Adequate",IF($I8="No","Inadequate",IF($I8="Partial","Inadequate",IF($I8="N/A","Inadequate",IF(OR($I8="",$I8=0),"Blank","Error"))))) -> Adequate | K8: No Override | L8: =IF($K8="No Override",$J8,$K8) -> Adequate | M8: =IF($J8=$L8,"","***") | N8: =IF(OR($I8="",$I8=0),"",$I8) -> Yes | O8: =IF(OR($H8="",$H8=0),"",$H8) | P8: =$L8 -> Adequate | Q8: =$K8 -> No Override | R8: =$C8 -> 2 | S8: =IF($L8=$P8,"","***")
A9: 3 | B9: 1 | C9: =IF($B9="",$A9,$B9) -> 1 | D9: Incident Response | E9: IR-1.1 | F9: Incident Response Policies and Procedures | G9: Are there formally documented policies and procedures for Incident Response? If yes, please attach. | H9: ='8. Incident Response'!$K3 -> 0 | I9: ='8. Incident Response'!$J3 -> Yes | J9: =IF($I9="Yes","Adequate",IF($I9="No","Inadequate",IF($I9="Partial","Inadequate",IF($I9="N/A","Inadequate",IF(OR($I9="",$I9=0),"Blank","Error"))))) -> Adequate | K9: No Override | L9: =IF($K9="No Override",$J9,$K9) -> Adequate | M9: =IF($J9=$L9,"","***") | N9: =IF(OR($I9="",$I9=0),"",$I9) -> Yes | O9: =IF(OR($H9="",$H9=0),"",$H9) | P9: =$L9 -> Adequate | Q9: =$K9 -> No Override | R9: =$C9 -> 1 | S9: =IF($L9=$P9,"","***")
A10: 3 | B10: 2 | C10: =IF($B10="",$A10,$B10) -> 2 | D10: Incident Response | E10: IR-2.1 | F10: Incident Response Training | G10: Are staff provided with incident response training? | H10: ='8. Incident Response'!$K4 -> 0 | I10: ='8. Incident Response'!$J4 -> Yes | J10: =IF($I10="Yes","Adequate",IF($I10="No","Inadequate",IF($I10="Partial","Inadequate",IF($I10="N/A","Inadequate",IF(OR($I10="",$I10=0),"Blank","Error"))))) -> Adequate | K10: No Override | L10: =IF($K10="No Override",$J10,$K10) -> Adequate | M10: =IF($J10=$L10,"","***") | N10: =IF(OR($I10="",$I10=0),"",$I10) -> Yes | O10: =IF(OR($H10="",$H10=0),"",$H10) | P10: =$L10 -> Adequate | Q10: =$K10 -> No Override | R10: =$C10 -> 2 | S10: =IF($L10=$P10,"","***")
A11: 3 | B11: 2 | C11: =IF($B11="",$A11,$B11) -> 2 | D11: Incident Response | E11: IR-2.2 | F11: Incident Response Training | G11: Is incident response training unique based on the role of the individual? | H11: ='8. Incident Response'!$K5 -> 0 | I11: ='8. Incident Response'!$J5 -> No | J11: =IF($I11="Yes","Adequate",IF($I11="No","Inadequate",IF($I11="Partial","Inadequate",IF($I11="N/A","Inadequate",IF(OR($I11="",$I11=0),"Blank","Error"))))) -> Inadequate | K11: No Override | L11: =IF($K11="No Override",$J11,$K11) -> Inadequate | M11: =IF($J11=$L11,"","***") | N11: =IF(OR($I11="",$I11=0),"",$I11) -> No | O11: =IF(OR($H11="",$H11=0),"",$H11) | P11: =$L11 -> Inadequate | Q11: =$K11 -> No Override | R11: =$C11 -> 2 | S11: =IF($L11=$P11,"","***")
A12: 3 | B12: 2 | C12: =IF($B12="",$A12,$B12) -> 2 | D12: Incident Response | E12: IR-3.1 | F12: Incident Response Testing and Exercises | G12: Are incident response tests conducted? | H12: ='8. Incident Response'!$K6 -> 0 | I12: ='8. Incident Response'!$J6 -> No | J12: =IF($I12="Yes","Adequate",IF($I12="No","Inadequate",IF($I12="Partial","Inadequate",IF($I12="N/A","Inadequate",IF(OR($I12="",$I12=0),"Blank","Error"))))) -> Inadequate | K12: No Override | L12: =IF($K12="No Override",$J12,$K12) -> Inadequate | M12: =IF($J12=$L12,"","***") | N12: =IF(OR($I12="",$I12=0),"",$I12) -> No | O12: =IF(OR($H12="",$H12=0),"",$H12) | P12: =$L12 -> Inadequate | Q12: =$K12 -> No Override | R12: =$C12 -> 2 | S12: =IF($L12=$P12,"","***")
A13: 3 | B13: 2 | C13: =IF($B13="",$A13,$B13) -> 2 | D13: Incident Response | E13: IR-3.2 | F13: Incident Response Testing and Exercises | G13: Are the incident response test results analyzed? | H13: ='8. Incident Response'!$K7 -> 0 | I13: ='8. Incident Response'!$J7 -> No | J13: =IF($I13="Yes","Adequate",IF($I13="No","Inadequate",IF($I13="Partial","Inadequate",IF($I13="N/A","Inadequate",IF(OR($I13="",$I13=0),"Blank","Error"))))) -> Inadequate | K13: No Override | L13: =IF($K13="No Override",$J13,$K13) -> Inadequate | M13: =IF($J13=$L13,"","***") | N13: =IF(OR($I13="",$I13=0),"",$I13) -> No | O13: =IF(OR($H13="",$H13=0),"",$H13) | P13: =$L13 -> Inadequate | Q13: =$K13 -> No Override | R13: =$C13 -> 2 | S13: =IF($L13=$P13,"","***")
A14: 3 | B14: 1 | C14: =IF($B14="",$A14,$B14) -> 1 | D14: Incident Response | E14: IR-5.1 | F14: Incident Monitoring | G14: Are security incidents tracked and documented? | H14: ='8. Incident Response'!$K8 -> 0 | I14: ='8. Incident Response'!$J8 -> Yes | J14: =IF($I14="Yes","Adequate",IF($I14="No","Inadequate",IF($I14="Partial","Inadequate",IF($I14="N/A","Inadequate",IF(OR($I14="",$I14=0),"Blank","Error"))))) -> Adequate | K14: No Override | L14: =IF($K14="No Override",$J14,$K14) -> Adequate | M14: =IF($J14=$L14,"","***") | N14: =IF(OR($I14="",$I14=0),"",$I14) -> Yes | O14: =IF(OR($H14="",$H14=0),"",$H14) | P14: =$L14 -> Adequate | Q14: =$K14 -> No Override | R14: =$C14 -> 1 | S14: =IF($L14=$P14,"","***")
A15: 3 | B15: 1 | C15: =IF($B15="",$A15,$B15) -> 1 | D15: Incident Response | E15: IR-6.1 | F15: Incident Reporting | G15: Are security incidents timely reported to appropriate personnel/ government authorities? | H15: ='8. Incident Response'!$K9 -> 0 | I15: ='8. Incident Response'!$J9 -> Yes | J15: =IF($I15="Yes","Adequate",IF($I15="No","Inadequate",IF($I15="Partial","Inadequate",IF($I15="N/A","Inadequate",IF(OR($I15="",$I15=0),"Blank","Error"))))) -> Adequate | K15: No Override | L15: =IF($K15="No Override",$J15,$K15) -> Adequate | M15: =IF($J15=$L15,"","***") | N15: =IF(OR($I15="",$I15=0),"",$I15) -> Yes | O15: =IF(OR($H15="",$H15=0),"",$H15) | P15: =$L15 -> Adequate | Q15: =$K15 -> No Override | R15: =$C15 -> 1 | S15: =IF($L15=$P15,"","***")
A16: 4 | C16: =IF($B16="",$A16,$B16) -> 4 | D16: Maintenance | E16: MA-1.1 | F16: System Maintenance Policy and Procedures | G16: Are there formally documented policies and procedures for Maintenance? If yes, please attach. | H16: ='9. Maintenance'!$K3 -> Maintenance procedures are part of corporate QMS and are propriatary | I16: ='9. Maintenance'!$J3 -> Yes | J16: =IF($I16="Yes","Adequate",IF($I16="No","Inadequate",IF($I16="Partial","Inadequate",IF($I16="N/A","Inadequate",IF(OR($I16="",$I16=0),"Blank","Error"))))) -> Adequate | K16: No Override | L16: =IF($K16="No Override",$J16,$K16) -> Adequate | M16: =IF($J16=$L16,"","***") | N16: =IF(OR($I16="",$I16=0),"",$I16) -> Yes | O16: =IF(OR($H16="",$H16=0),"",$H16) -> Maintenance procedures are part of corporate QMS and are propriatary | P16: =$L16 -> Adequate | Q16: =$K16 -> No Override | R16: =$C16 -> 4 | S16: =IF($L16=$P16,"","***")
A17: 4 | C17: =IF($B17="",$A17,$B17) -> 4 | D17: Maintenance | E17: MA-2.1 | F17: Controlled Maintenance | G17: Are maintenance and repairs on the information system scheduled, performed, documented, and reviewed? | H17: ='9. Maintenance'!$K4 -> 0 | I17: ='9. Maintenance'!$J4 -> Yes | J17: =IF($I17="Yes","Adequate",IF($I17="No","Inadequate",IF($I17="Partial","Inadequate",IF($I17="N/A","Inadequate",IF(OR($I17="",$I17=0),"Blank","Error"))))) -> Adequate | K17: No Override | L17: =IF($K17="No Override",$J17,$K17) -> Adequate | M17: =IF($J17=$L17,"","***") | N17: =IF(OR($I17="",$I17=0),"",$I17) -> Yes | O17: =IF(OR($H17="",$H17=0),"",$H17) | P17: =$L17 -> Adequate | Q17: =$K17 -> No Override | R17: =$C17 -> 4 | S17: =IF($L17=$P17,"","***")
A18: 4 | C18: =IF($B18="",$A18,$B18) -> 4 | D18: Maintenance | E18: MA-2.2 | F18: Controlled Maintenance | G18: Do you approve and monitor all maintenance activities? | H18: ='9. Maintenance'!$K5 -> By maintenance we assume two main parts: 1) Patches and enhancements to the product. This is fully monitored and controlled by our SDLC. 2) Help-desk activities. Although all processes and proceudres are approved, the actual activities by support are controlled by severity where minor issues are closed by support while higher severity items are escalated and closely controlled | I18: ='9. Maintenance'!$J5 -> Partial | J18: =IF($I18="Yes","Adequate",IF($I18="No","Inadequate",IF($I18="Partial","Inadequate",IF($I18="N/A","Inadequate",IF(OR($I18="",$I18=0),"Blank","Error"))))) -> Inadequate | K18: No Override | L18: =IF($K18="No Override",$J18,$K18) -> Inadequate | M18: =IF($J18=$L18,"","***") | N18: =IF(OR($I18="",$I18=0),"",$I18) -> Partial | O18: =IF(OR($H18="",$H18=0),"",$H18) -> By maintenance we assume two main parts: 1) Patches and enhancements to the product. This is fully monitored and controlled by our SDLC. 2) Help-desk activities. Although all processes and proceudres are approved, the actual activities by support are controlled by severity where minor issues are closed by support while higher severity items are escalated and closely controlled | P18: =$L18 -> Inadequate | Q18: =$K18 -> No Override | R18: =$C18 -> 4 | S18: =IF($L18=$P18,"","***")
A19: 4 | C19: =IF($B19="",$A19,$B19) -> 4 | D19: Maintenance | E19: MA-2.3 | F19: Controlled Maintenance | G19: Is management's approval required for the removal of the information system or its components for off-site maintenance and repairs? | H19: ='9. Maintenance'!$K6 -> PeriGen does not move, copy or remove data/systems from customer controlled instances of our system | I19: ='9. Maintenance'!$J6 -> N/A | J19: =IF($I19="Yes","Adequate",IF($I19="No","Inadequate",IF($I19="Partial","Inadequate",IF($I19="N/A","Inadequate",IF(OR($I19="",$I19=0),"Blank","Error"))))) -> Inadequate | K19: No Override | L19: =IF($K19="No Override",$J19,$K19) -> Inadequate | M19: =IF($J19=$L19,"","***") | N19: =IF(OR($I19="",$I19=0),"",$I19) -> N/A | O19: =IF(OR($H19="",$H19=0),"",$H19) -> PeriGen does not move, copy or remove data/systems from customer controlled instances of our system | P19: =$L19 -> Inadequate | Q19: =$K19 -> No Override | R19: =$C19 -> 4 | S19: =IF($L19=$P19,"","***")
A20: 4 | B20: 1 | C20: =IF($B20="",$A20,$B20) -> 1 | D20: Maintenance | E20: MA-2.4 | F20: Controlled Maintenance | G20: Do you sanitize equipment to remove all information from associated media (e.g., hard drives) prior to removal from the facilities for off-site maintenance or repairs? | H20: ='9. Maintenance'!$K7 -> PeriGen does not move, copy or remove data/systems from customer controlled instances of our system | I20: ='9. Maintenance'!$J7 -> N/A | J20: =IF($I20="Yes","Adequate",IF($I20="No","Inadequate",IF($I20="Partial","Inadequate",IF($I20="N/A","Inadequate",IF(OR($I20="",$I20=0),"Blank","Error"))))) -> Inadequate | K20: No Override | L20: =IF($K20="No Override",$J20,$K20) -> Inadequate | M20: =IF($J20=$L20,"","***") | N20: =IF(OR($I20="",$I20=0),"",$I20) -> N/A | O20: =IF(OR($H20="",$H20=0),"",$H20) -> PeriGen does not move, copy or remove data/systems from customer controlled instances of our system | P20: =$L20 -> Inadequate | Q20: =$K20 -> No Override | R20: =$C20 -> 1 | S20: =IF($L20=$P20,"","***")
A21: 4 | C21: =IF($B21="",$A21,$B21) -> 4 | D21: Maintenance | E21: MA-2.5 | F21: Controlled Maintenance | G21: Do you check all potentially impacted security controls to verify that the controls are still functioning properly following maintenance or repair actions? (E.g., verify that audit logs are still functioning properly, user level of access is still appropriate.) | H21: ='9. Maintenance'!$K8 -> Upon update, Operations staff perfroms a validation of installation to ensure the update was perromed correctly. Logs are reviewed for errors and authentication is confirmed implicitly is order to perform this check. The user aspect of the validation is the responsibility of the customer. | I21: ='9. Maintenance'!$J8 -> Partial | J21: =IF($I21="Yes","Adequate",IF($I21="No","Inadequate",IF($I21="Partial","Inadequate",IF($I21="N/A","Inadequate",IF(OR($I21="",$I21=0),"Blank","Error"))))) -> Inadequate | K21: No Override | L21: =IF($K21="No Override",$J21,$K21) -> Inadequate | M21: =IF($J21=$L21,"","***") | N21: =IF(OR($I21="",$I21=0),"",$I21) -> Partial | O21: =IF(OR($H21="",$H21=0),"",$H21) -> Upon update, Operations staff perfroms a validation of installation to ensure the update was perromed correctly. Logs are reviewed for errors and authentication is confirmed implicitly is order to perform this check. The user aspect of the validation is the responsibility of the customer. | P21: =$L21 -> Inadequate | Q21: =$K21 -> No Override | R21: =$C21 -> 4 | S21: =IF($L21=$P21,"","***")
A22: 4 | C22: =IF($B22="",$A22,$B22) -> 4 | D22: Maintenance | E22: MA-3.1 | F22: Maintenance Tools | G22: Does the organization approve, control and monitor information system maintenance tools? | H22: ='9. Maintenance'!$K9 -> 0 | I22: ='9. Maintenance'!$J9 -> Yes | J22: =IF($I22="Yes","Adequate",IF($I22="No","Inadequate",IF($I22="Partial","Inadequate",IF($I22="N/A","Inadequate",IF(OR($I22="",$I22=0),"Blank","Error"))))) -> Adequate | K22: No Override | L22: =IF($K22="No Override",$J22,$K22) -> Adequate | M22: =IF($J22=$L22,"","***") | N22: =IF(OR($I22="",$I22=0),"",$I22) -> Yes | O22: =IF(OR($H22="",$H22=0),"",$H22) | P22: =$L22 -> Adequate | Q22: =$K22 -> No Override | R22: =$C22 -> 4 | S22: =IF($L22=$P22,"","***")
A23: 1 | B23: 1 | C23: =IF($B23="",$A23,$B23) -> 1 | D23: Maintenance | E23: MA-4.3 | F23: Nonlocal Maintenance | G23: Are strong authenticators/passwords used in the establishment of nonlocal maintenance and diagnostic sessions? | H23: ='9. Maintenance'!$K10 -> Access is perfromed via SecureLink where passowrd control and policies are enforced. | I23: ='9. Maintenance'!$J10 -> Yes | J23: =IF($I23="Yes","Adequate",IF($I23="No","Inadequate",IF($I23="Partial","Inadequate",IF($I23="N/A","Inadequate",IF(OR($I23="",$I23=0),"Blank","Error"))))) -> Adequate | K23: No Override | L23: =IF($K23="No Override",$J23,$K23) -> Adequate | M23: =IF($J23=$L23,"","***") | N23: =IF(OR($I23="",$I23=0),"",$I23) -> Yes | O23: =IF(OR($H23="",$H23=0),"",$H23) -> Access is perfromed via SecureLink where passowrd control and policies are enforced. | P23: =$L23 -> Adequate | Q23: =$K23 -> No Override | R23: =$C23 -> 1 | S23: =IF($L23=$P23,"","***")
A24: 1 | B24: 2 | C24: =IF($B24="",$A24,$B24) -> 2 | D24: Maintenance | E24: MA-4.4 | F24: Nonlocal Maintenance | G24: Do you maintain records for nonlocal maintenance and diagnostic activities? | H24: ='9. Maintenance'!$K11 -> We only maintain records of support incidences that were called in and where support connected to the site instance remotely. | I24: ='9. Maintenance'!$J11 -> Yes | J24: =IF($I24="Yes","Adequate",IF($I24="No","Inadequate",IF($I24="Partial","Inadequate",IF($I24="N/A","Inadequate",IF(OR($I24="",$I24=0),"Blank","Error"))))) -> Adequate | K24: No Override | L24: =IF($K24="No Override",$J24,$K24) -> Adequate | M24: =IF($J24=$L24,"","***") | N24: =IF(OR($I24="",$I24=0),"",$I24) -> Yes | O24: =IF(OR($H24="",$H24=0),"",$H24) -> We only maintain records of support incidences that were called in and where support connected to the site instance remotely. | P24: =$L24 -> Adequate | Q24: =$K24 -> No Override | R24: =$C24 -> 2 | S24: =IF($L24=$P24,"","***")
A25: 1 | B25: 2 | C25: =IF($B25="",$A25,$B25) -> 2 | D25: Maintenance | E25: MA-4.5 | F25: Nonlocal Maintenance | G25: Are the sessions and network connections terminated after the nonlocal maintenance has been completed? | H25: ='9. Maintenance'!$K12 -> 0 | I25: ='9. Maintenance'!$J12 -> Yes | J25: =IF($I25="Yes","Adequate",IF($I25="No","Inadequate",IF($I25="Partial","Inadequate",IF($I25="N/A","Inadequate",IF(OR($I25="",$I25=0),"Blank","Error"))))) -> Adequate | K25: No Override | L25: =IF($K25="No Override",$J25,$K25) -> Adequate | M25: =IF($J25=$L25,"","***") | N25: =IF(OR($I25="",$I25=0),"",$I25) -> Yes | O25: =IF(OR($H25="",$H25=0),"",$H25) | P25: =$L25 -> Adequate | Q25: =$K25 -> No Override | R25: =$C25 -> 2 | S25: =IF($L25=$P25,"","***")
A26: 4 | C26: =IF($B26="",$A26,$B26) -> 4 | D26: Maintenance | E26: MA-5.1 | F26: Maintenance Personnel | G26: Do you authorize and maintain a list of authorized maintenance personnel? | H26: ='9. Maintenance'!$K13 -> Access to hospital is goverend by individual account / profile in SecureLink. | I26: ='9. Maintenance'!$J13 -> Yes | J26: =IF($I26="Yes","Adequate",IF($I26="No","Inadequate",IF($I26="Partial","Inadequate",IF($I26="N/A","Inadequate",IF(OR($I26="",$I26=0),"Blank","Error"))))) -> Adequate | K26: No Override | L26: =IF($K26="No Override",$J26,$K26) -> Adequate | M26: =IF($J26=$L26,"","***") | N26: =IF(OR($I26="",$I26=0),"",$I26) -> Yes | O26: =IF(OR($H26="",$H26=0),"",$H26) -> Access to hospital is goverend by individual account / profile in SecureLink. | P26: =$L26 -> Adequate | Q26: =$K26 -> No Override | R26: =$C26 -> 4 | S26: =IF($L26=$P26,"","***")
A27: 4 | C27: =IF($B27="",$A27,$B27) -> 4 | D27: Maintenance | E27: MA-6.1 | F27: Timely Maintenance | G27: Is there a maintenance contract with the vendor to provide timely maintenance in the event of a failure of the information system? (E.g., spare parts on hand, response times from the vendor or other personnel, documented in OLA/SLA agreements.) | H27: ='9. Maintenance'!$K14 -> Only for software support services | I27: ='9. Maintenance'!$J14 -> Yes | J27: =IF($I27="Yes","Adequate",IF($I27="No","Inadequate",IF($I27="Partial","Inadequate",IF($I27="N/A","Inadequate",IF(OR($I27="",$I27=0),"Blank","Error"))))) -> Adequate | K27: No Override | L27: =IF($K27="No Override",$J27,$K27) -> Adequate | M27: =IF($J27=$L27,"","***") | N27: =IF(OR($I27="",$I27=0),"",$I27) -> Yes | O27: =IF(OR($H27="",$H27=0),"",$H27) -> Only for software support services | P27: =$L27 -> Adequate | Q27: =$K27 -> No Override | R27: =$C27 -> 4 | S27: =IF($L27=$P27,"","***")
A28: 4 | C28: =IF($B28="",$A28,$B28) -> 4 | D28: Personnel Security | E28: PS-1.1 | F28: Personnel Security Policies and Procedures | G28: Are there formally documented policies and procedures for Personnel Security? If yes, please attach. | H28: ='13. Personnel Security'!$K3 -> 0 | I28: ='13. Personnel Security'!$J3 -> Yes | J28: =IF($I28="Yes","Adequate",IF($I28="No","Inadequate",IF($I28="Partial","Inadequate",IF($I28="N/A","Inadequate",IF(OR($I28="",$I28=0),"Blank","Error"))))) -> Adequate | K28: No Override | L28: =IF($K28="No Override",$J28,$K28) -> Adequate | M28: =IF($J28=$L28,"","***") | N28: =IF(OR($I28="",$I28=0),"",$I28) -> Yes | O28: =IF(OR($H28="",$H28=0),"",$H28) | P28: =$L28 -> Adequate | Q28: =$K28 -> No Override | R28: =$C28 -> 4 | S28: =IF($L28=$P28,"","***")
A29: 4 | C29: =IF($B29="",$A29,$B29) -> 4 | D29: Personnel Security | E29: PS-2.1 | F29: Position Risk Designation | G29: Does the organization assign risk designations to all positions? | H29: ='13. Personnel Security'!$K4 -> 0 | I29: ='13. Personnel Security'!$J4 -> No | J29: =IF($I29="Yes","Adequate",IF($I29="No","Inadequate",IF($I29="Partial","Inadequate",IF($I29="N/A","Inadequate",IF(OR($I29="",$I29=0),"Blank","Error"))))) -> Inadequate | K29: No Override | L29: =IF($K29="No Override",$J29,$K29) -> Inadequate | M29: =IF($J29=$L29,"","***") | N29: =IF(OR($I29="",$I29=0),"",$I29) -> No | O29: =IF(OR($H29="",$H29=0),"",$H29) | P29: =$L29 -> Inadequate | Q29: =$K29 -> No Override | R29: =$C29 -> 4 | S29: =IF($L29=$P29,"","***")
A30: 4 | C30: =IF($B30="",$A30,$B30) -> 4 | D30: Personnel Security | E30: PS-2.2 | F30: Position Risk Designation | G30: Does the organization establish screening criteria for individuals filling those positions? | H30: ='13. Personnel Security'!$K5 -> All employees are screened during job interviews | I30: ='13. Personnel Security'!$J5 -> Yes | J30: =IF($I30="Yes","Adequate",IF($I30="No","Inadequate",IF($I30="Partial","Inadequate",IF($I30="N/A","Inadequate",IF(OR($I30="",$I30=0),"Blank","Error"))))) -> Adequate | K30: No Override | L30: =IF($K30="No Override",$J30,$K30) -> Adequate | M30: =IF($J30=$L30,"","***") | N30: =IF(OR($I30="",$I30=0),"",$I30) -> Yes | O30: =IF(OR($H30="",$H30=0),"",$H30) -> All employees are screened during job interviews | P30: =$L30 -> Adequate | Q30: =$K30 -> No Override | R30: =$C30 -> 4 | S30: =IF($L30=$P30,"","***")
A31: 4 | C31: =IF($B31="",$A31,$B31) -> 4 | D31: Personnel Security | E31: PS-2.3 | F31: Position Risk Designation | G31: Does the organization review and revise position risk designations at least every three years? | H31: ='13. Personnel Security'!$K6 -> 0 | I31: ='13. Personnel Security'!$J6 -> No | J31: =IF($I31="Yes","Adequate",IF($I31="No","Inadequate",IF($I31="Partial","Inadequate",IF($I31="N/A","Inadequate",IF(OR($I31="",$I31=0),"Blank","Error"))))) -> Inadequate | K31: No Override | L31: =IF($K31="No Override",$J31,$K31) -> Inadequate | M31: =IF($J31=$L31,"","***") | N31: =IF(OR($I31="",$I31=0),"",$I31) -> No | O31: =IF(OR($H31="",$H31=0),"",$H31) | P31: =$L31 -> Inadequate | Q31: =$K31 -> No Override | R31: =$C31 -> 4 | S31: =IF($L31=$P31,"","***")
A32: 4 | B32: 1 | C32: =IF($B32="",$A32,$B32) -> 1 | D32: Personnel Security | E32: PS-3.1 | F32: Personnel Screening | G32: Does the organization screen individuals prior to authorizing access to the information system? | H32: ='13. Personnel Security'!$K7 -> All employees are screened during job interviews | I32: ='13. Personnel Security'!$J7 -> Yes | J32: =IF($I32="Yes","Adequate",IF($I32="No","Inadequate",IF($I32="Partial","Inadequate",IF($I32="N/A","Inadequate",IF(OR($I32="",$I32=0),"Blank","Error"))))) -> Adequate | K32: No Override | L32: =IF($K32="No Override",$J32,$K32) -> Adequate | M32: =IF($J32=$L32,"","***") | N32: =IF(OR($I32="",$I32=0),"",$I32) -> Yes | O32: =IF(OR($H32="",$H32=0),"",$H32) -> All employees are screened during job interviews | P32: =$L32 -> Adequate | Q32: =$K32 -> No Override | R32: =$C32 -> 1 | S32: =IF($L32=$P32,"","***")
A33: 4 | B33: 1 | C33: =IF($B33="",$A33,$B33) -> 1 | D33: Personnel Security | E33: PS-3.2 | F33: Personnel Screening | G33: Does the organization re-screen individuals with access to the information system? | H33: ='13. Personnel Security'!$K8 -> 0 | I33: ='13. Personnel Security'!$J8 -> No | J33: =IF($I33="Yes","Adequate",IF($I33="No","Inadequate",IF($I33="Partial","Inadequate",IF($I33="N/A","Inadequate",IF(OR($I33="",$I33=0),"Blank","Error"))))) -> Inadequate | K33: No Override | L33: =IF($K33="No Override",$J33,$K33) -> Inadequate | M33: =IF($J33=$L33,"","***") | N33: =IF(OR($I33="",$I33=0),"",$I33) -> No | O33: =IF(OR($H33="",$H33=0),"",$H33) | P33: =$L33 -> Inadequate | Q33: =$K33 -> No Override | R33: =$C33 -> 1 | S33: =IF($L33=$P33,"","***")
A34: 4 | B34: 3 | C34: =IF($B34="",$A34,$B34) -> 3 | D34: Personnel Security | E34: PS-4.1 | F34: Personnel Termination | G34: Does the organization have appropriate termination procedures in place to those with access to the information system? | H34: ='13. Personnel Security'!$K9 -> 0 | I34: ='13. Personnel Security'!$J9 -> Yes | J34: =IF($I34="Yes","Adequate",IF($I34="No","Inadequate",IF($I34="Partial","Inadequate",IF($I34="N/A","Inadequate",IF(OR($I34="",$I34=0),"Blank","Error"))))) -> Adequate | K34: No Override | L34: =IF($K34="No Override",$J34,$K34) -> Adequate | M34: =IF($J34=$L34,"","***") | N34: =IF(OR($I34="",$I34=0),"",$I34) -> Yes | O34: =IF(OR($H34="",$H34=0),"",$H34) | P34: =$L34 -> Adequate | Q34: =$K34 -> No Override | R34: =$C34 -> 3 | S34: =IF($L34=$P34,"","***")
A35: 4 | C35: =IF($B35="",$A35,$B35) -> 4 | D35: Personnel Security | E35: PS-5.1 | F35: Personnel Transfer | G35: Does the organization have appropriate transfer procedures in place to those with access to the information system? | H35: ='13. Personnel Security'!$K10 -> 0 | I35: ='13. Personnel Security'!$J10 -> No | J35: =IF($I35="Yes","Adequate",IF($I35="No","Inadequate",IF($I35="Partial","Inadequate",IF($I35="N/A","Inadequate",IF(OR($I35="",$I35=0),"Blank","Error"))))) -> Inadequate | K35: No Override | L35: =IF($K35="No Override",$J35,$K35) -> Inadequate | M35: =IF($J35=$L35,"","***") | N35: =IF(OR($I35="",$I35=0),"",$I35) -> No | O35: =IF(OR($H35="",$H35=0),"",$H35) | P35: =$L35 -> Inadequate | Q35: =$K35 -> No Override | R35: =$C35 -> 4 | S35: =IF($L35=$P35,"","***")
A36: 4 | C36: =IF($B36="",$A36,$B36) -> 4 | D36: Personnel Security | E36: PS-6.1 | F36: Access Agreements | G36: Does the organization have access agreements (reviewed annually) for individuals with access to the information system? | H36: ='13. Personnel Security'!$K11 -> 0 | I36: ='13. Personnel Security'!$J11 -> Partial | J36: =IF($I36="Yes","Adequate",IF($I36="No","Inadequate",IF($I36="Partial","Inadequate",IF($I36="N/A","Inadequate",IF(OR($I36="",$I36=0),"Blank","Error"))))) -> Inadequate | K36: No Override | L36: =IF($K36="No Override",$J36,$K36) -> Inadequate | M36: =IF($J36=$L36,"","***") | N36: =IF(OR($I36="",$I36=0),"",$I36) -> Partial | O36: =IF(OR($H36="",$H36=0),"",$H36) | P36: =$L36 -> Inadequate | Q36: =$K36 -> No Override | R36: =$C36 -> 4 | S36: =IF($L36=$P36,"","***")
A37: 4 | B37: 1 | C37: =IF($B37="",$A37,$B37) -> 1 | D37: Personnel Security | E37: PS-7.1 | F37: Third Party Personnel Security | G37: Does the organization have appropriate third-party access control procedures for external parties granted access to the information system? | H37: ='13. Personnel Security'!$K12 -> 0 | I37: ='13. Personnel Security'!$J12 -> Yes | J37: =IF($I37="Yes","Adequate",IF($I37="No","Inadequate",IF($I37="Partial","Inadequate",IF($I37="N/A","Inadequate",IF(OR($I37="",$I37=0),"Blank","Error"))))) -> Adequate | K37: No Override | L37: =IF($K37="No Override",$J37,$K37) -> Adequate | M37: =IF($J37=$L37,"","***") | N37: =IF(OR($I37="",$I37=0),"",$I37) -> Yes | O37: =IF(OR($H37="",$H37=0),"",$H37) | P37: =$L37 -> Adequate | Q37: =$K37 -> No Override | R37: =$C37 -> 1 | S37: =IF($L37=$P37,"","***")
A38: 4 | C38: =IF($B38="",$A38,$B38) -> 4 | D38: Personnel Security | E38: PS-8.1 | F38: Personnel Sanctions | G38: Does the organization have appropriate personnel sanctions policies and procedures? | H38: ='13. Personnel Security'!$K13 -> 0 | I38: ='13. Personnel Security'!$J13 -> Yes | J38: =IF($I38="Yes","Adequate",IF($I38="No","Inadequate",IF($I38="Partial","Inadequate",IF($I38="N/A","Inadequate",IF(OR($I38="",$I38=0),"Blank","Error"))))) -> Adequate | K38: No Override | L38: =IF($K38="No Override",$J38,$K38) -> Adequate | M38: =IF($J38=$L38,"","***") | N38: =IF(OR($I38="",$I38=0),"",$I38) -> Yes | O38: =IF(OR($H38="",$H38=0),"",$H38) | P38: =$L38 -> Adequate | Q38: =$K38 -> No Override | R38: =$C38 -> 4 | S38: =IF($L38=$P38,"","***")

Sheet Override Control Env2
A1: Tier | B1: Client Tier | C1: Calc Tier | D1: Control Family | E1: Control Question # | F1: Control Name | G1: Security Question | H1: Comment | I1: Response | J1: Calc Response | K1: Override | L1: Final Response | M1: FindOverrideChanges | N1: Response: | O1: Comments/ Notes: | P1: FinalResponse | Q1: Overrides | R1: OverrideTier | S1: CheckOverrideChanges
