Workbook

Sheet NYP General Assessment
L6: HDR | M6: True
B7: Type: NYP General Assessment | L7: HDR | M7: True
L8: HDR | M8: True
L9: HDR | M9: True
B10: Name | D10: Enter the name | F10: =GENERAL!D4 -> PeriWatch Vigilance - 9181 - NYP General Assessment | L10: HDR | M10: True
L11: HDR | M11: True
B12: Short Name | D12: Question / Description | F12: Answer / Value
B14: Name | D14: Enter the name | L14: ATTR
B16: Short Name | D16: Question / Description | F16: Answer / Value | H16: Comment
H17: =IF(F18=B32003,C32003,"") -> Enter Response | M17: =IF(F18=B32003,E32003,"") -> 2
B18: Information Question 01 | D18: APPLICATION/PRODUCT/SERVICE NAME: | F18: Select here to enter response | G18: * | H18: =GENERAL!D12 -> PeriWatch Vigilance | L18: CTRL | N18: 201633
H19: =IF(F20=B32004,C32004,"") -> Enter Response | M19: =IF(F20=B32004,E32004,"") -> 2
B20: NYP: Information Question 01.5 | D20: IT SYSTEM REQUEST NUMBER: | F20: Select here to enter a response | G20: * | H20: =GENERAL!D14 -> 9181 | L20: CTRL | N20: 207848
H21: =IF(F22=B32005,C32005,"") -> Enter Response | M21: =IF(F22=B32005,E32005,"") -> 2
B22: Information Question 02 | D22: Name: | F22: Select here to enter response | G22: * | H22: =GENERAL!D16 -> Michael Kennedy | L22: CTRL | N22: 201635
H23: =IF(F24=B32006,C32006,"") -> Enter Response | M23: =IF(F24=B32006,E32006,"") -> 2
B24: Information Question 03 | D24: Email: | F24: Select here to enter response | G24: * | H24: =GENERAL!D18 -> Perigen Fetal Surveillance | L24: CTRL | N24: 201637
H25: =IF(F26=B32007,C32007,"") -> Enter Response | M25: =IF(F26=B32007,E32007,"") -> 2
B26: Information Question 04 | D26: Phone number: | F26: Select here to enter response | G26: * | H26: =GENERAL!D20 -> 0 | L26: CTRL | N26: 201639
H27: =IF(F28=B32008,C32008,"") -> Enter Response | M27: =IF(F28=B32008,E32008,"") -> 2
B28: Information Question 05 | D28: DATE SUBMITTED (mm/dd/yy): | F28: Select here to enter response | G28: * | H28: =GENERAL!D22 -> 44531 | L28: CTRL | N28: 201641
H29: =IF(F30=B32009,C32009,"") -> Enter Response | M29: =IF(F30=B32009,E32009,"") -> 2
B30: Information Question 06 | D30: EXPECTED GO-LIVE DATE (mm/dd/yy): | F30: Select here to enter response | G30: * | H30: =GENERAL!D24 -> 0 | L30: CTRL | N30: 201643
B32: Information Question 07 | D32: Will this application or system be HOSTED by NYP or the Vendor? | F32: =GENERAL!D26 -> NYP | G32: * | L32: CTRL | N32: 201645
B34: Information Question 08 | D34: Will this application or system be SUPPORTED by NYP or the Vendor? | F34: =GENERAL!D28 -> Vendor | G34: * | L34: CTRL | N34: 201648
H35: =IF(F36=B32014,C32014,"") -> Enter Response | M35: =IF(F36=B32014,E32014,"") -> 2
B36: Information Question 09 | D36: Description of product features, functionality and/or services: | F36: Select here to enter response | G36: * | H36: =GENERAL!D30 -> OB Fetal Surveillance, archiving, alerts and early warning functions | L36: CTRL | N36: 201651
B38: System Architecture Diagram | D38: Please insert a graphic image containing a diagram of the recommended system architecture | F38: =GENERAL!D34 -> Select here to add attachment | G38: * | H38: =GENERAL!E34 -> * | J38: =IF(F38=B32015,D32015,"") -> Please attach system architecture diagram | L38: CTRL | N38: 201653
H39: =IF(F40=B32017,C32017,"") -> Please confirm DESIGN Tab review: | M39: =IF(F40=B32017,E32017,"") -> 2
B40: NYP: Information IT Resources | D40: Will this PMO request require technical resources from IT such as Server and Database resources? OR Does this PMO request introduce a new network-connected device (such as a biomedical, audio/visual, or building management) or changes to an existing device or service, that will require ongoing connectivity and support? | F40: =GENERAL!D36 -> Yes | G40: * | H40: =GENERAL!F36 -> This PMO requires IT involvement to create the required environmnets (servers, DBs) for PeriWatch Vigilance. | L40: CTRL | N40: 211983
B42: Information Question 10 | D42: Does your application include a technology that can be utilized to provide a highly available system architecture, which meets the Tiering requirements of the system? NOTE: If answering NO, disregard the remaining BCDR questions!! | F42: =BCDR!D5 -> No | G42: * | L42: CTRL | N42: 201656
B44: Will the server / workstation be built and managed by NYP? ( | D44: Does this request include a Medical Device/ BioMed Component? NOTE: If answering NO, disregard the remaining Medical Device questions!! | F44: =GENERAL!D38 -> No | G44: * | L44: CTRL | N44: 201680
B46: Information Question 19 | D46: Doest this request include a cloud-based or externally-hosted component? NOTE: If answering NO, disregard the remaining Vendor Hosted questions!! | F46: =GENERAL!D40 -> No | G46: * | L46: CTRL | N46: 201683
H47: =IF(F48=B32025,C32025,"") -> Enter Response | M47: =IF(F48=B32025,E32025,"") -> 2
B48: BCDR RTO & RPO Tiering Level | D48: Please describe what technologies, native to your application, that can be utilized to provide a highly available system architecture that meets the "RTO and "RPO" of the appropriate Tiering level. | F48: Select here to enter response | G48: * | H48: =BCDR!D7 -> There are no native technologies. PeriWatch Vigilance relies on SQL clustering for DB HA and Vmware HA capabilities. Typically, PeriWatch Vigilance is not considered tier 1 application like fetal surveillance. | L48: CTRL | N48: 201686
H49: =IF(F50=B32027,C32027,"") -> Enter Response | M49: =IF(F50=B32027,E32027,"") -> 2
B50: BCDR Interoperability & Support | D50: Please let us know below, if your application provides interoperability and support for these technologies, or encounters general issues with using these technologies to provide high availability. | F50: Select here to enter response | G50: * | H50: =BCDR!D9 -> Same as above. | L50: CTRL | N50: 201689
H51: =IF(F52=B32029,C32029,"") -> Enter Response | M51: =IF(F52=B32029,E32029,"") -> 2
B52: Vendor Information | D52: Vendor Name: | F52: Select here to enter response | G52: * | H52: =SECURITY!D6 -> PeriGen Inc. | L52: CTRL | N52: 201725
H53: =IF(F54=B32030,C32030,"") -> Enter Response | M53: =IF(F54=B32030,E32030,"") -> 2
...

Sheet GENERAL
B1: GENERAL
B2: Complete ALL Orange highlighted cells
B4: Enter the name | D4: =D12&" - "&D14&" - NYP General Assessment" -> PeriWatch Vigilance - 9181 - NYP General Assessment
B6: Question / Description
B8: Enter the name
B10: Question / Description | D10: Answer / Value
B12: APPLICATION/PRODUCT/SERVICE NAME: | D12: PeriWatch Vigilance | E12: *
B14: IT SYSTEM REQUEST NUMBER: | D14: 9181 | E14: *
B16: Name: | D16: Michael Kennedy | E16: *
B18: Email: | D18: Perigen Fetal Surveillance | E18: *
B20: Phone number: | E20: *
B22: DATE SUBMITTED (mm/dd/yy): | D22: 44531 | E22: *
B24: EXPECTED GO-LIVE DATE (mm/dd/yy): | E24: *
B26: Will this application or system be HOSTED by NYP or the Vendor? | D26: NYP | E26: *
B28: Will this application or system be SUPPORTED by NYP or the Vendor? | D28: Vendor | E28: *
B30: Description of product features, functionality and/or services: | D30: OB Fetal Surveillance, archiving, alerts and early warning functions | E30: *
B32: Web URLs | D32: www.perigen.com
B34: Please insert a graphic image containing a diagram of the recommended system architecture | D34: Select here to add attachment | E34: * | F34: See PowerPoint submitted with this document | AF34: =IF(D34="Select here to add attachment","1","") -> 1
F35: =IF(D36="Yes", "Comment","") -> Comment
B36: 1. Will this PMO request require technical resources from IT such as Server and Database resources? OR 2. Does this PMO request introduce a new network-connected device (such as a biomedical, audio/visual, or building management) or changes to an existing device or service, that will require ongoing connectivity and support? | D36: Yes | E36: * | F36: This PMO requires IT involvement to create the required environmnets (servers, DBs) for PeriWatch Vigilance. | S36: =IF(C36="Yes", "1","") | AF36: =IF(D36="Yes", "1","") -> 1
B38: Does this request include a Medical Device/ BioMed Component? NOTE: If answering NO, disregard the remaining Medical Device questions!! | D38: No | E38: * | F38: However it involves connecivity to existing fetal monitors. See above.
B40: Doest this request include a cloud-based or externally-hosted component? NOTE: If answering NO, disregard the remaining Vendor Hosted questions!! | D40: No | E40: * | F40: All to be hosted by NYP
B42: Vendor/NYP IT Owner Comments & Concerns

Sheet BCDR
B1: BCDR
B2: Complete ALL Orange highlighted cells
B3: Question / Description | D3: Answer / Value
B5: Does your application include a technology that can be utilized to provide a highly available system architecture, which meets the Tiering requirements of the system? NOTE: If answering NO, disregard the remaining BCDR questions. | D5: No | E5: *
B7: Please describe what technologies, native to your application, that can be utilized to provide a highly available system architecture that meets the "RTO and "RPO" of the appropriate Tiering level. | D7: There are no native technologies. PeriWatch Vigilance relies on SQL clustering for DB HA and Vmware HA capabilities. Typically, PeriWatch Vigilance is not considered tier 1 application like fetal surveillance. | E7: *
B9: Please let us know below, if your application provides interoperability and support for these technologies, or encounters general issues with using these technologies to provide high availability. | D9: Same as above. | E9: *

Sheet MEDICAL DEVICE
D1: Medical Devices
D2: Complete ALL Orange highlighted cells and where applicable provide additional comments in column I.
A4: MD1 | B4: 1.1 | D4: Device Information | E4: Manufacturer Name | G4: PeriGen Inc. | H4: * | I4: PeriWatch Vigilance is an enterprise-wide system comprised of the following medical devices: PeriWatch Vigilance Surveillance PeriWatch Vigilance Cues PeriWatch Vigilance Curve PeriWatch Vigilance HUB
E5: Device Name | G5: PeriWatch Vigilance | H5: *
E6: Device Model | G6: PeriWatch Vigilance | H6: *
E7: Software Version | G7: 2021.1 | H7: *
E8: Device Category | G8: surveillance | H8: *
E9: Short Description of Medical Device Function | G9: Obstetrical early warning | H9: *
D10: Data Management
B11: 1.2 | E11: Data Management: | F11: Does device display, transmit, or maintain/store private data (including electronic Protected Health Information [ePHI])? | G11: Yes | H11: *
B12: 1.3 | E12: Record Management | F12: How many individual patient records can be stored on the device? | G12: more than 1,000 | H12: *
I13: =IF(G14="No", "Please Explain","")
B14: 1.4 | D14: Device Certification | E14: FDA | F14: Is the device FDA cleared or approved | G14: Yes | H14: * | AG14: =IF(G14="No","1","")
B15: 1.5 | E15: Manufacturer Disclosure Statement for Medical Device Security – MDS2: | F15: Attach device MDS2 form. | G15: Select here to add attachment | H15: * | I15: See MDS2 form submitted with this document | AG15: =IF(G15="Select here to add attachment","1","") -> 1
D16: Operating System Version and Support
A17: MD2 | B17: 2.1 | D17: Operating System Version and Support | E17: OS Name and Version | G17: Windows Server 2019 | H17: *
B18: 2.2 | E18: OS vendor end-of-life support date | G18: NA | H18: *
D19: Operating System Security Features
I20: =IF(G21="No", "Please Explain","") & IF(G21="N/A", "Comments","") -> Comments
B21: 2.3 | D21: Operating System Security features: | E21: OS Features | F21: Hardened OS | G21: N/A | H21: * | I21: Provided/configured by the customer | AG21: =IF(G21="No","1","") & IF(G21="N/A", "2","") -> 2
I22: =IF(G23="No", "Please Explain","") & IF(G23="N/A", "Comments","") -> Comments
B23: 2.4 | F23: Automatic Logoff | G23: N/A | H23: * | I23: Provided/configured by the customer | AG23: =IF(G23="No","1","") & IF(G23="N/A", "2","") -> 2
I24: =IF(G25="No", "Please Explain","") & IF(G25="N/A", "Comments","") -> Comments
B25: 2.4 | E25: Software Firewall | F25: Firewall enabled | G25: N/A | H25: * | I25: Provided/configured by the customer | AG25: =IF(G25="No","1","") & IF(G25="N/A", "2","") -> 2
I26: =IF(G27="No", "Please Explain","") & IF(G27="N/A", "Comments","") -> Comments
B27: 2.5 | F27: Default Deny for Apps, Drivers & Libraries | G27: N/A | H27: * | I27: Provided/configured by the customer | AG27: =IF(G27="No","1","") & IF(G27="N/A", "2","") -> 2
I28: =IF(G29="No", "Please Explain","") & IF(G29="N/A", "Comments","") -> Comments
B29: 2.6 | F29: Device Control, USB Connections Monitoring | G29: N/A | H29: * | I29: Provided/configured by the customer | AG29: =IF(G29="No","1","") & IF(G29="N/A", "2","") -> 2
I30: =IF(G31="No", "Please Explain","") & IF(G31="N/A", "Comments","") -> Comments
B31: 2.7 | F31: Memory Protection | G31: N/A | H31: * | I31: Provided/configured by the customer | AG31: =IF(G31="No","1","") & IF(G31="N/A", "2","") -> 2
I32: =IF(G33="No", "Please Explain","") & IF(G33="N/A", "Comments","") -> Comments
B33: 2.8 | F33: File Integrity Monitoring and Activity Audit Logs | G33: N/A | H33: * | I33: Provided/configured by the customer | AG33: =IF(G33="No","1","") & IF(G33="N/A", "2","") -> 2
I34: =IF(G35="No", "Please Explain","") & IF(G35="N/A", "Comments","") -> Comments
B35: 2.9 | E35: Does the device support Least Privileged Access limiting user access to the minimal level that will allow normal functioning or operation. | G35: N/A | H35: * | I35: Provided/configured by the customer | AG35: =IF(G35="No","1","") & IF(G35="N/A", "2","") -> 2
I36: =IF(G37="No", "Please Explain","") & IF(G37="N/A", "Comments","") -> Comments
B37: 2.1 | E37: CD/USB boot disabled | G37: N/A | H37: * | I37: PeriGen assumes the customer provides a pre-configured VM with all the above configured according to customer IT policies | AG37: =IF(G37="No","1","") & IF(G37="N/A", "2","") -> 2
D38: s
I39: =IF(G40="No", "Please Explain","") -> Please Explain
A40: MD3 | B40: 3.1 | D40: Connectivity | E40: Network Connectivity | F40: Dedicated cable connection (e.g., IEEE 1073, serial port, USB, FireWire, etc.)? | G40: No | H40: * | I40: The device is software only and running on the customer provided VM which include local network connectivity. | AG40: =IF(G40="No","1","") -> 1
I41: =IF(G42="No", "Please Explain","")
...

Sheet SECURITY
B1: SECURITY
B2: Please Note: The Security Tab must be completed for all System Requests EXCLUDING Medical Devices. Complete ALL Orange highlighted cells and where applicable provide additional comments in column G.
B4: Question / Description | D4: Answer / Value | G4: Comments and Notes
B5: Application/Solution/Service Information
B6: Vendor Name | D6: PeriGen Inc. | F6: *
B7: Application/Solution/Service Name | D7: PeriWatch Vigilance | F7: *
B8: Software Version | D8: 2021.1 | F8: *
B9: Short Description of Application/Solution or Service being provided | D9: Obstetrical Early Warning system | F9: *
B12: Data Classification
B13: What type of data is created, processed, stored, or received by the system or application (or accessed by the vendor/contractor in case of professional services projects)? (Please select all that apply)
B14: PHI | D14: Yes | F14: *
B15: PII | D15: No | F15: *
B16: PCI | D16: No | F16: * | G16: =IF(D16="Yes","Please attach evidence of PCI Compliance.", "") | AF16: =IF(D16="Yes","1","0") -> 0
B17: PayRoll | D17: No | F17: *
B18: Financial | D18: No | F18: *
G19: =IF(D20="Yes","Please Explain","")
B20: Is there any OTHER data not previously mentioned that is created, processed, stored, or received by the system or application (or accessed by the vendor/contractor in case of professional services projects)? If so, please specify. | D20: No | F20: * | AA20: =IF(D20="Yes", "1","")
B22: Data/Application Hosting
B23: Where is the application/data being processed or stored?
B24: NYP Data Center | D24: Yes | F24: *
B25: Hosted By Vendor | D25: No | F25: *
G26: =IF(D27="Yes", "Comment","")
B27: Is the application/data Hosted by other 3rd Party? If so, provide name | D27: No | AA27: =IF(D27="Yes", "1","")
B28: Is the application/data NYP data stored on a Vendor owned system? | D28: No | F28: *
G29: =IF(D30="N/A", "Comment","")
B30: N/A - (e.g. Standalone, desktop, embedded device)? | D30: No | AA30: =IF(D30="N/A", "1","")
B32: Communication/Transmission Methods
B33: Is NYP data transmitted over a private or public network? (Please select all that apply)
B34: Local NYP local network | D34: Yes | F34: *
B35: WAN | D35: No | F35: *
B36: NYP Virtual Private Network (VPN) | D36: No | F36: *
B37: Internet | D37: No | F37: *
B38: WiFi | D38: Yes | F38: * | G38: only if the customer is using mobile workstations or tablets,
B39: BlueTooth | D39: No | F39: *
B40: Mobile | D40: Yes | F40: * | G40: Not natively. Only if the customer provides secure remote access to mobile devices.
B42: Data Transfers
B43: What type of data is transferred to or from this system/application? (Please select all that apply)
B44: PHI | D44: Yes | F44: *
B45: PII | D45: No | F45: *
B46: PCI | D46: No | F46: *
...

Sheet VENDOR HOSTED
D1: Cloud-based or Externally Hosted Systems
D2: Complete ALL Orange highlighted cells and where applicable provide additional comments incolumn W.
A3: DID | B3: Domain | D3: Control Group | E3: CGID | F3: CID | G3: NYP | H3: Third Party Information Security Assessment Questions | I3: Yes/No/NA | J3: COBIT | K3: HIPAA | L3: ISO27001 | M3: SP800_53 | N3: FedRAMP | O3: PCI_DSS | P3: BITS | Q3: GAPP | R3: SaaS | S3: PaaS | T3: IaaS | U3: SP | V3: CUST | W3: Comments and Notes
D4: Vendor/Cloud Information | H4: VENDOR /3RD PARTY ORGANIZATION NAME(s)
H5: VENDOR CONTACT NAME
H6: VENDOR ROLE
W7: =IF(I8="Yes", "Comments","")
H8: Will subcontractors be involved in services performed by the vendor? If so, list all subcontractors and services they provide. | AO8: =IF(I8="Yes", "1","")
A9: CO | B9: Compliance
W10: =IF(I11="No", "Comments","") & IF(I11="N/A", "Comments","")
A11: CO | B11: Compliance | D11: Independent Audits | E11: CO-02 | F11: CO-02.1 | G11: CR | H11: Have you conducted SAS70 Type II/SSAE 16 SOC2/ISAE3402 or similar third party review of the data center where NYP data is stored? | J11: COBIT 4.1 DS5.5, ME2.5, ME 3.1 PO 9.6 | K11: 45 CFR 164.308 (a)(8) 45 CFR 164.308(a)(1)(ii)(D) | L11: Clause 4.2.3e Clause 5.1 g Clause 5.2.1 d) Clause 6 A.6.1.8 | M11: NIST SP800-53 R3 CA-1 NIST SP800-53 R3 CA-2 NIST SP800-53 R3 CA-6 NIST SP800-53 R3 RA-5 | N11: NIST SP800-53 R3 CA-1_x000D_ NIST SP800-53 R3 CA-2_x000D_ NIST SP800-53 R3 CA-2 (1)_x000D_ NIST SP800-53 R3 CA-6_x000D_ NIST SP800-53 R3 RA-5_x000D_ NIST SP800-53 R3 RA-5 (1)_x000D_ NIST SP800-53 R3 RA-5 (2)_x000D_ NIST SP800-53 R3 RA-5 (3)_x000D_ NIST SP800-53 R3 RA-5 (9)_x000D_ NIST SP800-53 R3 RA-5 (6)_x000D_ | O11: PCI DSS v2.0 11.2 PCI DSS v2.0 11.3 PCI DSS v2.0 6.6 PCI DSS v2.0 12.1.2.b | P11: SIG v6.0: L.2, L.4, L.7, L.9, L.11 | Q11: GAPP Ref 1.2.5 GAPP Ref 1.2.7 GAPP Ref 4.2.1 GAPP Ref 8.2.7 GAPP Ref 10.2.3 GAPP Ref 10.2.5 | R11: Y | S11: Y | T11: Y | U11: Y | V11: Y | AO11: =IF(I11="No","1","")&IF(I11="N/A","2","")
W12: =IF(I13="No", "Comments","") & IF(I13="N/A", "Comments","")
A13: CO | B13: Compliance | E13: CO-02 | F13: CO-02.4 | G13: CR | H13: Does your Internal Audit organization review the compliance and effectiveness of your information security practices and controls? | J13: COBIT 4.1 DS5.5, ME2.5, ME 3.1 PO 9.6 | K13: 45 CFR 164.308 (a)(8) 45 CFR 164.308(a)(1)(ii)(D) | L13: Clause 4.2.3e Clause 5.1 g Clause 5.2.1 d) Clause 6 A.6.1.8 | M13: NIST SP800-53 R3 CA-1 NIST SP800-53 R3 CA-2 NIST SP800-53 R3 CA-6 NIST SP800-53 R3 RA-5 | N13: NIST SP800-53 R3 CA-1_x000D_ NIST SP800-53 R3 CA-2_x000D_ NIST SP800-53 R3 CA-2 (1)_x000D_ NIST SP800-53 R3 CA-6_x000D_ NIST SP800-53 R3 RA-5_x000D_ NIST SP800-53 R3 RA-5 (1)_x000D_ NIST SP800-53 R3 RA-5 (2)_x000D_ NIST SP800-53 R3 RA-5 (3)_x000D_ NIST SP800-53 R3 RA-5 (9)_x000D_ NIST SP800-53 R3 RA-5 (6)_x000D_ | O13: PCI DSS v2.0 11.2 PCI DSS v2.0 11.3 PCI DSS v2.0 6.6 PCI DSS v2.0 12.1.2.b | P13: SIG v6.0: L.2, L.4, L.7, L.9, L.11 | Q13: GAPP Ref 1.2.5 GAPP Ref 1.2.7 GAPP Ref 4.2.1 GAPP Ref 8.2.7 GAPP Ref 10.2.3 GAPP Ref 10.2.5 | R13: Y | S13: Y | T13: Y | U13: Y | V13: Y | AO13: =IF(I13="No","1","")&IF(I13="N/A","2","")
W14: =IF(I15="No", "Comments","") & IF(I15="N/A", "Comments","")
A15: CO | B15: Compliance | E15: CO-02 | F15: CO-02.5 | G15: CR | H15: Does an external firm (such as KPMG, PWC) perform external audits of your company's and partners' information security practices and controls? | J15: COBIT 4.1 DS5.5, ME2.5, ME 3.1 PO 9.6 | K15: 45 CFR 164.308 (a)(8) 45 CFR 164.308(a)(1)(ii)(D) | L15: Clause 4.2.3e Clause 5.1 g Clause 5.2.1 d) Clause 6 A.6.1.8 | M15: NIST SP800-53 R3 CA-1 NIST SP800-53 R3 CA-2 NIST SP800-53 R3 CA-6 NIST SP800-53 R3 RA-5 | N15: NIST SP800-53 R3 CA-1_x000D_ NIST SP800-53 R3 CA-2_x000D_ NIST SP800-53 R3 CA-2 (1)_x000D_ NIST SP800-53 R3 CA-6_x000D_ NIST SP800-53 R3 RA-5_x000D_ NIST SP800-53 R3 RA-5 (1)_x000D_ NIST SP800-53 R3 RA-5 (2)_x000D_ NIST SP800-53 R3 RA-5 (3)_x000D_ NIST SP800-53 R3 RA-5 (9)_x000D_ NIST SP800-53 R3 RA-5 (6)_x000D_ | O15: PCI DSS v2.0 11.2 PCI DSS v2.0 11.3 PCI DSS v2.0 6.6 PCI DSS v2.0 12.1.2.b | P15: SIG v6.0: L.2, L.4, L.7, L.9, L.11 | Q15: GAPP Ref 1.2.5 GAPP Ref 1.2.7 GAPP Ref 4.2.1 GAPP Ref 8.2.7 GAPP Ref 10.2.3 GAPP Ref 10.2.5 | R15: Y | S15: Y | T15: Y | U15: Y | V15: Y | AO15: =IF(I15="No","1","")&IF(I15="N/A","2","")
W16: =IF(I17="No", "Comments","") & IF(I17="N/A", "Comments","") | AO16: =IF(I16="No","1","")&IF(I16="N/A","2","")
A17: CO | B17: Compliance | E17: CO-02 | F17: CO-02.7 | G17: CR | H17: Is a summary of the results of your internal audit and external audits readily available for review? | J17: COBIT 4.1 DS5.5, ME2.5, ME 3.1 PO 9.6 | K17: 45 CFR 164.308 (a)(8) 45 CFR 164.308(a)(1)(ii)(D) | L17: Clause 4.2.3e Clause 5.1 g Clause 5.2.1 d) Clause 6 A.6.1.8 | M17: NIST SP800-53 R3 CA-1 NIST SP800-53 R3 CA-2 NIST SP800-53 R3 CA-6 NIST SP800-53 R3 RA-5 | N17: NIST SP800-53 R3 CA-1_x000D_ NIST SP800-53 R3 CA-2_x000D_ NIST SP800-53 R3 CA-2 (1)_x000D_ NIST SP800-53 R3 CA-6_x000D_ NIST SP800-53 R3 RA-5_x000D_ NIST SP800-53 R3 RA-5 (1)_x000D_ NIST SP800-53 R3 RA-5 (2)_x000D_ NIST SP800-53 R3 RA-5 (3)_x000D_ NIST SP800-53 R3 RA-5 (9)_x000D_ NIST SP800-53 R3 RA-5 (6)_x000D_ | O17: PCI DSS v2.0 11.2 PCI DSS v2.0 11.3 PCI DSS v2.0 6.6 PCI DSS v2.0 12.1.2.b | P17: SIG v6.0: L.2, L.4, L.7, L.9, L.11 | Q17: GAPP Ref 1.2.5 GAPP Ref 1.2.7 GAPP Ref 4.2.1 GAPP Ref 8.2.7 GAPP Ref 10.2.3 GAPP Ref 10.2.5 | R17: Y | S17: Y | T17: Y | U17: Y | V17: Y | AO17: =IF(I17="No","1","")&IF(I17="N/A","2","")
W18: =IF(I19="No", "Comments","") & IF(I19="N/A", "Comments","")
A19: CO | B19: Compliance | E19: CO-03 | F19: CO-03.1 | G19: CR | H19: Can NYP perform vulnerability and penetration tests of the application? | J19: COBIT 4.1 ME 2.6, DS 2.1, DS 2.4 | K19: 45 CFR 164.308(b)(1) (New) 45 CFR 164.308 (b)(4) | L19: A.6.2.3 A.10.2.1 A.10.2.2 A.10.6.2 | M19: NIST SP800-53 R3 CA-3 NIST SP800-53 R3 SA-9 NIST SP800-53 R3 SA-12 NIST SP800-53 R3 SC-7 | O19: PCI DSS v2.0 2.4 PCI DSS v2.0 12.8.2 PCI DSS v2.0 12.8.3 PCI DSS v2.0 12.8.4 Appendix A | P19: AUP v5.0 C.2 SIG v6.0: C.2.4,C.2.6, G.4.1, G.4.2, L.2, L.4, L.7, L.11 | Q19: GAPP Ref 1.2.11 GAPP Ref 4.2.3 GAPP Ref 7.2.4 GAPP Ref 10.2.3 GAPP Ref 10.2.4 | R19: Y | S19: Y | T19: Y | U19: Y | V19: Y | AO19: =IF(I19="No","1","")&IF(I19="N/A","2","")
W20: =IF(I21="No", "Comments","") & IF(I21="N/A", "Comments","")
A21: CO | B21: Compliance | D21: Third Party Audits | E21: CO-03 | F21: CO-03.2 | G21: CR | H21: Do you have an external third-party perform quarterly vulnerability scans and penetration tests on your applications and annual tests of your networks? | J21: COBIT 4.1 ME 2.6, DS 2.1, DS 2.4 | K21: 45 CFR 164.308(b)(1) (New) 45 CFR 164.308 (b)(4) | L21: A.6.2.3 A.10.2.1 A.10.2.2 A.10.6.2 | M21: NIST SP800-53 R3 CA-3 NIST SP800-53 R3 SA-9 NIST SP800-53 R3 SA-12 NIST SP800-53 R3 SC-7 | O21: PCI DSS v2.0 2.4 PCI DSS v2.0 12.8.2 PCI DSS v2.0 12.8.3 PCI DSS v2.0 12.8.4 Appendix A | P21: AUP v5.0 C.2 SIG v6.0: C.2.4,C.2.6, G.4.1, G.4.2, L.2, L.4, L.7, L.11 | Q21: GAPP Ref 1.2.11 GAPP Ref 4.2.3 GAPP Ref 7.2.4 GAPP Ref 10.2.3 GAPP Ref 10.2.4 | R21: Y | S21: Y | T21: Y | U21: Y | V21: Y | AO21: =IF(I21="No","1","")&IF(I21="N/A","2","")
A22: DG | B22: Data Governance | AO22: =IF(I22="No","1","")&IF(I22="N/A","2","")
W23: =IF(I24="No", "Comments","") & IF(I24="N/A", "Comments","")
A24: DG | B24: Data Governance | D24: Retention Policy | E24: DG-04 | F24: DG-04.1 | G24: CR | H24: Do you have technical control capabilities to enforce NYP data retention policies? | J24: COBIT 4.1 DS 4.1, DS 4.2, DS 4.5, DS 4.9, DS 11.6 | K24: 45 CFR 164.308 (a)(7)(ii)(A) 45 CFR 164.310 (d)(2)(iv) 45 CFR 164.308(a)(7)(ii)(D) (New) 45 CFR 164.316(b)(2)(i) (New) | L24: Clause 4.3.3 A.10.5.1 A.10.7.3 | M24: NIST SP800-53 R3 CP-2 NIST SP800-53 R3 CP-6 NIST SP800-53 R3 CP-7 NIST SP800-53 R3 CP-8 NIST SP800-53 R3 CP-9 NIST SP800-53 R3 SI-12 NIST SP800-53 R3 AU-11 | O24: PCI DSS v2.0 3.1 PCI DSS v2.0 3.1.1 PCI DSS v2.0 3.2 PCI DSS v2.0 9.9.1 PCI DSS v2.0 9.5 PCI DSS v2.0 9.6 PCI DSS v2.0 10.7 | P24: SIG v6.0: D.2.2.9 | Q24: GAPP Ref 5.1.0 GAPP Ref 5.1.1 GAPP Ref 5.2.2 GAPP Ref 8.2.6 | R24: Y | S24: Y | T24: Y | U24: Y | V24: Y | AO24: =IF(I24="No","1","")&IF(I24="N/A","2","")
W25: =IF(I26="No", "Comments","") & IF(I26="N/A", "Comments","")
A26: DG | B26: Data Governance | D26: Secure Disposal | E26: DG-05 | F26: DG-05.1 | G26: CR | H26: Do you support secure deletion (ex. degaussing / cryptographic wiping) of archived data as determined by NYP? | J26: COBIT 4.1 DS 11.4 | K26: 45 CFR 164.310 (d)(2)(i) 45 CFR 164.310 (d)(2)(ii) | L26: A.9.2.6 A.10.7.2 | M26: NIST SP800-53 R3 MP-6 NIST SP800-53 R3 PE-1 | N26: NIST SP800-53 R3 MP-6_x000D_ NIST SP800-53 R3 MP-6 (4)_x000D_ NIST SP800-53 R3 PE-1_x000D_ | O26: PCI DSS v2.0 3.1.1 PCI DSS v2.0 9.10 PCI DSS v2.0 9.10.1 PCI DSS v2.0 9.10.2 PCI DSS v2.0 3.1 | P26: SIG v6.0: D.2.2.10, D.2.2.11, D.2.2.14, | Q26: GAPP Ref 5.1.0 GAPP Ref 5.2.3 | R26: Y | S26: Y | T26: Y | U26: Y | V26: Y | AO26: =IF(I26="No","1","")&IF(I26="N/A","2","")
W27: =IF(I28="No", "Comments","") & IF(I28="N/A", "Comments","")
A28: DG | B28: Data Governance | E28: DG-05 | F28: DG-05.2 | G28: CR | H28: Can you provide a published procedure for exiting the service arrangement, including assurance to sanitize all computing resources of NYP's data once NYP has exited your environment or has vacated a resource? | J28: COBIT 4.1 DS 11.4 | K28: 45 CFR 164.310 (d)(2)(i) 45 CFR 164.310 (d)(2)(ii) | L28: A.9.2.6 A.10.7.2 | M28: NIST SP800-53 R3 MP-6 NIST SP800-53 R3 PE-1 | N28: NIST SP800-53 R3 MP-6_x000D_ NIST SP800-53 R3 MP-6 (4)_x000D_ NIST SP800-53 R3 PE-1_x000D_ | O28: PCI DSS v2.0 3.1.1 PCI DSS v2.0 9.10 PCI DSS v2.0 9.10.1 PCI DSS v2.0 9.10.2 PCI DSS v2.0 3.1 | P28: SIG v6.0: D.2.2.10, D.2.2.11, D.2.2.14, | Q28: GAPP Ref 5.1.0 GAPP Ref 5.2.3 | R28: Y | S28: Y | T28: Y | U28: Y | V28: Y | AO28: =IF(I28="No","1","")&IF(I28="N/A","2","")
W29: =IF(I30="No", "Comments","") & IF(I30="N/A", "Comments","")
A30: DG | B30: Data Governance | D30: Nonproduction Data | E30: DG-06 | F30: DG-06.1 | G30: CR | H30: Do you have procedures in place to ensure production data shall not be replicated or used in non-production environments? | K30: 45 CFR 164.308(a)(4)(ii)(B) | L30: A.7.1.3 A.10.1.4 A.12.4.2 A.12.5.1 | M30: NIST SP800-53 R3 SA-11 NIST SP800-53 R3 CM-04 | N30: NIST SP800-53 R3 SA-11_x000D_ NIST SP800-53 R3 SA-11 (1)_x000D_ NIST SP800-53 R3 CM-04_x000D_ | O30: PCI DSS v2.0 6.4.3 | P30: SIG v6.0: I.2.18 | Q30: GAPP Ref 1.2.6 | R30: Y | S30: Y | T30: Y | U30: Y | V30: Y | AO30: =IF(I30="No","1","")&IF(I30="N/A","2","")
A31: FS | B31: Facility Security | AO31: =IF(I31="No","1","")&IF(I31="N/A","2","")
W32: =IF(I33="No", "Comments","") & IF(I33="N/A", "Comments","")
A33: FS | B33: Facility Security | D33: Policy | E33: FS-01 | F33: FS-01.1 | G33: CR | H33: Can you provide evidence that policies and procedures have been established for maintaining a safe and secure working environment in offices (e.g., clean desk sweeps), rooms, facilities and secure area where NYP data is accessed or stored? | J33: COBIT 4.1 DS5.7, DS 12.1, DS 12.4 DS 4.9 | K33: 45 CFR 164.310 (a)(1) 45 CFR 164.310 (a)(2)(ii) 45 CFR 164.308(a)(3)(ii)(A) (New) 45 CFR 164.310 (a)(2)(iii) (New) | L33: A.5.1.1 A.9.1.3 A.9.1.5 | M33: NIST SP800-53 R3 CA-2 NIST SP800-53 R3 PE-1 NIST SP800-53 R3 PE-6 NIST SP800-53 R3 PE-7 NIST SP800-53 R3 PE-8 | N33: NIST SP800-53 R3 CA-2_x000D_ NIST SP800-53 R3 CA-2 (1)_x000D_ NIST SP800-53 R3 PE-1_x000D_ NIST SP800-53 R3 PE-6_x000D_ NIST SP800-53 R3 PE-6 (1)_x000D_ NIST SP800-53 R3 PE-7_x000D_ NIST SP800-53 R3 PE-7 (1)_x000D_ NIST SP800-53 R3 PE-8_x000D_ | O33: PCI DSS v2.0 9.1 PCI DSS v2.0 9.2 PCI DSS v2.0 9.3 PCI DSS v2.0 9.4 | P33: AUP v5.0 F.2 SIG v6.0: F.1.1, F.1.2 F.1.3, F.1.4, F1.5, F.1.6, F.1.7, F.1.8, F.1.9, F.2.1, F.2.2, F.2.3, F.2.4, F.2.5, F2.6, F.2.7, F.2.8, F.2.9, F.2.10, F.2.11, F.2.12, F.2.13, F.2.14, F.2.15, F.2.16, F.2.17, F.2.18,F.2.19, F.2.20 | Q33: GAPP Ref 8.1.0 GAPP Ref 8.1.1 GAPP Ref 8.2.1 | R33: Y | S33: Y | T33: Y | U33: Y | V33: Y | AO33: =IF(I33="No","1","")&IF(I33="N/A","2","")
W34: =IF(I35="No", "Comments","") & IF(I35="N/A", "Comments","")
A35: FS | B35: Facility Security | D35: User Access | E35: FS-02 | F35: FS-02.1 | G35: CR | H35: Is access to the data center limited to only workforce members that require access? | K35: 45 CFR 164.310(a)(1) (New) 45 CFR 164.310(a)(2)(ii) (New) 45 CFR 164.310(b) (New) 45 CFR 164.310 ( c) (New) | L35: A.9.1.1 A.9.1.2 | M35: NIST SP800-53 R3 PE-2 NIST SP800-53 R3 PE-3 NIST SP800-53 R3 PE-4 NIST SP800-53 R3 PE-5 NIST SP800-53 R3 PE-6 | N35: NIST SP800-53 R3 PE-2_x000D_ NIST SP800-53 R3 PE-2 (1)_x000D_ NIST SP800-53 R3 PE-3_x000D_ NIST SP800-53 R3 PE-4_x000D_ NIST SP800-53 R3 PE-5_x000D_ NIST SP800-53 R3 PE-6_x000D_ NIST SP800-53 R3 PE-6 (1)_x000D_ | O35: PCI DSS v2.0 9.1 | P35: AUP v5.0 H.6 SIG v6.0: F.1.2.3, F.1.2.4, F.1.2.5, F.1.2.6, F.1.2.8, F.1.2. 9, F.1.2.10, F.1.2.11, F.1.2.12, F.1.2.13, F.1.2.14, F.1.2.15, F.1.2.24, F.1.4.2, F1.4.6, F.1.4.7, F.1.7, F.1.8, F.2.13, F.2.14, F.2.15, F.2.16, F.2.17, F.2.18 | Q35: GAPP Ref 8.2.1 GAPP Ref 8.2.2 GAPP Ref 8.2.3 | R35: N | S35: N | T35: N | U35: N | V35: N | AO35: =IF(I35="No","1","")&IF(I35="N/A","2","")
W36: =IF(I37="No", "Comments","") & IF(I37="N/A", "Comments","")
A37: FS | B37: Facility Security | D37: Offsite Authorization | E37: FS-06 | F37: FS-06.1 | G37: CR | H37: Do you have documentation that describes scenarios where data may be moved from one physical location to another? (ex. Offsite backups, business continuity failovers, replication). Can you provide that to NYP? | K37: 45 CFR 164.310 (d)(1) (New) | L37: A.9.2.7 A.10.1.2 | M37: NIST SP800-53 R3 MA-1 NIST SP800-53 R3 MA-2 NIST SP800-53 R3 PE-16 | N37: NIST SP800-53 R3 MA-1_x000D_ NIST SP800-53 R3 MA-2_x000D_ NIST SP800-53 R3 MA-2 (1)_x000D_ NIST SP800-53 R3 PE-16_x000D_ | O37: PCI DSS v2.0 9.8 PCI DSS v2.0 9.9 | P37: AUP v5.0 G.21 SIG v6.0:F.2.18 | Q37: GAPP Ref 8.2.5 GAPP Ref 8.2.6 | R37: Y | S37: Y | T37: Y | U37: Y | V37: Y | AO37: =IF(I37="No","1","")&IF(I37="N/A","2","")
W38: =IF(I39="No", "Comments","") & IF(I39="N/A", "Comments","")
A39: FS | B39: Facility Security | D39: Asset Management | E39: FS-08 | F39: FS-08.1 | G39: CR | H39: Do you maintain a complete inventory of all of your critical assets which includes ownership of the asset? | K39: 45 CFR 164.310 (d)(2)(iii) | L39: A.7.1.1 A.7.1.2 | M39: NIST SP800-53 R3 CM-8 | N39: NIST SP800-53 R3 CM-8_x000D_ NIST SP800-53 R3 CM-8 (1)_x000D_ NIST SP800-53 R3 CM-8 (3)_x000D_ NIST SP800-53 R3 CM-8 (5)_x000D_ | O39: PCI DSS v2.0 9.9.1 PCI DSS v2.0 12.3.3 PCI DSS v2.0 12.3.4 | P39: AUP v5.0 D.1 SIG v6.0: D.1.1, D.2.1. D.2.2, | R39: Y | S39: Y | T39: Y | U39: Y | V39: Y | AO39: =IF(I39="No","1","")&IF(I39="N/A","2","")
W40: =IF(I41="No", "Comments","") & IF(I41="N/A", "Comments","")
...

Sheet DESIGN
A1: IT Infrastructure Solution Design
A2: Description
A3: Should technical resources be required from NYP for the project, the vendor and NYP BRM representative will attend a Solution Design session alongside technical leads from the infrastructure team to discuss requirements and architect the solution according to NYP technical standards. The output of this session will include artifacts needed for both the implementation of the project and ongoing (day 2) support of the solution/service. The following artifacts will be created for net new systems, or if this is a modification to an existing system, these artifacts will be updated: • Bill of Materials required to build, test, and go live with the solution (BOM) • High Level Architecture Diagram (HLD) • Low Level technical blueprint of the solution (LLD) In addition to any technical documentation and vendor provided reference architectures, please come to Solution Design prepared to discuss the in-depth technical details and infrastructure requirements including, but not limited to the following topics:
A9: Application | B9: Topic | C9: NYP Standards
B10: Data Flows | C10: All data flows associated with the application must be documented in the LLD.
B12: Ports & Protocols | C12: All TCP and UDP ports in use must be documented and known for firewall traversal.
B14: Data Center Resiliency | C14: Built-in application; VMWare Site Recovery Manager; F5 GTM and LTM;
A16: Server | B16: Topic | C16: NYP Standards
B17: Vendor supplied images i.e. OVA, OVF | C17: Supported
B19: Resource requirements i.e. vCPUs, memory, storage. | C19: Customizable, but no resource reservations permitted
B21: Operating Systems supported | C21: RHEL 7.2, Windows Server 2016
B22: Remote Access | C22: NYP PRA Portal, NYP Client VPN, NYP VPN Tunnel
B23: Antivirus | C23: Cylance
B24: Approved Software | C24: BigFix, Splunk, Snow, VMWare Tools, SCCM, IE, .NET, Silverlight
B25: OS Firewall | C25: Deny all inbound ports by default
A26: Storage | B26: Topic | C26: NYP Standards
B27: NAS/SAN Requirements | C27: DellEMC Isilon, Pure FlashArray
B29: Initial capacity requirements and growth projections | C29: Customizable
B31: Data Lifecycle Policies – Retention, Archival, Attrition | C31: Customizable
B32: NAS authentication | C32: Mandatory Active Directory integration
B33: Bandwidth & Latency | C33: Bandwidth requirements and latency thresholds must be specified and documented
B35: Internet connectivity | C35: NYP Web Proxy must be utilized
B36: Site-to-Site VPN | C36: Supported via enterprise VPN infrastructure
B37: Client VPN | C37: NYP utilizes Cisco Anyconnect
B38: Load Balancing | C38: NYP provides global (GTM) and local (LTM) traffic management utilizing F5 technology
A39: Network - WAN/Data Center | B39: Topic | C39: NYP Standards
B40: Bandwidth & Latency | C40: Bandwidth requirements and latency thresholds must be specified and documented
B42: Internet connectivity | C42: NYP Web Proxy must be utilized
B43: Site-to-Site VPN | C43: Supported via enterprise VPN infrastructure
B44: Client VPN | C44: NYP utilizes Cisco Anyconnect
B45: Load Balancing | C45: NYP provides global (GTM) and local (LTM) traffic management utilizing F5 technology
A46: Network - LAN | B46: Topic | C46: NYP Standards
B47: Power-over-Ethernet | C47: 802.3af and 802.3at supported
B48: Multicast | C48: Supported – PIM sparse-mode
B49: Bandwidth | C49: Bandwidth requirements must be specified and documented
A50: Network - WiFi | B50: Topic | C50: NYP Standards
B51: Frequency | C51: 5-Ghz support required for clinical, voice, and video use cases
B53: Security | C53: WPA2 Enterprise
B54: Authentication | C54: 802.1x EAP-TLS, EAP-PEAP
B55: SSID | C55: All devices must use a standard NYP SSID; Rogue and ad-hoc wireless networks are not permitted
...

Sheet Values-DoNotDelete
A1: General-C26 | B1: Yes/No | C1: Attachments | D1: DestructionOfData | E1: CloudProvider | F1: Virtual Networking | G1: VendorServerAuth
A2: Vendor | B2: Yes | C2: Select here to add attachment | D2: Vendor will destroy data in accordance with NIST standards | E2: AWS | F2: VNET | G2: Password
A3: NYP | B3: No | C3: N/A | D3: Vendor will return data to NYP | E3: Azure | F3: VPC | G3: Certificate
B4: N/A | C4: Please attach system architecture diagram | D4: N/A | E4: GCP | F4: Other | G4: Other
E5: Other | F5: N/A | G5: N/A
E6: N/A
A8: NoOfRecords | B8: DR Environment | C8: Security Groups+NACLs | D8: Regions | E8: AV
A9: 1 to 10 | B9: VPN | C9: NSGs | D9: US East | E9: NYP Standard - Cylance malware protection
A10: 11 to 1,000 | B10: Express Route | C10: NACLs | D10: US East 2 | E10: Preinstalled AntiVirus / AntiMalware
A11: more than 1,000 | B11: Direct Connect | C11: Both | D11: US West | E11: Other (embedded Security - whitelisting)
A12: N/A | B12: Internet | C12: Neither | D12: US West 2 | E12: N/A
B13: Other | C13: N/A | D13: Other
B14: N/A | D14: N/A
A16: PatchMgmt | C16: ScanningModes | D16: EncryptionAtRest | E16: 3rdParty SW | F16: RemoteAccess
A17: Manual updates by Vendor | C17: Continuously and automatically (on access) | D17: NYP Standard - Bit locker through NYP AD Domain rules | E17: Not installed | F17: Remote troubleshooting via Remote Desktop
A18: Automated updates by Vendor | C18: On-demand on-line | D18: Other encryption types. (please specify in Comments) | E18: Usage is restricted to service | F18: Remote Monitoring
A19: Device supports NYP installed/maintained SCCM Agent for patch deployment | C19: Scheduled off-line | D19: Industry standard algorithm (e.g. AES 256). | E19: Hardened installation | F19: Remote Software Distribution
A20: Manual updates by NYP | C20: At boot or shutdown time | D20: N/A | E20: Default installation | F20: Anti-Virus Service Management and Updates
A21: Automated Microsoft Security Patches by NYP | C21: On-demand off-line | E21: Not Supported | F21: Not Supported
A22: Part of Corrective Maintenance | C22: Customizable / Configurable | E22: Software-only product | F22: N/A
A23: Not Supported | C23: Not supported | E23: N/A
A24: N/A | C24: N/A
A25: Supports Multiple
