Workbook

Sheet Cover Page
A1: Vendor Security Assessment Toolkit by CORL Technologies
A12: Version 3.10

Sheet Instructions
A1: Tips for a smooth and timely assessment:
B2: 1. Respond to the questionnaire in the committed timeframe (usually 10-15 days). Your response time is part of the feedback provided to the client. 2. Provide information that is specific to the product/service being considered by/provided to the client. Although some of the questions are about your company’s infrastructure, it is important for CORL to assess the specific product(s)/service(s) being provided to the client. 3. Provide the requested artifacts with the questionnaire and fully complete the questionnaire to reduce follow up or additional document requests. 4. Contact CORL if you have questions or need clarification on the control questions. We are here to help you. 5. Contact CORL if there will be a delay in returning the questionnaire. We understand that delays can happen. Keeping us informed helps us keep your client up to date and helps reduce negative response time scores. 6. Respond to requests for clarification or additional artifacts in a timely manner.
A4: "IRQ" - Inherent Risk Questionnaire - Business Owner to Complete
B5: Avera Health Business Owner completes the Inherent Risk Questionnaire ("IRQ") to facilitate better understanding of the scope of business between the Vendor and the organization for the vendor security risk management project.
A7: "VPQ" - Vendor Profile Questionnaire - Vendor to Complete
B8: Please complete this questionnaire as it relates to the business relationship between your organization and Avera Health. In the "Disclosure Permitted?" column, please indicate if CORL Technologies may disclose the responses provided herein to other CORL Technologies clients who also utilize your organization as a vendor. Allowing such disclosure may expedite future assessments.
A10: Scope - Vendor to Complete
B11: Please identify all environments that will handle, process, transmit, or store Avera Health data. Please provided a response to all questions for each identified environment.
A13: "VSQ" - Vendor Security Questionnaire - Excel worksheets 1-17 herein - Vendor to Complete
B14: Avera Health is obligated by regulations and internal risk management policies to gain reasonable assurance that its vendors are protecting Avera Health data. To meet this obligation, Avera Health is requiring vendors to complete this Vendor Security Questionnaire (VSQ) within 10 business days of receiving it. All "N/A" and "Partial" responses MUST be accompanied by an explanation in the comments column. Any questions should be directed to CORL Client Engagement clientengagement@corltech.com.
A16: "Required Evidence" - Evidence and Assurances specific to CLIENT - Vendor to Provide
B17: Upon completion of this questionnaire, CORL and Avera Health will obtain evidence and assurances relating to the key controls as defined by the Avera Health team. Please indicate within the "Required Evidence" sheet whether you have provided the documentation requested by CORL and Avera Health. Instructions surrounding Evidence and Assurances: The Vendor Profile Questions (VPQ) & Scope sections include questions that relate to information about your organization and the products and services provided to Avera Health. The Vendor Security Questionnaire (worksheets 1-17) section relates to questions about overall security controls at the vendor level and product level. All responses require references to documents that provide evidence of the control. If your organization has received a current security certification, please provide documentation in lieu of evidence. Relevant security certifications include, SOC 2 Type 2 (must include Security TSP), HITRUST and/or ISO 27001. Please provide certification and/or evidence documents along with this completed questionnaire to CORL Technologies within 10 business days.

Sheet Data Validation Key
A1: Response Questions | B1: Data Classifications | C1: Types of Data: | D1: Type of Access | E1: Method of Access | F1: Volume of Records | G1: Financial Value | H1: Breah Business Impact | I1: Geographic Scope | J1: Size of Organization (# of Employees) | K1: How data is stored, hosted | L1: App / Product? | M1: Vendor Age / Business Relationship Length
A2: Yes | B2: Company Data | C2: PHI | D2: Intentionally Shared | E2: Electronic | F2: Most of our patients | G2: High | H2: High | I2: International | J2: > 100,000 | K2: In the Cloud | L2: Yes | M2: < 5 Years
A3: No | B3: Restricted Data | C3: PII | D3: Incidental Access | E3: Physical | F3: Most our employees | G3: Medium High | H3: Medium High | I3: National | J3: > 10,001 | K3: On our Network | L3: No | M3: 5 - 10 Years
A4: Partial | B4: Sensitive Data | C4: PCI | D4: No Access | E4: Electronic and Physical | F4: Data related to a specific business unit or division | G4: Medium | H4: Medium | I4: Single-State | J4: > 1001 | K4: At the Vendor's Location | M4: 11 - 20 Years
A5: N/A | B5: Internal Data | C5: Intellectual property | F5: Data related to a specific service line or facility | G5: Medium Low | H5: Medium Low | J5: > 501 | M5: > 20 Years
B6: Public Data | C6: PHI, PII | F6: Very specific and limited focus | G6: Low | H6: Low | J6: > 51
C7: PHI, PCI | G7: None | H7: None | J7: > 1
C8: PHI, Intellectual property
C9: PCI, PII
C10: PCI, Intellectual property
C11: PII, Intellectual property
C12: All Data types
A20: Key | C20: Overrides
A21: Tier 1 | C21: No Override
A22: Tier 2 | C22: Adequate
A23: Tier 3 | C23: Inadequate
A24: Conditional to other Questions | C24: N/A
A25: Response acceptance dependent on the business relationship btwn client and vendor
A26: Questions dependent on comments and QA by CE

Sheet IVPQ
A1: Initial Vendor Profile Questionnaire - for CLIENT NAME
A2: Vendor name: | D2: Name:
A3: Service(s) / Product(s) provided: | D3: Title:
A4: Vendor Website Domain(s): | D4: Email:
A5: Date Completed: | D5: Phone:
A6: Control Question # | B6: Control Name | C6: Control Questions | D6: Response: | E6: Comments/ Notes: | F6: Evidence Provided | G6: NIST SP800-53 R4: Control # | H6: HIPAA CFR Control Reference(s):
A7: Vendor Discovery Questions:
A8: 1.1 | B8: Accessible Data | C8: Will you have access to the following types of data: | G8: N/A | H8: N/A
A9: 1.1-a | B9: Accessible Data | C9: PHI (Protected Health Information) | G9: N/A | H9: N/A
A10: 1.1-b | B10: Accessible Data | C10: Intellectual Property | G10: N/A | H10: N/A
A11: 1.1-c | B11: Accessible Data | C11: Financial Property | G11: N/A | H11: N/A
A12: 1.1-d | B12: Accessible Data | C12: PII (Personally Identifiable Information) | G12: N/A | H12: N/A
A13: 1.1-e | B13: Accessible Data | C13: PCI (Payment Card Industry) | G13: N/A | H13: N/A
A14: 1.1-f | B14: Accessible Data | C14: Employee Information | G14: N/A | H14: N/A
A15: 1.2 | B15: Security Leadership | C15: Do you have a designated responsible leader for information security? If so, please explain their title and role in the comments section. | G15: N/A | H15: N/A
A16: 1.3 | B16: Security Assurances | C16: Has your company attained any of the following security certifications or external, independent validations of the following:? | G16: N/A | H16: N/A
A17: 1.3-a | B17: Security Assurances | C17: SOC (indicate SOC 1, 2 or 3 and type 1 or 2) | F17: Example evidence: certification document | G17: N/A | H17: N/A
A18: 1.3-b | B18: Security Assurances | C18: HITRUST | F18: Example evidence: certification document | G18: N/A | H18: N/A
A19: 1.3-c | B19: Security Assurances | C19: PCI Compliance | F19: Example evidence: certification document | G19: N/A | H19: N/A
A20: 1.3-d | B20: Security Assurances | C20: ISO 27001 | F20: Example evidence: certification document | G20: N/A | H20: N/A
A21: 1.3-e | B21: Security Assurances | C21: FedRAMP | F21: Example evidence: certification document | G21: N/A | H21: N/A
A22: 1.3-f | B22: Security Assurances | C22: HIPAA (please provide type of assessment performed and certifying organization in the comments section) | F22: Example evidence: certification document | G22: N/A | H22: N/A
A23: 1.3-g | B23: Security Assurances | C23: NIST (please provide type of assessment performed and certifying organization in the comments section) | F23: Example evidence: certification document | G23: N/A | H23: N/A
A24: 1.3-h | B24: Security Assurances | C24: Other? (please specify in the comments section) | F24: Example evidence: certification document | G24: N/A | H24: N/A
A25: 1.4 | B25: Cyber Liability Insurance | C25: Do you maintain cyber liability insurance in addition to general liability insurance? If Yes, please explain how much in the comments section. | F25: Example evidence: insurance policy | G25: N/A | H25: N/A
A26: 1.5 | B26: Contractors/Subcontractors | C26: Do you use any employees, contractors or subcontractors outside of the United States? | E26: Please list locations and approximate # of employees at each location | G26: N/A | H26: N/A
A27: 1.6 | B27: Contractors/Subcontractors | C27: Do any of your subcontractors (foreign or domestic) have access to sensitive and/or confidential data? If yes, please name the companies and services they provide to you in the comments section. | E27: Please provide a list of sub-contractors | G27: N/A | H27: N/A
A28: 1.7 | B28: Employee Screenings | C28: Do you conduct background checks for all employees, contractors and subcontractors? If not, for which areas/positions do you require a background check. Please explain in the comments section. | G28: PS-3 | H28: 164.308(a)(3)(ii)(B)
A29: 1.8 | B29: Data Storage | C29: Is this a remote hosted or cloud system? If yes, please answer the following questions. | G29: N/A | H29: N/A
A30: 1.8-a | B30: Data Storage | C30: Do you have any data centers outside of the United States? | G30: N/A | H30: N/A
A31: 1.8-b | B31: Data Storage | C31: Can data be restricted to be stored only within the United States? | G31: N/A | H31: N/A
A32: 1.9 | B32: Data Storage | C32: Will data be stored at an encrypted data center? | E32: Please list names of recognized data centers | G32: SC-13 | H32: 164.312(a)(2)(iv) 164.312(e)(2)(ii)
A33: 1.1 | B33: Data Center Security Assurances | C33: What certifications does your data center have or external, independent validations of the following:? | G33: N/A | H33: N/A
A34: 1.10-a | B34: Data Center Security Assurances | C34: SOC (indicate SOC 1, 2, or 3 and type 1 or 2) | G34: N/A | H34: N/A
A35: 1.10-b | B35: Data Center Security Assurances | C35: PCI Compliance | G35: N/A | H35: N/A
A36: 1.10-c | B36: Data Center Security Assurances | C36: HITRUST | G36: N/A | H36: N/A
A37: 1.10-d | B37: Data Center Security Assurances | C37: ISO 27001 | G37: N/A | H37: N/A
A38: 1.10-e | B38: Data Center Security Assurances | C38: FedRAMP | G38: N/A | H38: N/A
A39: 1.10-f | B39: Data Center Security Assurances | C39: HIPAA (please provide type of assessment performed and certifying organization in the comments section) | G39: N/A | H39: N/A
A40: 1.10-g | B40: Data Center Security Assurances | C40: NIST (please provide type of assessment performed and certifying organization in the comments section) | G40: N/A | H40: N/A
...

Sheet IRQ
A1: Inherent Risk Questionnaire ("IRQ")
A2: Official Name of Vendor: | D2: Vendor POC Name:
A3: Vendor-specific business unit / division, if applicable: | D3: Vendor POC Title:
A4: Vendor Website Domain(s): | D4: Vendor POC Email:
A5: Date IRQ Completed: | D5: Vendor POC Phone #:
A6: Control Question # | B6: Control Name | C6: Control Questions | D6: Response | E6: Notes
A7: Inherent Risk Questions:
A8: 1 | B8: Products and Applications | C8: Does your organization use a vendor specific service/product(s)? (if "Yes" please list the names of the services/products in "Notes")
A9: 2 | B9: Accessible Data | C9: Type of data vendor will have access to:
A10: 3 | B10: Data Storage | C10: Where will the data of your organization be stored, hosted?
A11: 4 | B11: Report Support | C11: Does vendor provide remote support?
A12: 5 | B12: Records | C12: Volume of your organization's records accessible by vendor:
A13: 6 | B13: Vendor Business Operations | C13: Geographic scope of the vendor (if vendor has international operations, please list country name(s) in "Notes"):
A14: 7 | B14: Vendor Age | C14: How long has the vendor been in business in general?
A15: 8 | B15: Business Relationship Length | C15: How long has the vendor been in business with your organization?
A16: 9 | B16: Annual Revenue | C16: What is the vendor's annual revenue?
A17: 10 | B17: Vendor Size | C17: Size of the vendor (# of employees):
A18: 11 | B18: Business Associate Agreement (BAA) | C18: Is there an executed Business Associate Agreement between your organization and the vendor?
A19: 12 | B19: Information Security Agreement (ISA) | C19: Is there an executed Information Security Agreement between your organization and the vendor?
A20: 13 | B20: Security Assessment Activities | C20: Has your organization completed security assessment activities on the vendor in the past? (if "Yes" please describe the assessment scope and approximate timeframe in "Notes"):

Sheet Vendor Profile Questionnaire
A1: Instructions: Please complete this questionnaire as it relates to the business relationship between your organization and Avera Health. In the "Disclosure Permitted?" column, please indicate if CORL Technologies may disclose the responses provided herein to other CORL Technologies clients who also utilize PeriGen. Allowing such disclosure may expedite future assessments.
A2: Initial Vendor Profile Questionnaire - on behalf of Avera Health
A3: PeriGen: | D3: Name: | E3: Bruno Bendavid
A4: Service(s) / Product(s) provided: | B4: PeriWatch Tracings | D4: Title: | E4: SVP Product Management
A5: Vendor Website Domain(s): | B5: www.perigen.com | D5: Email: | E5: bruno.bendavid@perigen.com
A6: Date Completed: | D6: Phone: | E6: 514-978-0611
A7: Vendor Discovery Questions:
A8: Questions | B8: Response | C8: Disclosure Permitted? | D8: Comments
A10: Does PeriGen have a designated leader responsible for information security? | B10: Yes | C10: Yes
A11: Name of Information Security leader? | B11: Bruno Bendavid | C11: Yes
A12: Title | B12: SVP Product Management | C12: Yes
A13: Role | B13: Direct/Manage/Prioritize product content and schedules | C13: Yes
A14: Does PeriGen employ an information security team? | B14: No | C14: Yes
A15: Number of full-time information security personnel? | C15: Yes
A16: Does PeriGen employ an incident response officer? | B16: Yes | C16: Yes
A17: Name of incident response officer? | B17: Bruno Bendavid | C17: Yes
A18: Title | B18: SVP Product Management | C18: Yes
A19: Email | B19: bruno.bendavid@perigen.com | C19: Yes
A20: Phone | B20: 514-978-0611 | C20: Yes
A21: Does PeriGen outsource information security functions to a third party? If yes, please provide the name and scope of services provided in the comments section. | B21: Yes | C21: Yes | D21: DSI Tech (https://dsitech.com/) which provide IT management and support
A22: Does VENDOR maintain cyber liability insurance in addition to general liability insurance? If Yes, please explain how much in the comments section. | B22: Yes | C22: No | D22: 5,000,000$
A23: Does PeriGen have any employees or physical office locations outside of the United States? | B23: Yes | C23: Yes
A24: Is any Avera Health data accessed, transmitted, or stored outside of the United States? | B24: No | C24: Yes
A25: What year was PeriGen founded? | B25: 36164 | C25: Yes
A26: Approximately how many people does PeriGen employ? | B26: <100 | C26: Yes
A27: Has PeriGen ever experienced a data breach? If so, please explain in the comments section. | B27: No | C27: Yes
A28: Is there a current BAA in place? | B28: Yes | C28: Yes
A29: Does PeriGen utilize any subcontractors with access Avera Health data? If yes, please provide the name of the subcontractor(s) in the comments section. | B29: No | C29: Yes
A30: Please describe how your organization obtains data from Avera Health. Include file type(s) and the medium(s) utilized to transmit the data (e.g., SFTP, Encrypted email). | B30: All connectivity is done via SecureLink. Not data is transmitted outside Avera's netwrok. | C30: N/A

Sheet Scope
A1: Vendor Scope Questions
A2: Instructions: Please identify all environments that will handle, process, transmit, or store Avera Health data. Please provided a response to all questions for each identified environment. | B2: PeriWatch Tracings - Avera Enterprise instance | D2: Environment 2 | F2: Environment 3
B3: Response | C3: Comments | D3: Response | E3: Comments | F3: Response | G3: Comments
A4: Please identity the environment (e.g., back office, data center, application's/software's name, service/solution name) in the "response" column and provide a brief description in the comments section: | B4: Client -server application hosted at the data center
A5: Is the identified environment either of the following:
A6: Service | B6: No
A7: Product | B7: Yes | C7: PeriWatch Tracings
A8: What is the volume of Avera Health records that the identified environment will transmit, process, or store? | B8: Only L&D records so a function of birth rate | C8: Data is only stored on hospital hosted servers. An estimate of volume of data stored on hospital servers including long term archive files is ~10GB (steady state) + 5GB per year as continuous archive files per pregnancy
A9: Please indicate if the identified environment will: | B9: If "yes", please provide details in the comments section.
A10: have access into the Avera Health's network for remote Support | B10: Yes | C10: Remote support is only provided by SecureLink (Avera approved)
A11: have access into the Avera Health's network to provide onsite support | B11: Yes | C11: Only on Avera's request
A12: Have access to infrastructure that stores or transmits Avera Health data: | B12: Yes | C12: Only via HL7
A13: Have access to a database or application that stores or transmits Avera Health data: | B13: Yes | C13: Only via HL7
A14: Receive transmitted data from Avera Health | B14: Yes | C14: Only via HL7
A15: Not access Avera Health's information
A16: What types of Avera Health information will the identified environment have access to: | B16: If "yes", please provide details in the comments section.
A17: PHI (Protected Health Information) | B17: Yes
A18: PII (Personally Identifiable Information) | B18: Yes
A19: PCI (Payment Card Industry) | B19: No
A20: Employee Information | B20: No
A21: Avera Health Internal/Proprietary Information | B21: No
A22: Please indicate if the identified environment will utilize the following device(s) to access and/or transmit Avera Health data: | B22: If "yes", please provide details in the comments section.
A23: Workstation | B23: Yes | C23: Client application is installed on applicable workstations where clinicians can see real-time vitals and chart applicable data to the patient record. Data is then trasmitted from the server to the EMR over HL7
A24: Mobile Device | B24: No
A25: Medical Device | B25: Yes | C25: Fetal monitors
A26: Other Method? Please explain in the comments section | B26: No
A27: Please indicate all locations where the data will be stored for the identified environment: | B27: If "yes", please provide details in the comments section.
A28: Avera Health Data Center | B28: Yes
A29: PeriGen Data Center | B29: No
A30: 3rd Party Data Center | B30: No
A31: Workstation | B31: No
A32: Mobile Device | B32: No
A33: Medical Device | B33: No
A34: Other? Please explain in the comments section | B34: No
A35: Does the identified environment maintain any of the following security assurances:
A36: SSAE 16 / SOC 1 Type 1 | B36: No | C36: The system is fully hosted by Avera therefore our understanding is that the question in this section apply to Avera
A37: SSAE 16 / SOC 1 Type 2 | B37: No
A38: SOC 2 Type 1 | B38: No
A39: SOC 2 Type 2 | B39: No
A40: SOC 3 | B40: No
...

Sheet Network_Architecture_Diagrams
A1: Objective: | B1: Summary/Explanation (if diagrams are not available): | C1: Evidence/Assurance
A2: Please provide any and all network architecture diagram(s) within this worksheet: | C2: Please attach network architecture diagram(s) or provide screenshots below:

Sheet Connectivity Mapping
A1: Objective: | B1: Summary/Explanation: | C1: Evidence/Assurance
A2: Please provide a summary of how you will be connecting to the Avera Health Network (if applicable) | C2: If necessary please provide supporting documentation

Sheet Required Evidence
A1: Key Control Question Reference # | B1: Key Control: | C1: Control Area # | D1: Evidence Requested: | E1: Provided to CORL? | F1: Vendor Comments
A2: AC-2.1 - AC-2.5 | B2: Account Management | C2: AC-2 | D2: Provide Policy and procedures for managing accounts, including - creating, modifying, monitoring, and deleteing/disabling accounts.
A3: AC-17.1 - AC-17.3 | B3: Remote Access | C3: AC-17 | D3: Provide policy and procedure for remote access
A4: AC-3.1 | B4: Wireless Access | C4: AC-3 | D4: Provide Wireless Access Policy and Procedures
A5: AU-1.1 | B5: Audit and Accountability | C5: AU-1 | D5: Provide Audit log policy and procedures
A6: CM-2.1 | B6: Baseline Configuration | C6: CM-2 | D6: Provide the most recent Baseline Configuration document for the information system (e.g., hardening procedures for Window OS, baseline security settings for sever AND application builds.)
A7: CM-3.1 - CM-3.6 | B7: Configuration Change Control | C7: CM-3 | D7: Configuration Change Control procedures
A8: CM-5.1 | B8: Access Restrictions for Change | C8: CM-5 | D8: Configuration Change Control procedures
A9: CM-6.1 - CM-6.3 | B9: Configuration Settings | C9: CM-6 | D9: Provide report monitoring records related to most recent changes to the Configuration settings information system
A10: CM-7.1 | B10: Least Functionality | C10: CM-7 | D10: (See CM 2.1 - Most recent Baseline Configuration)
A11: CM-8.1 - CM-8.2 | B11: Information System Component Inventory | C11: CM-8 | D11: Provide documentation that demonstrates information system Component Inventory is maintained and kept up to date.
A12: CM-9.1 - CM-9.4 | B12: Configuration Management Plan | C12: CM-9 | D12: Provide Software Development/Deployment Life Cycle (SDLC) documentation which includes secure coding procedures, where applicable.
A13: CM-10.1 | B13: Software Usage Restrictions | C13: CM-10 | D13: Provide Acceptable Use policy. Provide samples of software licensing documentation.
... A32: IR-8 | B32: Incident Response Plan | C32: IR-8 | D32: Is there a comprehensive Incident Response Plan? If so, please attach.

Sheet 1. Access Controls
A1: Control Question # | B1: NIST SP800-53 R4: Control # | C1: HIPAA CFR Control Reference(s) | D1: HITRUST CSF | E1: Control Name | F1: Security Questions: | G1: =Scope!$B$4 & " Response:" -> Client -server application hosted at the data center Response: | H1: =Scope!$B$4 &" Comments:" -> Client -server application hosted at the data center Comments: | I1: =Scope!$D$4 & " Response:" -> Response: | J1: =Scope!$D$4 & " Comments:" -> Comments: | K1: =Scope!$F$4 & " Response:" -> Response: | L1: =Scope!$F$4 & " Comments:" -> Comments:
A2: Access Control
A3: AC-1.1 | B3: AC-1 | C3: 164.308(a)(3)(i) 164.308(a)(3)(ii)(A) 164.308(a)(4)(i) 164.308(a)(4)(ii)(B) 164.308(a)(4)(ii)(C) 164.312(a)(1) | D3: 01.a 01.i 04.a | E3: Access Control Policy and Procedures | F3: Are there formally documented policies and procedures for access control? If yes, please attach. | H3: Comment is required | J3: Comment is required | L3: Comment is required
A4: AC-2.1 | B4: AC-2 | C4: 164.308(a)(3)(ii)(A) *From AC-13 164.308(a)(3)(ii)(B) 164.308(a)(4)(i) 164.308(a)(4)(ii)(B) 164.308(a)(4)(ii)(C) 164.308(a)(5)(ii)(C) 164.312(a)(2)(i) 164.312(a)(2)(ii) | D4: 01.b 01.c 01.e 02.i | E4: Account Management | F4: Do you have a process for managing accounts, including - creating, modifying, monitoring, and deleting/disabling accounts? | H4: Comment is required | J4: Comment is required | L4: Comment is required
A5: AC-2.2 | F5: Are accounts reviewed on a periodic basis? If yes, include timeframe in comment. | H5: Comment is required | J5: Comment is required | L5: Comment is required
A6: AC-2.3 | F6: Have all guest, shared (other than Admin/Root), or group accounts been removed or disabled? | H6: Comment is required | J6: Comment is required | L6: Comment is required
A7: AC-2.4 | F7: Are account managers notified when accounts are no longer required, when users are terminated or transferred, or when individual access requirements change? | H7: Comment is required | J7: Comment is required | L7: Comment is required
A8: AC-2.5 | F8: Is approval from an authorized signer required before provisioning accounts? | H8: Comment is required | J8: Comment is required | L8: Comment is required
A9: AC-3.1 | B9: AC-3 | C9: 164.308(a)(3)(ii)(A) 164.308(a)(4)(ii)(B) 164.308(a)(4)(ii)(C) 164.310(a)(2)(iii) 164.310(b) 164.312(a)(1) 164.312(a)(2)(i) 164.312(a)(2)(ii) 164.312(a)(2)(iv) | D9: 01.s 01.v | E9: Access Enforcement | F9: Does the information system verify the rights of a user to access the information system? (Access Control Lists, Group/Role membership?) If yes, detail how the access is enforced in the comment. | H9: Comment is required | J9: Comment is required | L9: Comment is required
A10: AC-3.2 | B10: N/A | F10: Does the information system support role-based account management and access controls (RBAC)? | H10: Comment is required | J10: Comment is required | L10: Comment is required
A11: AC-3.3 | B11: N/A | F11: If RBAC is supported, can a customer administrator create/customize unique roles and permissions. | H11: Comment is required | J11: Comment is required | L11: Comment is required
A12: AC-4.1 | B12: AC-4 | C12: 164.308(a)(3)(ii)(A) 164.308(a)(4)(ii)(B) 164.310(b) | D12: 01.m 01.o | E12: Information Flow Enforcement | F12: Is the flow of sensitive information secured between interconnected systems? (Firewall rule sets - iptables, proxies, encrypted tunnels.) | H12: Comment is required | J12: Comment is required | L12: Comment is required
A13: AC-5.1 | B13: AC-5 | C13: 164.308(a)(3)(i) 164.308(a)(4)(i) 164.308(a)(4)(ii)(A) 164.312(a)(1) | E13: Separation of Duties | F13: Is separation of duties implemented? (E.g., Mission functions and support functions divided among personnel, different administrative accounts for different roles.) | H13: Comment is required | J13: Comment is required | L13: Comment is required
A14: AC-6.1 | B14: AC-6 | C14: 164.308(a)(3)(i) 164.308(a)(3)(ii)(A) *From AC-13 164.308(a)(4)(i) 164.308(a)(4)(ii)(A) 164.308(a)(4)(ii)(B) *From AC-13 164.308(a)(5)(ii)(C) *From AC-13 164.312(a)(1) | D14: 01.c 01.s 01.v | E14: Least Privilege | F14: Is least privilege employed? (I.e., must administrators switch to the root or a separate administrator account to perform administrative functions/make system changes?) | H14: Comment is required | J14: Comment is required | L14: Comment is required
A15: AC-7.1 | B15: AC-7 | D15: 01.p | E15: Unsuccessful Logon Attempts | F15: Is an account automatically locked out after a set amount of attempts? If yes, please provide the number of failed attempts that trigger an account to be locked out, in the comments section. | H15: Comment is required | J15: Comment is required | L15: Comment is required
A16: AC-8.1 | B16: AC-8 | D16: 01.p 05.j | E16: System Use Notification | F16: Is there a system use notification displayed before granting access that provides privacy and security notices? | H16: Comment is required | J16: Comment is required | L16: Comment is required
A17: AC-9.1 | B17: AC-9 | D17: 01.p | E17: Previous Logon Notification | F17: Does the system display the last user logon date and time to the user? | H17: Comment is required | J17: Comment is required | L17: Comment is required
A18: AC-10.1 | B18: AC-10 | D18: 01.p | E18: Concurrent Session Control | F18: Does the system limit the number of concurrent sessions for the user? | H18: Comment is required | J18: Comment is required | L18: Comment is required
A19: AC-11.1 | B19: AC-11 | C19: 164.310(b) 164.312(a)(2)(iii) | D19: 01.g 01.h 01.t | E19: Session Lock | F19: Does the application/system have a session lock after a period of inactivity that requires a user to reauthenticate? | H19: Comment is required | J19: Comment is required | L19: Comment is required
A20: AC-12.1 | B20: AC-12 | C20: 164.310(b) 164.312(a)(2)(iii) | D20: 01.t | E20: Session Termination | F20: Does the application/system terminate the session after predefined circumstances? | H20: Comment is required | J20: Comment is required | L20: Comment is required
A21: AC-14.1 | B21: AC-14 | D21: 01.v | E21: Permitted Actions without Identification or Authentication | F21: Does the system prevent user actions that can be performed on the system without identification and authentication? | H21: Comment is required | J21: Comment is required | L21: Comment is required
A22: AC-16.1 | B22: AC-16 | C22: 164.310(b) | E22: Security Attributes | F22: Is protected health information identified as such with access only provided to authorized personnel? | H22: Comment is required | J22: Comment is required | L22: Comment is required
A23: AC-17.1 | B23: AC-17 | C23: 164.310(b) | D23: 01.i 01.j 01.n 01.x 01.y | E23: Remote Access | F23: Is remote access allowed from outside the network only through the use of the VPN client? | H23: Comment is required | J23: Comment is required | L23: Comment is required
A24: AC-17.2 | F24: Are there established and documented usage restrictions for those connections? | H24: Comment is required | J24: Comment is required | L24: Comment is required
A25: AC-17.3 | F25: Is remote access to the information system authorized prior to allowing such connections? | H25: Comment is required | J25: Comment is required | L25: Comment is required
A26: AVH-AC-17.4 | F26: All vendors and 3rd party consultants are required to utilize SecureLink for all remote access requests. Is your organization able to use SecureLink for all remote access requests? If not, please explain why not. Additionally, please provide the name and supplemental documentation of the remote access solution currently used by your organization for review by Avera's Information Security department in lieu of SecureLink | H26: Comment is required | J26: Comment is required | L26: Comment is required
A27: AC-18.1 | B27: AC-18 | D27: 01.i 01.j 01.n 01.x | E27: Wireless Access | F27: Does the information system and/or associated device allow wireless access and only connect to secure networks? (Network access, Bluetooth, infrared, etc.) | H27: Comment is required | J27: Comment is required | L27: Comment is required
A28: AC-19.1 | B28: AC-19 | C28: 164.310(b) | D28: 01.k 01.n 01.x | E28: Access Control for Mobile Devices | F28: Can users or administrators connect using mobile devices (i.e. iPad, Smart Phone, PDAs)? | H28: Comment is required | J28: Comment is required | L28: Comment is required
A29: AC-19.2 | F29: Are there established and documented usage restrictions for those connections? | H29: Comment is required | J29: Comment is required | L29: Comment is required
A30: AC-19.3 | F30: Is remote access to the information system authorized prior to allowing such connections? | H30: Comment is required | J30: Comment is required | L30: Comment is required
A31: AC-20.1 | B31: AC-20 | D31: 01.i 01.j 01.n 05.i | E31: Use of External Information Systems | F31: Does the information system have any trust relationships with external environments? (E.g., interconnection agreements with third parties.) | H31: Comment is required | J31: Comment is required | L31: Comment is required
A32: AC-20.2 | F32: Are there established terms and conditions to access, process, store, or transmit organizational information using their systems? | H32: Comment is required | J32: Comment is required | L32: Comment is required
A33: AC-21.1 | B33: AC-21 | D33: 01.c | E33: Information Sharing | F33: Does the organization facilitate information sharing by enabling authorized users to determine whether access authorizations assigned to the sharing partner match the access restriction on the information for the user? | H33: Comment is required | J33: Comment is required | L33: Comment is required
A34: AC-22.1 | B34: AC-22 | E34: Publicly Accessible Content | F34: Is there any publicly accessible information? | H34: Comment is required | J34: Comment is required | L34: Comment is required
A35: AC-22.2 | F35: Are designated individuals trained to post and review information on the publicly accessible site? | H35: Comment is required | J35: Comment is required | L35: Comment is required

Sheet 2. Awareness and Training
A1: Control Question # | B1: NIST SP800-53 R4: Control # | C1: HIPAA CFR Control Reference(s) | D1: HITRUST CSF | E1: Control Name | F1: Security Questions: | G1: =Scope!$B$4 & " Response:" -> Client -server application hosted at the data center Response: | H1: =Scope!$B$4 &" Comments:" -> Client -server application hosted at the data center Comments: | I1: =Scope!$D$4 & " Response:" -> Response: | J1: =Scope!$D$4 & " Comments:" -> Comments: | K1: =Scope!$F$4 & " Response:" -> Response: | L1: =Scope!$F$4 & " Comments:" -> Comments:
A2: Awareness and Training
A3: AT-1.1 | B3: AT-1 | C3: 164.308(a)(5)(i) | D3: 02.e 04.a | E3: Security Awareness and Training Policy and Procedures | F3: Are there formally documented procedures for security awareness and training for this information system? If yes, please attach. | H3: Comment is required | J3: Comment is required | L3: Comment is required
A4: AT-2.1 | B4: AT-2 | C4: 164.308(a)(5)(i) 164.308(a)(5)(ii)(A) 164.308(a)(5)(ii)(B) | D4: 02.e 05.j | E4: Security Awareness | F4: Is basic security awareness training performed for all personnel as a part of the onboarding process? | H4: Comment is required | J4: Comment is required | L4: Comment is required
A5: AT-2.2 | F5: Is it periodically performed for all users? | H5: Comment is required | J5: Comment is required | L5: Comment is required
A6: AT-3.1 | B6: AT-3 | C6: 164.308(a)(5)(i) | D6: 02.e 05.j | E6: Role-Based Security Training | F6: Is there role-based security training for personnel with assigned security roles and responsibilities for this information system before access is granted and when required by information system changes? | H6: Comment is required | J6: Comment is required | L6: Comment is required
A7: AT-4.1 | B7: AT-4 | C7: 164.308(a)(5)(i) | D7: 02.e | E7: Security Training Records | F7: Do you document and monitor information system security training activities for individuals? | H7: Comment is required | J7: Comment is required | L7: Comment is required

Sheet 3. Audit and Accountability
A1: Control Question # | B1: NIST SP800-53 R4: Control # | C1: HIPAA CFR Control Reference(s) | D1: HITRUST CSF | E1: Control Name | F1: Security Questions: | G1: =Scope!$B$4 & " Response:" -> Client -server application hosted at the data center Response: | H1: =Scope!$B$4 &" Comments:" -> Client -server application hosted at the data center Comments: | I1: =Scope!$D$4 & " Response:" -> Response: | J1: =Scope!$D$4 & " Comments:" -> Comments: | K1: =Scope!$F$4 & " Response:" -> Response: | L1: =Scope!$F$4 & " Comments:" -> Comments:
A2: Audit and Accountability
A3: AU-1.1 | B3: AU-1 | C3: 164.312(b) | D3: 02.a 04.a 04.b 05.a 05.b 05.c | E3: Audit and Accountability Policy and Procedures | F3: Are there formally documented audit and accountability procedures for this information system? If yes, please attach. | H3: Comment is required | J3: Comment is required | L3: Comment is required
A4: AU-2.1 | B4: AU-2 | C4: 164.308(a)(5)(ii)(C) 164.312(b) | D4: 01.s | E4: Audit Events | F4: Is the information system actively auditing events such as access to patient information, login/logoffs, account creation, etc.? If yes, please detail the events captured in the comment. | H4: Comment is required | J4: Comment is required | L4: Comment is required
A5: AU-2.2 | F5: Are the audit logs captured sufficient for incident response and system and user performance/investigation? | H5: Comment is required | J5: Comment is required | L5: Comment is required
A6: AU-3.1 | B6: AU-3 | C6: 164.312(b) | E6: Content of Audit Records | F6: Does the system create audit records that contain sufficient information to, at a minimum, establish what type of event occurred, when the event occurred, where the event occurred, the source of the event, the outcome (success or failure) of the event, and the identity of any user/subject associated with the event? | H6: Comment is required | J6: Comment is required | L6: Comment is required
A7: AU-4.1 | B7: AU-4 | C7: 164.312(b) | E7: Audit Storage Capacity | F7: Have you evaluated the audit storage capacity of this information system and determined that it is adequate? | H7: Comment is required | J7: Comment is required | L7: Comment is required
A8: AU-5.1 | B8: AU-5 | E8: Response to Audit Processing Failures | F8: Does the information system generate an alert that notifies the team in the event of an audit processing failure? | H8: Comment is required | J8: Comment is required | L8: Comment is required
A9: AU-6.1 | B9: AU-6 | C9: 164.308(a)(1)(ii)(D) 164.308(a)(3)(ii)(A) 164.308(a)(4)(i) 164.308(a)(5)(ii)(C) 164.312(b) | E9: Audit Review, Analysis, and Reporting | F9: Do you review the audit logs for indications of inappropriate or unusual activity and report those incidents to authorized personnel? | H9: Comment is required | J9: Comment is required | L9: Comment is required
A10: AU-7.1 | B10: AU-7 | C10: 164.308(a)(1)(ii)(D) 164.312(b) | E10: Audit Reduction and Report Generation | F10: Does the information system provide the capability to generate customizable audit reports? | H10: Comment is required | J10: Comment is required | L10: Comment is required
A11: AU-7.2 | F11: Does the generation of an audit report alter the original content or time stamp of the audit record? | H11: Comment is required | J11: Comment is required | L11: Comment is required
A12: AU-8.1 | B12: AU-8 | E12: Time Stamps | F12: Are the audit logs time stamped? (Date and Time) | H12: Comment is required | J12: Comment is required | L12: Comment is required
A13: AU-9.1 | B13: AU-9 | E13: Protection of Audit Information | F13: Does the system/application protect audit information from unauthorized access, modification, and deletion? | H13: Comment is required | J13: Comment is required | L13: Comment is required
A14: AU-11.1 | B14: AU-11 | E14: Audit Record Retention | F14: Does the information system retain audit records in accordance with implemented policies? | H14: Comment is required | J14: Comment is required | L14: Comment is required
A15: AU-12.1 | B15: AU-12 | E15: Audit Generation | F15: Can the information system be configured to select which auditable events are captured in the audit log? | H15: Comment is required | J15: Comment is required | L15: Comment is required

Sheet 4. Security Assessment
A1: Control Question # | B1: NIST SP800-53 R4: Control # | C1: HIPAA CFR Control Reference(s) | D1: HITRUST CSF | E1: Control Name | F1: Security Questions: | G1: =Scope!$B$4 & " Response:" -> Client -server application hosted at the data center Response: | H1: =Scope!$B$4 &" Comments:" -> Client -server application hosted at the data center Comments: | I1: =Scope!$D$4 & " Response:" -> Response: | J1: =Scope!$D$4 & " Comments:" -> Comments: | K1: =Scope!$F$4 & " Response:" -> Response: | L1: =Scope!$F$4 & " Comments:" -> Comments:
A2: Security Assessment and Authorization
A3: CA-1.1 | B3: CA-1 | C3: 164.308(a)(8) | D3: 02.a 04.a 04.b 05.a 05.b 05.c | E3: Security Assessment and Authorization Policies and Procedures | F3: Are there formally documented policies and procedures for Security Assessments and Authorizations? If yes, please attach. | H3: Comment is required | J3: Comment is required | L3: Comment is required
A4: CA-2.1 | B4: CA-2 | C4: 164.308(a)(2) *From CA-04 164.308(a)(8) | D4: 03.b 05.h 05.j 05.k | E4: Security Assessments | F4: Has the scope of the security assessment plan been addressed, and does it cover specific security controls and enhancements? | H4: Comment is required | J4: Comment is required | L4: Comment is required
A5: CA-2.2 | F5: Are interconnection security agreements documented? (e.g. interface characteristics, security requirements, data types transmitted) | H5: Comment is required | J5: Comment is required | L5: Comment is required
A6: CA-2.3 | F6: Are these connections monitored for compliance with the agreements? | H6: Comment is required | J6: Comment is required | L6: Comment is required
A7: CA-3.1 | B7: CA-3 | C7: 164.308(b)(1) 164.308(b)(4) 164.314(a)(2)(ii) | D7: 01.j 05.i 05.j 05.k | E7: System Interconnections | F7: Does this information system interface with any other information system? | H7: Comment is required | J7: Comment is required | L7: Comment is required
A8: CA-3.2 | F8: Are the interfaces that interconnect with this information system documented? | H8: Comment is required | J8: Comment is required | L8: Comment is required
A9: CA-3.3 | F9: Is there documentation on what information is communicated through that interface and what the security requirements are? | H9: Comment is required | J9: Comment is required | L9: Comment is required
A10: CA-5.1 | B10: CA-5 | D10: 03.c | E10: Plan of Action and Milestones | F10: Have previous assessment results been used to mitigate identified risks? | H10: Comment is required | J10: Comment is required | L10: Comment is required
A11: CA-6.1 | B11: CA-6 | C11: 164.308(a)(2) 164.308(a)(8) | D11: 05.d | E11: Security Authorization | F11: Is there an authorizing official for this environment? Can they decide if an environment is turned off if necessary? | H11: Comment is required | J11: Comment is required | L11: Comment is required
A12: CA-6.2 | F12: Have assessments been officially signed off? By whom? | H12: Comment is required | J12: Comment is required | L12: Comment is required
A13: CA-7.1 | B13: CA-7 | C13: 164.308(a)(1)(ii)(D) 164.308(a)(8) | D13: 05.h | E13: Continuous Monitoring | F13: Is there a continuous monitoring strategy? What metrics are used to ensure compliance? | H13: Comment is required | J13: Comment is required | L13: Comment is required
A14: CA-7.2 | F14: Are continuous monitoring results analyzed? | H14: Comment is required | J14: Comment is required | L14: Comment is required
A15: CA-7.3 | F15: Are security controls monitored for compliance? What actions are taken if components are deemed non-compliant? | H15: Comment is required | J15: Comment is required | L15: Comment is required
A16: CA-7.4 | F16: Are the results of continuous monitoring reported to an authorizing official? | H16: Comment is required | J16: Comment is required | L16: Comment is required
A17: CA-8.1 | B17: CA-8 | E17: Penetration Testing | F17: Does your organization do penetration testing on internal networks? | H17: Comment is required | J17: Comment is required | L17: Comment is required
A18: CA-9.1 | B18: CA-9 | E18: Internal System Connections | F18: Is there a device or component that is uniquely used with this system? (E.g., biomedical devices used particularly with this information system). | H18: Comment is required | J18: Comment is required | L18: Comment is required
A19: CA-9.2 | F19: Is there documentation on what information is communicated with that device, how it is transferred, and how the data is secured? | H19: Comment is required | J19: Comment is required | L19: Comment is required

Sheet 5. Configuration
A1: Control Question # | B1: NIST SP800-53 R4: Control # | C1: HIPAA CFR Control Reference(s) | D1: HITRUST CSF | E1: Control Name | F1: Security Questions: | G1: =Scope!$B$4 & " Response:" -> Client -server application hosted at the data center Response: | H1: =Scope!$B$4 &" Comments:" -> Client -server application hosted at the data center Comments: | I1: =Scope!$D$4 & " Response:" -> Response: | J1: =Scope!$D$4 & " Comments:" -> Comments: | K1: =Scope!$F$4 & " Response:" -> Response: | L1: =Scope!$F$4 & " Comments:" -> Comments:
A2: Configuration Management
A3: CM-1.1 | B3: CM-1 | D3: 02.a 04.a 04.b 05.a 05.b 05.c | E3: Configuration Management Policy and Procedures | F3: Are there documented procedures to outline who/when and how the system/application is configured? If yes, please attach | H3: Comment is required | J3: Comment is required | L3: Comment is required
A4: CM-2.1 | B4: CM-2 | D4: 01.x | E4: Baseline Configuration | F4: Do you have a current configuration baseline documented for the information system? (The baseline configuration is a documented, up-to-date specification to which the information system is built.) | H4: Comment is required | J4: Comment is required | L4: Comment is required
A5: CM-3.1 | B5: CM-3 | E5: Configuration Change Control | F5: Are types of changes to the information system that are configuration-controlled defined? | H5: Comment is required | J5: Comment is required | L5: Comment is required
A6: CM-3.2 | F6: Does the organization review proposed configuration-controlled changes to the information system, using defined security impact analyses? | H6: Comment is required | J6: Comment is required | L6: Comment is required
A7: CM-3.3 | F7: Are all configuration changes adequately documented? | H7: Comment is required | J7: Comment is required | L7: Comment is required
A8: CM-3.4 | F8: Are all approved configuration controls implemented timely? | H8: Comment is required | J8: Comment is required | L8: Comment is required
A9: CM-3.5 | F9: Does the organization retain records of configuration controlled changes? | H9: Comment is required | J9: Comment is required | L9: Comment is required
A10: CM-3.6 | F10: Are there auditing and monitoring activities implemented to assess the configuration-controlled changes? | H10: Comment is required | J10: Comment is required | L10: Comment is required
A11: CM-4.1 | B11: CM-4 | E11: Security Impact Analysis | F11: Do you analyze changes to the information system to determine potential security impacts prior to change implementation? | H11: Comment is required | J11: Comment is required | L11: Comment is required
A12: CM-5.1 | B12: CM-5 | E12: Access Restrictions for Change | F12: Does the organization define, documents, approves, and enforces physical and logical access restrictions associated with changes to the information system? | H12: Comment is required | J12: Comment is required | L12: Comment is required
A13: CM-6.1 | B13: CM-6 | E13: Configuration Settings | F13: Have all the configuration settings been documented that reflect the most restrictive mode consistent with operational requirements? | H13: Comment is required | J13: Comment is required | L13: Comment is required
A14: CM-6.2 | F14: Is there any automated or manual monitoring of configuration changes? (e.g. Tripwire, manual checklists) | H14: Comment is required | J14: Comment is required | L14: Comment is required
A15: CM-6.3 | F15: Do you document and approve deviations from the established configuration settings? | H15: Comment is required | J15: Comment is required | L15: Comment is required
A16: CM-7.1 | B16: CM-7 | D16: 01.n 01.l | E16: Least Functionality | F16: Do you restrict or prohibit the use of any functions, ports, protocols and/or services that are not essential to the function of the information system? | H16: Comment is required | J16: Comment is required | L16: Comment is required
A17: CM-8.1 | B17: CM-8 | C17: 164.310(d)(1) 164.310(d)(2)(iii) | E17: Information System Component Inventory | F17: Do you have an accurate and current documented inventory of the components within the information system? | H17: Comment is required | J17: Comment is required | L17: Comment is required
A18: CM-8.2 | F18: If yes, do you review and update the information system component inventory regularly? | H18: Comment is required | J18: Comment is required | L18: Comment is required
A19: CM-9.1 | B19: CM-9 | D19: 05.c | E19: Configuration Management Plan | F19: Does the organization develop, document, and implement a configuration management plan for the information system that addresses roles, responsibilities and configuration management processes and procedures? | H19: Comment is required | J19: Comment is required | L19: Comment is required
A20: CM-9.2 | F20: Does the organization establish a process for identifying configuration items throughout the system development life cycle? | H20: Comment is required | J20: Comment is required | L20: Comment is required
A21: CM-9.3 | F21: Does the organization define configuration items for the information system? | H21: Comment is required | J21: Comment is required | L21: Comment is required
A22: CM-9.4 | F22: Does the organization protect the configuration management plan for unauthorized disclosures and modifications? | H22: Comment is required | J22: Comment is required | L22: Comment is required
A23: CM-10.1 | B23: CM-10 | E23: Software Usage Restrictions | F23: Is software usage in accordance with contract agreements and copyright laws? | H23: Comment is required | J23: Comment is required | L23: Comment is required
A24: CM-11.1 | B24: CM-11 | E24: User-Installed Software | F24: Is user installation of software restricted and monitored? | H24: Comment is required | J24: Comment is required | L24: Comment is required
A25: CM-12.1 | B25: N/A | E25: Patch Timeliness | F25: Are patches applied to the information system in a timely manner? If so, how quickly are patches applied? | H25: Comment is required | J25: Comment is required | L25: Comment is required
A26: CM-12.2 | E26: Patch Timeliness Policy | F26: Are there standards or policies which define the timing of patching the information system? | H26: Comment is required | J26: Comment is required | L26: Comment is required
A27: CM-13.1 | B27: N/A | E27: Patch Management Environments | F27: Do you use Development, Test, QA, and Production environments during the patch management process? If so, describe the manner in which these environment are utilized? | H27: Comment is required | J27: Comment is required | L27: Comment is required
A28: CM-14.1 | B28: N/A | E28: Patch Classification | F28: Do you categorize patches based on severity? If yes, please provide the categories, their definitions, and the associated time frames for deploying patches to production environments. | H28: Comment is required | J28: Comment is required | L28: Comment is required
A29: CM-14.2 | B29: N/A | F29: Do you implement patches categorized as "critical" within 72 hours of patch release? | H29: Comment is required | J29: Comment is required | L29: Comment is required

Sheet 6. Contingency Planning
A1: Control Question # | B1: NIST SP800-53 R4: Control # | C1: HIPAA CFR Control Reference(s) | D1: HITRUST CSF | E1: Control Name | F1: Security Questions: | G1: =Scope!$B$4 & " Response:" -> Client -server application hosted at the data center Response: | H1: =Scope!$B$4 &" Comments:" -> Client -server application hosted at the data center Comments: | I1: =Scope!$D$4 & " Response:" -> Response: | J1: =Scope!$D$4 & " Comments:" -> Comments: | K1: =Scope!$F$4 & " Response:" -> Response: | L1: =Scope!$F$4 & " Comments:" -> Comments:
A2: Contingency Planning
A3: CP-1.1 | B3: CP-1 | C3: 164.308(a)(7)(i) | D3: 02.a 04.a 04.b 05.a 05.b 05.c | E3: Contingency Planning Policy and Procedures | F3: Are there formally documented policies and procedures for Contingency Plan? If yes, please attach. | H3: Comment is required | J3: Comment is required | L3: Comment is required
A4: CP-2.1 | B4: CP-2 | C4: 164.308(a)(7)(ii)(B) 164.308(a)(7)(ii)(C) 164.308(a)(7)(ii)(D) 164.308(a)(7)(ii)(E) 164.310(a)(2)(i) 164.312(a)(2)(ii) | D4: 05.b 05.c | E4: Contingency Plan | F4: Have you developed a contingency plan for this information system? If yes, please attach. | H4: Comment is required | J4: Comment is required | L4: Comment is required
A5: CP-2.2 | F5: Does the contingency plan: - Identify the essential missions and business functions - Provide recovery objectives, restoration priorities, and metrics - Address contingency roles, responsibilities, and assigned individuals with contact information - Address maintaining essential missions and business functions despite a disruption - Address full restoration without deterioration of originally implemented security safeguards - Distributed to key personnel - Coordinated with incident handling procedures - Reviewed and updated to address changes - Protected from unauthorized disclosure or modification | H5: Comment is required | J5: Comment is required | L5: Comment is required
A6: CP-3.1 | B6: CP-3 | C6: 164.308(a)(7)(ii)(D) | D6: 02.e | E6: Contingency Training | F6: Does your department train personnel in their contingency roles and responsibilities and provide refresher training when required? | H6: Comment is required | J6: Comment is required | L6: Comment is required
A7: CP-4.1 | B7: CP-4 | C7: 164.308(a)(7)(ii)(D) | E7: Contingency Plan Testing | F7: Do you test and/or exercise the contingency plan periodically to determine the plan’s effectiveness and review the contingency plan test results to initiate any needed corrective actions? | H7: Comment is required | J7: Comment is required | L7: Comment is required
A8: CP-6.1 | B8: CP-6 | C8: 164.308(a)(7)(ii)(B) 164.310(a)(2)(i) | E8: Alternate Storage Site | F8: Has your department established an alternate storage site including necessary agreements to permit the storage and recovery of information system backup information? | H8: Comment is required | J8: Comment is required | L8: Comment is required
A9: CP-6.2 | F9: Does the alternate storage site provide information security safeguards equivalent to that of the primary site? | H9: Comment is required | J9: Comment is required | L9: Comment is required
A10: CP-7.1 | B10: CP-7 | C10: 164.308(a)(7)(ii)(B) 164.310(a)(2)(i) | E10: Alternate Processing Site | F10: Has your department established an alternate processing site to permit the resumption of information system operations for essential missions and business functions when the primary processing capabilities are unavailable? | H10: Comment is required | J10: Comment is required | L10: Comment is required
A11: CP-7.2 | F11: Does the alternate processing site provide information security safeguards equivalent to that of the primary site? | H11: Comment is required | J11: Comment is required | L11: Comment is required
A12: CP-8.1 | B12: CP-8 | C12: 164.308(a)(7)(ii)(B) | E12: Telecommunications Service | F12: Are there alternate forms of telecommunication available should primary means (e.g. email, cellular phone) be unavailable? | H12: Comment is required | J12: Comment is required | L12: Comment is required
A13: CP-9.1 | B13: CP-9 | C13: 164.308(a)(7)(ii)(A) 164.308(a)(7)(ii)(B) 164.310(d)(2)(iv) 164.312(c)(1) | E13: Information System Backup | F13: Is user-level information, system-level information, and information system documentation backed up? | H13: Comment is required | J13: Comment is required | L13: Comment is required
A14: CP-9.2 | F14: Is the confidentiality, integrity, and availability of backup information protected at the storage location? | H14: Comment is required | J14: Comment is required | L14: Comment is required
A15: CP-10.1 | B15: CP-10 | C15: 164.308(a)(7)(ii)(B) 164.308(a)(7)(ii)(C) | E15: Information System Recovery and Reconstitution | F15: Is there recovery and reconstitution of the information system to a known state after a disruption, compromise, or failure? | H15: Comment is required | J15: Comment is required | L15: Comment is required

Sheet 7. Authentication&Authorization
A1: Control Question # | B1: NIST SP800-53 R4: Control # | C1: HIPAA CFR Control Reference(s) | D1: HITRUST CSF | E1: Control Name | F1: Security Questions: | G1: =Scope!$B$4 & " Response:" -> Client -server application hosted at the data center Response: | H1: =Scope!$B$4 &" Comments:" -> Client -server application hosted at the data center Comments: | I1: =Scope!$D$4 & " Response:" -> Response: | J1: =Scope!$D$4 & " Comments:" -> Comments: | K1: =Scope!$F$4 & " Response:" -> Response: | L1: =Scope!$F$4 & " Comments:" -> Comments:
A2: Identification and Authentication
A3: IA-1.1 | B3: IA-1 | D3: 01.b 02.a 04.a 04.b 05.a 05.b 05.c | E3: Identification and Authentication Policy and Procedures | F3: Does the application/system use managed LDAP services for identification and authentication? If no, detail in the comment column what is used. | H3: Comment is required | J3: Comment is required | L3: Comment is required
A4: IA-1.2 | F4: Are there formally documented policies and procedures for Identification and Authentication? If yes, please attach. | H4: Comment is required | J4: Comment is required | L4: Comment is required
A5: IA-2.1 | B5: IA-2 | C5: 164.308(a)(5)(ii)(D) 164.312(a)(2)(i) 164.312(d) | D5: 01.q 01.p | E5: Identification and Authentication (Organizational Users) | F5: Does the information system use multifactor authentication for privileged or non-privileged access? (Uses at least two of: what you have, what you know, what you are. E.g., tokens, passwords, biometrics.) | H5: Comment is required | J5: Comment is required | L5: Comment is required
A6: IA-3.1 | B6: IA-3 | C6: 164.312(a)(2)(i) 164.312(d) | D6: 01.k 01.j | E6: Device Identification and Authentication | F6: Does the information system uniquely identify and authenticate devices before establishing a connection? (E.g., MAC, TCP/IP, IEEE 802.1x) | H6: Comment is required | J6: Comment is required | L6: Comment is required
A7: IA-4.1 | B7: IA-4 | C7: 164.308(a)(5)(ii)(D) 164.312(a)(2)(i) 164.312(d) | D7: 01.b 01.q | E7: Identifier Management | F7: Do you manage the information system identifiers for users and devices by requiring authorization by an authorized signer prior to assigning an identifier? | H7: Comment is required | J7: Comment is required | L7: Comment is required
A8: IA-4.2 | F8: Does the application/system prevent reuse of user or device identifiers? | H8: Comment is required | J8: Comment is required | L8: Comment is required
A9: IA-4.3 | F9: Does the application/system disable the user or device account after a pre-defined period of inactivity? | H9: Comment is required | J9: Comment is required | L9: Comment is required
A10: IA-5.1 | B10: IA-5 | C10: 164.308(a)(5)(ii)(D) | D10: 01.b 01.d 01.f 01.q 01.r 01.p | E10: Authenticator Management | F10: Does the application/system comply with the password complexity as outlined in implemented policies? | H10: Comment is required | J10: Comment is required | L10: Comment is required
A11: IA-5.2 | F11: Does information system force the End User to comply with the following password requirements regarding complexity, length and change? - Passwords at least 8 characters in length. - Passwords contain the following: - Mixed case alpha characters - at least one numeric digit - at least one non-alphanumeric character - Current password may not be reused - Do current passwords expire every 90 days? - Are passwords stored in an encrypted format? | H11: Comment is required | J11: Comment is required | L11: Comment is required
A12: IA-5.3 | F12: Are the passwords encrypted within the information system when stored or transmitted? | H12: Comment is required | J12: Comment is required | L12: Comment is required
A13: IA-5.4 | F13: Are factory default passwords changed once implemented into production? (Admin/root passwords.) | H13: Comment is required | J13: Comment is required | L13: Comment is required
A14: IA-5.5 | F14: Is the identity of the individual or device verified as part of the initial password distribution process? | H14: Comment is required | J14: Comment is required | L14: Comment is required
