Workbook
Name CORL: [1]Sheet1!$A$1:$A$2
Name Risk: [2]Sheet2!$A$3:$A$7

Sheet Cover Page
A1: Vendor Security Assessment Toolkit by CORL Technologies This document is PROPRIETARY and CONFIDENTIAL Information. It may not be used, disclosed or reproduced, in whole or in part, without the express written permission of CORL Technologies, LLC
A12: Version 3.00 (On Prem+PSQ)

Sheet Instructions
A1: "IRQ" - Inherent Risk Questionnaire - Business Owner to Complete
B2: St. Luke's (SLUHN) Business Owner completes the Inherent Risk Questionnaire ("IRQ") to facilitate better understanding of the scope of business between the Vendor and the organization for the vendor security risk management project.
A4: "VPQ" - Vendor Profile Questionnaire - Vendor to Complete
B5: Please complete this questionnaire as it relates to the business relationship between your organization and St. Luke's (SLUHN). In the "Disclosure Permitted?" column, please indicate if CORL Technologies may disclose the responses provided herein to other CORL Technologies clients who also utilize your organization as a vendor. Allowing such disclosure may expedite future assessments.
A7: Scope - Vendor to Complete
B8: Please identify all environments that will handle, process, transmit, or store St. Luke's (SLUHN) data. Please provided a response to all questions for each identified environment.
A10: "VSQ" - Vendor Security Questionnaire - Excel worksheets 1-17 herein - Vendor to Complete
B11: St. Luke's (SLUHN) is obligated by regulations and internal risk management policies to gain reasonable assurance that its vendors are protecting St. Luke's (SLUHN) data. To meet this obligation, St. Luke's (SLUHN) is requiring vendors to complete this Vendor Security Questionnaire (VSQ) within 15 business days of receiving it. All "N/A" and "Partial" responses MUST be accompanied by an explanation in the comments column. Any questions should be directed to CORL Client Engagement clientengagement@corltech.com.
A13: "Required Evidence" - Evidence and Assurances specific to CLIENT - Vendor to Provide
B14: Upon completion of this questionnaire, CORL and St. Luke's (SLUHN) will obtain evidence and assurances relating to the key controls as defined by the St. Luke's (SLUHN) team. Please indicate within the "Required Evidence" sheet whether you have provided the documentation requested by CORL and St. Luke's (SLUHN). Instructions surrounding Evidence and Assurances: The Vendor Profile Questions (VPQ) & Scope sections include questions that relate to information about your organization and the products and services provided to St. Luke's (SLUHN). The Vendor Security Questionnaire (worksheets 1-17) section relates to questions about overall security controls at the vendor level and product level. All responses require references to documents that provide evidence of the control. If your organization has received a current security certification, please provide documentation in lieu of evidence. Relevant security certifications include, SOC 2 Type 2 (must include Security TSP), HITRUST and/or ISO 27001. Please provide certification and/or evidence documents along with this completed questionnaire to CORL Technologies within 15 business days.

Sheet Data Validation Key
A1: Response Questions | B1: Data Classifications | C1: Types of Data: | D1: Type of Access | E1: Method of Access | F1: Volume of Records | G1: Financial Value | H1: Breah Business Impact | I1: Geographic Scope | J1: Size of Organization (# of Employees) | K1: How data is stored, hosted | L1: App / Product? | M1: Vendor Age / Business Relationship Length
A2: Yes | B2: Company Data | C2: PHI | D2: Intentionally Shared | E2: Electronic | F2: Most of our patients | G2: High | H2: High | I2: International | J2: > 100,000 | K2: In the Cloud | L2: Yes | M2: < 5 Years
A3: No | B3: Restricted Data | C3: PII | D3: Incidental Access | E3: Physical | F3: Most our employees | G3: Medium High | H3: Medium High | I3: National | J3: > 10,001 | K3: On our Network | L3: No | M3: 5 - 10 Years
A4: Partial | B4: Sensitive Data | C4: PCI | D4: No Access | E4: Electronic and Physical | F4: Data related to a specific business unit or division | G4: Medium | H4: Medium | I4: Single-State | J4: > 1001 | K4: At the Vendor's Location | M4: 11 - 20 Years
A5: N/A | B5: Internal Data | C5: Intellectual property | F5: Data related to a specific service line or facility | G5: Medium Low | H5: Medium Low | J5: > 501 | M5: > 20 Years
B6: Public Data | C6: PHI, PII | F6: Very specific and limited focus | G6: Low | H6: Low | J6: > 51
C7: PHI, PCI | G7: None | H7: None | J7: > 1
C8: PHI, Intellectual property
C9: PCI, PII
C10: PCI, Intellectual property
C11: PII, Intellectual property
C12: All Data types
A20: Key | C20: Overrides
A21: Tier 1 | C21: No Override
A22: Tier 2 | C22: Adequate
A23: Tier 3 | C23: Inadequate
A24: Conditional to other Questions | C24: N/A
A25: Response acceptance dependent on the business relationship btwn client and vendor
A26: Questions dependent on comments and QA by CE

Sheet IRQ
A1: Inherent Risk Questionnaire ("IRQ")
A2: Official Name of Vendor: | D2: Vendor POC Name:
A3: Vendor-specific business unit / division, if applicable: | D3: Vendor POC Title:
A4: Vendor Website Domain(s): | D4: Vendor POC Email:
A5: Date IRQ Completed: | D5: Vendor POC Phone #:
A6: Control Question # | B6: Control Name | C6: Control Questions | D6: Response | E6: Notes
A7: Inherent Risk Questions:
A8: 1 | B8: Products and Applications | C8: Does your organization use a vendor specific service/product(s)? (if "Yes" please list the names of the services/products in "Notes")
A9: 2 | B9: Accessible Data | C9: Type of data vendor will have access to:
A10: 3 | B10: Data Storage | C10: Where will the data of your organization be stored, hosted?
A11: 4 | B11: Report Support | C11: Does vendor provide remote support?
A12: 5 | B12: Records | C12: Volume of your organization's records accessible by vendor:
A13: 6 | B13: Vendor Business Operations | C13: Geographic scope of the vendor (if vendor has international operations, please list country name(s) in "Notes"):
A14: 7 | B14: Vendor Age | C14: How long has the vendor been in business in general?
A15: 8 | B15: Business Relationship Length | C15: How long has the vendor been in business with your organization?
A16: 9 | B16: Annual Revenue | C16: What is the vendor's annual revenue?
A17: 10 | B17: Vendor Size | C17: Size of the vendor (# of employees):
A18: 11 | B18: Business Associate Agreement (BAA) | C18: Is there an executed Business Associate Agreement between your organization and the vendor?
A19: 12 | B19: Information Security Agreement (ISA) | C19: Is there an executed Information Security Agreement between your organization and the vendor?
A20: 13 | B20: Security Assessment Activities | C20: Has your organization completed security assessment activities on the vendor in the past? (if "Yes" please describe the assessment scope and approximate timeframe in "Notes"):

Sheet IVPQ
A1: Initial Vendor Profile Questionnaire - for CLIENT NAME
A2: Vendor name: | D2: Name:
A3: Service(s) / Product(s) provided: | D3: Title:
A4: Vendor Website Domain(s): | D4: Email:
A5: Date Completed: | D5: Phone:
A6: Control Question # | B6: Control Name | C6: Control Questions | D6: Response: | E6: Comments/ Notes: | F6: Evidence Provided | G6: NIST SP800-53 R4: Control # | H6: HIPAA CFR Control Reference(s):
A7: Vendor Discovery Questions:
A8: 1.1 | B8: Accessible Data | C8: Will you have access to the following types of data: | G8: N/A | H8: N/A
A9: 1.1-a | B9: Accessible Data | C9: PHI (Protected Health Information) | G9: N/A | H9: N/A
A10: 1.1-b | B10: Accessible Data | C10: Intellectual Property | G10: N/A | H10: N/A
A11: 1.1-c | B11: Accessible Data | C11: Financial Property | G11: N/A | H11: N/A
A12: 1.1-d | B12: Accessible Data | C12: PII (Personally Identifiable Information) | G12: N/A | H12: N/A
A13: 1.1-e | B13: Accessible Data | C13: PCI (Payment Card Industry) | G13: N/A | H13: N/A
A14: 1.1-f | B14: Accessible Data | C14: Employee Information | G14: N/A | H14: N/A
A15: 1.2 | B15: Security Leadership | C15: Do you have a designated responsible leader for information security? If so, please explain their title and role in the comments section. | G15: N/A | H15: N/A
A16: 1.3 | B16: Security Assurances | C16: Has your company attained any of the following security certifications or external, independent validations of the following:? | G16: N/A | H16: N/A
A17: 1.3-a | B17: Security Assurances | C17: SOC (indicate SOC 1, 2 or 3 and type 1 or 2) | F17: Example evidence: certification document | G17: N/A | H17: N/A
A18: 1.3-b | B18: Security Assurances | C18: HITRUST | F18: Example evidence: certification document | G18: N/A | H18: N/A
A19: 1.3-c | B19: Security Assurances | C19: PCI Compliance | F19: Example evidence: certification document | G19: N/A | H19: N/A
A20: 1.3-d | B20: Security Assurances | C20: ISO 27001 | F20: Example evidence: certification document | G20: N/A | H20: N/A
A21: 1.3-e | B21: Security Assurances | C21: FedRAMP | F21: Example evidence: certification document | G21: N/A | H21: N/A
A22: 1.3-f | B22: Security Assurances | C22: HIPAA (please provide type of assessment performed and certifying organization in the comments section) | F22: Example evidence: certification document | G22: N/A | H22: N/A
A23: 1.3-g | B23: Security Assurances | C23: NIST (please provide type of assessment performed and certifying organization in the comments section) | F23: Example evidence: certification document | G23: N/A | H23: N/A
A24: 1.3-h | B24: Security Assurances | C24: Other? (please specify in the comments section) | F24: Example evidence: certification document | G24: N/A | H24: N/A
A25: 1.4 | B25: Cyber Liability Insurance | C25: Do you maintain cyber liability insurance in addition to general liability insurance? If Yes, please explain how much in the comments section. | F25: Example evidence: insurance policy | G25: N/A | H25: N/A
A26: 1.5 | B26: Contractors/Subcontractors | C26: Do you use any employees, contractors or subcontractors outside of the United States? | E26: Please list locations and approximate # of employees at each location | G26: N/A | H26: N/A
A27: 1.6 | B27: Contractors/Subcontractors | C27: Do any of your subcontractors (foreign or domestic) have access to sensitive and/or confidential data? If yes, please name the companies and services they provide to you in the comments section. | E27: Please provide a list of sub-contractors | G27: N/A | H27: N/A
A28: 1.7 | B28: Employee Screenings | C28: Do you conduct background checks for all employees, contractors and subcontractors? If not, for which areas/positions do you require a background check. Please explain in the comments section. | G28: PS-3 | H28: 164.308(a)(3)(ii)(B)
A29: 1.8 | B29: Data Storage | C29: Is this a remote hosted or cloud system? If yes, please answer the following questions. | G29: N/A | H29: N/A
A30: 1.8-a | B30: Data Storage | C30: Do you have any data centers outside of the United States? | G30: N/A | H30: N/A
A31: 1.8-b | B31: Data Storage | C31: Can data be restricted to be stored only within the United States? | G31: N/A | H31: N/A
A32: 1.9 | B32: Data Storage | C32: Will data be stored at an encrypted data center? | E32: Please list names of recognized data centers | G32: SC-13 | H32: 164.312(a)(2)(iv) 164.312(e)(2)(ii)
A33: 1.1 | B33: Data Center Security Assurances | C33: What certifications does your data center have or external, independent validations of the following:? | G33: N/A | H33: N/A
A34: 1.10-a | B34: Data Center Security Assurances | C34: SOC (indicate SOC 1, 2, or 3 and type 1 or 2) | G34: N/A | H34: N/A
A35: 1.10-b | B35: Data Center Security Assurances | C35: PCI Compliance | G35: N/A | H35: N/A
A36: 1.10-c | B36: Data Center Security Assurances | C36: HITRUST | G36: N/A | H36: N/A
A37: 1.10-d | B37: Data Center Security Assurances | C37: ISO 27001 | G37: N/A | H37: N/A
A38: 1.10-e | B38: Data Center Security Assurances | C38: FedRAMP | G38: N/A | H38: N/A
A39: 1.10-f | B39: Data Center Security Assurances | C39: HIPAA (please provide type of assessment performed and certifying organization in the comments section) | G39: N/A | H39: N/A
A40: 1.10-g | B40: Data Center Security Assurances | C40: NIST (please provide type of assessment performed and certifying organization in the comments section) | G40: N/A | H40: N/A
...

Sheet Vendor Profile Questionnaire
A1: Instructions: Please complete this questionnaire as it relates to the business relationship between your organization and St. Luke's (SLUHN). In the "Disclosure Permitted?" column, please indicate if CORL Technologies may disclose the responses provided herein to other CORL Technologies clients who also utilize PeriGen. Allowing such disclosure may expedite future assessments.
A2: Initial Vendor Profile Questionnaire - on behalf of St. Luke's (SLUHN)
A3: Vendor name: | B3: PeriGen | D3: Name: | E3: Bruno Bendavid
A4: Service(s) / Product(s) provided: | B4: PeriCALM Tracings | D4: Title: | E4: SVP Product Management
A5: Vendor Website Domain(s): | B5: www.perigen.com | D5: Email: | E5: bruno.bendavid@perigen.com
A6: Date Completed: | B6: 43817 | D6: Phone: | E6: 514-978-0611
A7: Vendor Discovery Questions:
A8: Questions | B8: Response | C8: Disclosure Permitted? | D8: Comments
A10: Does PeriGen have a designated leader responsible for information security? | B10: Yes | C10: Yes
A11: Name of Information Security leader? | B11: Bruno Bendavid | C11: Yes
A12: Title | B12: SVP Product Management | C12: Yes
A13: Role | B13: Product Management | C13: Yes
A14: Does PeriGen employ an information security team? | B14: No | C14: Yes
A15: Number of full-time information security personnel? | B15: No. Role part of product development | C15: Yes
A16: Does PeriGen employ an incident response officer? | C16: Yes
A17: Name of incident response officer? | B17: Bruno Bendavid | C17: Yes
A18: Title | B18: SVP Product Management | C18: Yes
A19: Email | B19: bruno.bendavid@perigen.coom | C19: Yes
A20: Phone | B20: 514-978-0611 | C20: Yes
A21: Does PeriGen outsource information security functions to a third party? If yes, please provide the name and scope of services provided in the comments section. | B21: Yes | C21: Yes | D21: IT infrastructure management
A22: Does VENDOR maintain cyber liability insurance in addition to general liability insurance? If Yes, please explain how much in the comments section. | B22: Yes | C22: Yes | D22: Liability insurance is set to $5 million (both general and cyber)
A23: Does PeriGen have any employees or physical office locations outside of the United States? | B23: Yes | C23: Yes
A24: Is any St. Luke's (SLUHN) data accessed, transmitted, or stored outside of the United States? | B24: No | C24: Yes | D24: PeriGen has technical resources residing outside the United States; Montreal, Canada and Tel Aviv, Israel. The primary support center is in Cary, NC (PeriGen HQ). These resources may from time to time analyze and troubleshoot the solution which may require access to ePHI data via approved connections. ePHI is never copied or stored outside the US.
A25: What year was PeriGen founded? | B25: 36164 | C25: Yes
A26: Approximately how many people does PeriGen employ? | B26: <100 | C26: Yes
A27: Has PeriGen ever experienced a data breach? If so, please explain in the comments section. | B27: No | C27: Yes
A28: Is there a current BAA in place? | B28: Yes | C28: Yes
A29: Does PeriGen utilize any subcontractors with access to St. Luke's (SLUHN) data? If yes, please provide the name of the subcontractor(s) in the comments section. | B29: No | C29: Yes
A30: Please describe how your organization obtains data from St. Luke's (SLUHN). Include file type(s) and the medium(s) utilized to transmit the data (e.g., SFTP, Encrypted email). | B30: No data collected outside the servers hosted by the SLUHN | C30: N/A

Sheet Scope
A1: Vendor Scope Questions
A2: Instructions: Please identify all environments that will handle, process, transmit, or store St. Luke's (SLUHN) data. Please provided a response to all questions for each identified environment. | B2: Environment 1 | D2: Environment 2 | F2: Environment 3
B3: Response | C3: Comments | D3: Response | E3: Comments | F3: Response | G3: Comments
A4: Please identity the environment (e.g., back office, systems involved in support /maintenance services, applications/softwares) in the "response" column and provide a brief description in the comments section: | B4: PeriCALM Tracings Fetal monitoring application | C4: Dedicated and fully hospital hosted fetal monitoring, documentation, alerts, archiving and decision support
A5: Is the identified environment either of the following:
A6: Service | B6: No
A7: Product | B7: Yes
A8: What is the volume of St. Luke's (SLUHN) records that the identified environment will transmit, process, or store? | B8: Data is only stored on hospital hosted servers. An estimate of volume of data stored on hospital servers including long term archive files is ~10GB (steady state) + 5GB per year as continuous archive files per pregnancy
A9: Please indicate if the identified environment will: | B9: If "yes", please provide details in the comments section.
A10: have access into the St. Luke's (SLUHN) network for remote Support | B10: Yes | C10: All access to the PeriGen servers is done via SecureLink approved infrastructure for 24/7/365 support
A11: have access into the St. Luke's (SLUHN) network to provide onsite support | B11: Yes | C11: PeriGen support staff have user access credentials to PeriGen server(s) only. This can be used for onsite support/operations if required by the customer
A12: Have access to infrastructure that stores or transmits St. Luke's (SLUHN) data: | B12: No | C12: No if the question pertains to physical access
A13: Have access to a database or application that stores or transmits St. Luke's (SLUHN) data: | B13: Yes | C13: Only to the PeriGen application DB and ADT/EMR HL7 data interfaces
A14: Receive transmitted data from St. Luke's (SLUHN) | B14: Yes | C14: Only ADT inbound
A15: Not access St. Luke's (SLUHN)'s information | B15: No
A16: What types of St. Luke's (SLUHN) information will the identified environment have access to: | B16: If "yes", please provide details in the comments section.
A17: PHI (Protected Health Information) | B17: Yes | C17: Only data supplied via the ADT inbound interface
A18: PII (Personally Identifiable Information) | B18: No
A19: PCI (Payment Card Industry) | B19: No
A20: Employee Information | B20: No
A21: St. Luke's (SLUHN) Internal/Proprietary Information | B21: No
A22: Please indicate if the identified environment will utilize the following device(s) to access and/or transmit St. Luke's (SLUHN) data: | B22: If "yes", please provide details in the comments section.
A23: St. Luke's (SLUHN) Workstation | B23: Yes | C23: The PeriCALM application is installed on workstation at the bedside and nursing stations. Data is communicated between workstations and server. Not data is cached or saved on the workstation.
A24: PeriGen Workstation | B24: No | C24: unclear. PeriGen does not provide any workstation hardware. Only customer supplied stations are in scope.
A25: St. Luke's (SLUHN) Mobile Device | B25: No
A26: PeriGen Mobile Device | B26: No
A27: Medical Device | B27: Yes | C27: The system interfaces to fetal monitor to collect the fetal tracing, trasmit it to the main server which publishes it to all open client application instances on the network
A28: Other Method? Please explain in the comments section | B28: No
A29: Please indicate all locations where the data will be stored for the identified environment: | B29: If "yes", please provide details in the comments section.
A30: St. Luke's (SLUHN) Data Center | B30: Yes | C30: All data is stored on the main DB/App server and possibly on the long term data archival system used by the customer at the data center. No data is stored on client workstations
A31: PeriGen Data Center | B31: No
A32: 3rd Party Data Center | B32: No
A33: St. Luke's (SLUHN) Workstation | B33: No
A34: PeriGen Workstation | B34: No
A35: St. Luke's (SLUHN) Mobile Device | B35: No
A36: PeriGen Mobiel Device | B36: No
A37: Medical Device | B37: No
A38: Other? Please explain in the comments section | B38: No
A39: Does the identified environment maintain any of the following security assurances:
A40: SSAE 16 / SOC 1 Type 1 | B40: No
...

Sheet Network_Architecture_Diagrams
A1: Objective: | B1: Summary/Explanation (if diagrams are not available): | C1: Evidence/Assurance
A2: Please provide any and all network architecture diagram(s) within this worksheet: | C2: Please attach network architecture diagram(s) or provide screenshots below:

Sheet Connectivity Mapping
A1: Objective: | B1: Summary/Explanation: | C1: Evidence/Assurance
A2: Please provide a summary of how you will be connecting to the St.Luke's (SLUHN) Network (if applicable) | B2: Connectivity is perfromed by SecureLink which is already approved and operational. | C2: If necessary please provide supporting documentation

Sheet Required Evidence
A1: Key Control Question Reference # | B1: Key Control: | C1: Control Area # | D1: Evidence Requested: | E1: Provided to CORL? | F1: Vendor Comments
A2: CM-2.1 | B2: Baseline Configuration | C2: CM-2 | D2: Provide the most recent Baseline Configuration document for the information system (e.g., hardening procedures for Window OS, baseline security settings for sever AND application builds.) | E2: Yes | F2: Guidelines and environments provided by the customer based on PeriGen provided specifications. See the attached System Specification.
A3: CM-3.1 - CM-3.6 | B3: Configuration Change Control | C3: CM-3 | D3: Configuration Change Control procedures | E3: Yes | F3: See attached SDLC master policy/procedure | G3: There are no specific procedures for "configuration change controls". Product development life cycle and change control in general are embedded within QMS SOPs and Procedures propriatary to PeriGen
A4: CM-5.1 | B4: Access Restrictions for Change | C4: CM-5 | D4: Configuration Change Control procedures | E4: Yes | F4: See attached SDLC master policy/procedure
A5: CM-6.1 - CM-6.3 | B5: Configuration Settings | C5: CM-6 | D5: Provide report monitoring records related to most recent changes to the Configuration settings information system | E5: No | F5: Tracking is done within our development systems (VSTS). It isnt possible/practical to provide such a report.
A6: CM-7.1 | B6: Least Functionality | C6: CM-7 | D6: (See CM 2.1 - Most recent Baseline Configuration) | E6: Yes | F6: See the attached system specifications
A7: CM-8.1 - CM-8.2 | B7: Information System Component Inventory | C7: CM-8 | D7: Provide documentation that demonstrates information system Component Inventory is maintained and kept up to date. | E7: Yes | F7: See 2 examples of system specifictaion for the version 3.18.04 and 3.18.05
A8: CM-9.1 - CM-9.4 | B8: Configuration Management Plan | C8: CM-9 | D8: Provide Software Development/Deployment Life Cycle (SDLC) documentation which includes secure coding procedures, where applicable. | E8: Yes | F8: See attached SDLC master policy/procedure | G8: PeriGen SDLC procedures are extensive and propriatary in compliance with FDA and MDSAP guidelines for class II Medical Devices. Secure coding practices are followed but not formally captured in a procedure. This is planned for 2020
A9: CM-10.1 | B9: Software Usage Restrictions | C9: CM-10 | D9: Provide Acceptable Use policy. Provide samples of software licensing documentation. | E9: Yes | F9: This is the clause in standard PeriGen contracts regarding Acceptable Use: "PeriGen grants to Customer a non-exclusive, non-transferable license (“License”) to use the Software solely at the applicable Facility(ies) listed in the Order Form, solely in object code form and solely for Customer’s internal use. Customer shall ensure that all Staff responsible for using the Software are properly trained. Customer will be allowed to make and retain a copy of the Software for back up purposes only, in accordance with Customer’s standard policies. Each copy of the Software is subject to all of the terms and conditions of this Agreement and must contain the same titles, trademarks, and copyright notices as the original. Customer and its Staff shall not (i) copy, modify or change the Software in any manner except as may be expressly permitted herein; (ii) make any modifications to the operation or installation of the Software without the written consent of PeriGen; (iii) sell, rent, lease, lend, reproduce, license, sublicense, distribute or otherwise transfer the Software or decompile, disassemble or reverse engineer the Software or any PeriGen Intellectual Property, in whole or in part; (iv) write or develop any derivative technology including, without limitation, any other software program based upon the Software or any PeriGen Intellectual Property; (v) use the Software to provide any facility management, service bureau or similar services to third parties; (vi) modify or attempt to modify the Software’s configuration without the prior written consent of PeriGen, to be given in PeriGen’s sole discretion, and any intervention or actions required to be taken by PeriGen with respect to such unauthorized modifications shall be at Customer’s expense; or (vii) remove any copyright, patent, trademark or other proprietary or restrictive notice or legend contained or included in any PeriGen Intellectual Property or any copies thereof. Customer shall only use PeriGen-certified FDA compliant fetal monitor cables, if applicable. "
A10: CM-11.1 | B10: User-Installed Software | C10: CM-11 | D10: Provide documentation that demonstrates unapproved software is prohibited from use on the information system. Provide evidence of any mechanisms that prevent unapproved software from being used. | E10: N/A | F10: Controlled by customer IT policies. Only PeriGen employees can install the customer approved software version. Signed document are maintained for each installation. See an attached example. | G10: Maybe clause in contract and allowed change control (like MS patches)
A11: IA-5.2 - IA-5.8 | B11: Authenticator Management | C11: IA-5 | D11: Provide Password policy and procedures, including length and complexity requirements as well as process initial password distribution and changing of factory defaults. | E11: Yes | F11: See the attached PeriGen Privacy & Security Policy and Procedures document
A12: MA-4.1 - MA-4.5 | B12: Non-local Maintenance | C12: MA-4 | D12: Provide policy and procedures surrounding secure remote support of the information system. | E12: Yes | F12: See the attached PeriGen Privacy & Security Policy and Procedures document
A13: RA-5.1 | B13: Vulnerability Scanning | C13: RA-5 | D13: Provide Vulnerability Management procedures and copy of the most recent vulnerability scans of all systems which process, transmit, or store client data | E13: Yes | F13: See the attached PeriGen Privacy & Security Policy and Procedures document
A14: SC-15.1 - SC-15.3 | B14: Collaborative Computing Devices | C14: SC-15 | D14: Provide hardware configuration specifications that demonstrate remote activation of collaborative computing devices are prohibited | E14: N/A | F14: There are no collaborative devices being used at PeriGen as specified in 15.1
A15: SC-8.1, SC-8.2, SC-28.1 | B15: Encryption | C15: SC-8, SC-28 | D15: Provide Encryption policy and procedures for information in transit and information at rest. | E15: Yes | F15: See the attached PeriGen Privacy & Security Policy and Procedures document
A16: SC-18.1 | B16: Mobile Code | C16: SC-18 | D16: Provide Communications Protection policy and Mobile Code Implementation policy | E16: N/A | F16: No mobile code applicable for PeriCALM Tracings
A17: SI-2.1 - SI-2.3 | B17: Flaw Remediation | C17: SI-2 | D17: Provide documentation that all identified vulnerabilities are remediated in a timely manner. | E17: Partial | F17: Embedded in SDLC process. Each flaw is assessed individulay and scheduled for release according to severity/priority. There is no direct document to demonstrate that other than what is covered in SDLC policy.
A18: SI-3.1 - SI-3.4 | B18: Malicious Code Protection | C18: SI-3 | D18: Provide evidence that malware protection solutions are implemented on servers, workstations, and all other end points that process, transmit, or store client data. | E18: Yes | F18: See attached sample report from our automated system
A19: SI-4.1 | B19: Information Systems Monitoring | C19: SI-4 | D19: Provide evidence that intrusion detection and intrusion prevention solutions are implemented and monitored. | E19: Yes | F19: See attached
A20: SI-7.1 | B20: Software, Firmware, and Information Integrity | C20: SI-7 | D20: Provide evidence that information integrity tools are used. (e.g., tripwire) | E20: No
A21: SI-8.1 | B21: Spam Protection | C21: SI-8 | D21: Provide documentation that spam protection mechanisms are employed at information system entry/exit points and are updated when new releases of such mechanisms are available. | E21: Yes | F21: Corporate policy as of Office 365 E5 service. See the attached screenshot for corporate SPAM settings
A22: SA-4.1 | B22: Acquisition Process | C22: SA-4 | D22: Please provide Vendor Management Policy/ Procedures | E22: No
A23: SA-12 | B23: Supply Chain Protection | C23: SA-12 | D23: Please provide Vendor Management Policy/ Procedures | E23: No
A24: IR-8 | B24: Incident Response Plan | C24: IR-8 | D24: Please provide comprehensive Incident Response Plan | E24: Yes | F24: See the attached PeriGen Privacy & Security Policy and Procedures document

Sheet Product Security Questionnaire
A1: Initial Product Profile
A2: Vendor: PeriGen | B2: Completed by: | C2: Name: Bruno Bendavid | D2: Title: SVP Product Management
A3: Product name: PeriCALM Tracings | C3: Phone: 514-978-0611 | D3: Email: bruno.bendavid@perigen.com
A4: Date Completed: Dec 18, 2019
A5: Questions | B5: Yes/No | C5: Comments
A6: (1) Will PeriCALM process transmit or store the following types of St. Luke's (SLUHN)'s data:
A7: • Protected Health Information (PHI) | B7: Yes
A8: • Personally Identifiable Information (PII) | B8: Yes
A9: • Payment Card Industry (PCI) | B9: No
A10: • Employee Information | B10: No
A11: • Other? Please explain in the comments section
A12: (2) Please select the implementation method for the product that St. Luke's (SLUHN) is utilizing/will utilize:
A13: • Software-as-a-Service | B13: No
A14: • Locally installed | B14: Yes
A15: • Hybrid (please explain in the comments section)
A16: • Other (please explain in the comments section)
A17: (3) Please describe how the PeriCALM is integrated with the client's infrastructure. | B17: Yes | C17: PeriCALM Tracing server is installed locally at the customers data center. Interfaces include ADT, inbound/outbound HL7 & Single-Sign-On functions with the EMR and diect connectivity to fetal monitors via RS232.
A18: (4) Do you maintain any documentation which include the details of PeriCALM's security configuration specifications? If so, please attach in the comments section. | B18: No | C18: We only maintain configuration parameterrs that were chosen by each customer. Typicaly, all authentication is done based on AD users and groups where group management is done within PeriCALM for authorization. This is controlled by the customer.
A19: (5) Please provide a detailed overview of how PeriCALM will access, transmit, or store St. Luke's (SLUHN) data? | B19: Yes | C19: Assuming that "PeriGen data" means data generated by the customer on the PeriGen server/system. All data obtained at the site (ADT, HL7 interface, fetal monitoring and manual documentation by clinical staff) is stored on the server hosted by the customer. There are no interfaces or transmission of data outside the customer secured network.
A20: (6) Is your organization is providing remote support or maintenance services? If yes, please outline the scope of the data to which your organization will have access. | B20: Yes | C20: PeriGen support has access to the PeriGen main server and the data stored on it for remote support. The data includes limited patient indentifiers (from ADT) and clinical data collected for these patients (tracings and vitals collected from fetal monitors and manually entered data charted by clinicians).
A21: (7) If your organization is providing remote support/maintenance services, please describe the method used to establish remote access to the client's infrastructure/ product. | B21: Yes | C21: All remote access is done via SecureLink which was approved by SLUHN.
A22: (8) Is there a point of contact for which security related questions/concerns about PeriCALM can be resolved? If so, please provide contact information, including: position title, email, and phone number in the comments section. | B22: Yes | C22: Bruno Bendavid. SVP Product Management. Bruno.bendavid@perigen.com, 514-978-0611
A23: (9) In what year was PeriCALM first offered as a product? | C23: Commercialization started in 2003
A25: Comprehensive Product Security Questionnaire
A26: Security Questions: | B26: Response: | C26: Comments/Evidence:
A27: Certifications
A28: (10) Has PeriCALM attained any of the following security certifications:
A29: • SSAE16 (indicate Type 1 or 2) | B29: No
A30: • SOC 2 (indicate Type 1 or 2) | B30: No
A31: • SOC 3 (indicate Trust Service Principles maintained) | B31: No
A32: • HITRUST | B32: No
A33: • ISO 27001 | B33: No
A34: • FedRamp | B34: No
A35: • CSA STAR (indicate Certification or Attestation) | B35: No
A36: • PCI DSS | B36: No
A37: • Other? Please explain the in comments section. | B37: No
A38: (11) Has PeriCALM attained any of the following miscellaneous certifications:
A39: • HackerSafe | B39: No
A40: • SquareTrade | B40: No
A41: • Qualys | B41: No
...

Sheet 1. Access Controls
A1: Control Question # | B1: NIST SP800-53 R4: Control # | C1: HIPAA CFR Control Reference(s) | D1: Control Name | E1: Security Questions: | F1: =Scope!$B$4 & " Response:" -> PeriCALM Tracings Fetal monitoring application Response: | G1: =Scope!$B$4 &" Comments:" -> PeriCALM Tracings Fetal monitoring application Comments: | H1: =Scope!$D$4 & " Response:" -> Response: | I1: =Scope!$D$4 & " Comments:" -> Comments: | J1: =Scope!$F$4 & " Response:" -> Response: | K1: =Scope!$F$4 & " Comments:" -> Comments:
A2: Access Control
A3: AC-1.1 | B3: AC-1 | C3: 164.308(a)(3)(i) 164.308(a)(3)(ii)(A) 164.308(a)(4)(i) 164.308(a)(4)(ii)(B) 164.308(a)(4)(ii)(C) 164.312(a)(1) | D3: Access Control Policy and Procedures | E3: Are there formally documented policies and procedures for access control? If yes, please attach. | F3: Yes | G3: Comment is required | I3: Comment is required | K3: Comment is required
A4: AC-3.1 | B4: AC-3 | C4: 164.308(a)(3)(ii)(A) 164.308(a)(4)(ii)(B) 164.308(a)(4)(ii)(C) 164.310(a)(2)(iii) 164.310(b) 164.312(a)(1) 164.312(a)(2)(i) 164.312(a)(2)(ii) 164.312(a)(2)(iv) | D4: Access Enforcement | E4: Does the information system verify the rights of a user to access the information system? (Access Control Lists, Group/Role membership?) If yes, detail how the access is enforced in the comment. | F4: Yes | G4: Access controlled is enforced by groups membership. An AD user must belong to an AD group that is identical by name to an internal PeriCALM group. An authenticated user that belong to such a group inherits its access rights. These rights are controlled by the customer application administrators where AD group membership is controlled by customer IT administrators. | I4: Comment is required | K4: Comment is required
A5: AC-3.2 | B5: N/A | E5: Does the information system support role-based account management and access controls (RBAC)? | F5: Yes | G5: Comment is required | I5: Comment is required | K5: Comment is required
A6: AC-3.3 | B6: N/A | E6: If RBAC is supported, can a customer administrator create/customize unique roles and permissions. | F6: Yes | G6: Comment is required | I6: Comment is required | K6: Comment is required
A7: AC-7.1 | B7: AC-7 | D7: Unsuccessful Logon Attempts | E7: Is an account automatically locked out after a set amount of attempts? If yes, please provide the number of failed attempts that trigger an account to be locked out, in the comments section. | F7: Yes | G7: Via AD authentication controls. | I7: Comment is required | K7: Comment is required
A8: AC-8.1 | B8: AC-8 | D8: System Use Notification | E8: Is there a system use notification displayed before granting access that provides privacy and security notices? | F8: No | G8: Comment is required | I8: Comment is required | K8: Comment is required
A9: AC-9.1 | B9: AC-9 | D9: Previous Logon Notification | E9: Does the system display the last user logon date and time to the user? | F9: No | G9: Comment is required | I9: Comment is required | K9: Comment is required
A10: AC-10.1 | B10: AC-10 | D10: Concurrent Session Control | E10: Does the system limit the number of concurrent sessions for the user? | F10: No | G10: Comment is required | I10: Comment is required | K10: Comment is required
A11: AC-11.1 | B11: AC-11 | C11: 164.310(b) 164.312(a)(2)(iii) | D11: Session Lock | E11: Does the application/system have a session lock after a period of inactivity that requires a user to reauthenticate? | F11: Yes | G11: Comment is required | I11: Comment is required | K11: Comment is required
A12: AC-12.1 | B12: AC-12 | C12: 164.310(b) 164.312(a)(2)(iii) | D12: Session Termination | E12: Does the application/system terminate the session after predefined circumstances? | F12: No | G12: Comment is required | I12: Comment is required | K12: Comment is required
A13: AC-14.1 | B13: AC-14 | D13: Permitted Actions without Identification or Authentication | E13: Does the system prevent user actions that can be performed on the system without identification and authentication? | F13: Yes | G13: Comment is required | I13: Comment is required | K13: Comment is required

Sheet 2. Awareness and Training
A1: Control Question # | B1: NIST SP800-53 R4: Control # | C1: HIPAA CFR Control Reference(s) | D1: Control Name | E1: Security Questions: | F1: =Scope!$B$4 & " Response:" -> PeriCALM Tracings Fetal monitoring application Response: | G1: =Scope!$B$4 &" Comments:" -> PeriCALM Tracings Fetal monitoring application Comments: | H1: =Scope!$D$4 & " Response:" -> Response: | I1: =Scope!$D$4 & " Comments:" -> Comments: | J1: =Scope!$F$4 & " Response:" -> Response: | K1: =Scope!$F$4 & " Comments:" -> Comments:
A2: Awareness and Training
A3: AT-1.1 | B3: AT-1 | C3: 164.308(a)(5)(i) | D3: Security Awareness and Training Policy and Procedures | E3: Are there formally documented procedures for security awareness and training for this information system? If yes, please attach. | F3: Yes | G3: Comment is required | I3: Comment is required | K3: Comment is required
A4: AT-2.1 | B4: AT-2 | C4: 164.308(a)(5)(i) 164.308(a)(5)(ii)(A) 164.308(a)(5)(ii)(B) | D4: Security Awareness | E4: Is basic security awareness training performed for all personnel as a part of the onboarding process? | F4: Yes | G4: Comment is required | I4: Comment is required | K4: Comment is required
A5: AT-2.2 | E5: Is it periodically performed for all users? | F5: Yes | G5: Customer responsibility to train their internal administrators/super-users to periodically train end-users | I5: Comment is required | K5: Comment is required
A6: AT-3.1 | B6: AT-3 | C6: 164.308(a)(5)(i) | D6: Role-Based Security Training | E6: Is there role-based security training for personnel with assigned security roles and responsibilities for this information system before access is granted and when required by information system changes? | F6: No | G6: All security related topics are cover during initial training and user guides | I6: Comment is required | K6: Comment is required
A7: AT-4.1 | B7: AT-4 | C7: 164.308(a)(5)(i) | D7: Security Training Records | E7: Do you document and monitor information system security training activities for individuals? | F7: No | G7: Comment is required | I7: Comment is required | K7: Comment is required

Sheet 3. Audit and Accountability
A1: Control Question # | B1: NIST SP800-53 R4: Control # | C1: HIPAA CFR Control Reference(s) | D1: Control Name | E1: Security Questions: | F1: =Scope!$B$4 & " Response:" -> PeriCALM Tracings Fetal monitoring application Response: | G1: =Scope!$B$4 &" Comments:" -> PeriCALM Tracings Fetal monitoring application Comments: | H1: =Scope!$D$4 & " Response:" -> Response: | I1: =Scope!$D$4 & " Comments:" -> Comments: | J1: =Scope!$F$4 & " Response:" -> Response: | K1: =Scope!$F$4 & " Comments:" -> Comments:
A2: Audit and Accountability
A3: AU-2.1 | B3: AU-2 | C3: 164.308(a)(5)(ii)(C) 164.312(b) | D3: Audit Events | E3: Is the information system actively auditing events such as access to patient information, login/logoffs, account creation, etc.? If yes, please detail the events captured in the comment. | F3: Yes | G3: * logon/logoff * Access from station (hostname) * Screens access by user * All data changes (old values, new values, user, dataTime) All the above include username and dataTime | I3: Comment is required | K3: Comment is required
A4: AU-2.2 | E4: Are the audit logs captured sufficient for incident response and system and user performance/investigation? | F4: Yes | G4: Comment is required | I4: Comment is required | K4: Comment is required
A5: AU-3.1 | B5: AU-3 | C5: 164.312(b) | D5: Content of Audit Records | E5: Does the system create audit records that contain sufficient information to, at a minimum, establish what type of event occurred, when the event occurred, where the event occurred, the source of the event, the outcome (success or failure) of the event, and the identity of any user/subject associated with the event? | F5: Yes | G5: Comment is required | I5: Comment is required | K5: Comment is required
A6: AU-5.1 | B6: AU-5 | D6: Response to Audit Processing Failures | E6: Does the information system generate an alert that notifies the team in the event of an audit processing failure? | F6: No | G6: Comment is required | I6: Comment is required | K6: Comment is required
A7: AU-7.1 | B7: AU-7 | C7: 164.308(a)(1)(ii)(D) 164.312(b) | D7: Audit Reduction and Report Generation | E7: Does the information system provide the capability to generate customizable audit reports? | F7: No | G7: Comment is required | I7: Comment is required | K7: Comment is required
A8: AU-7.2 | E8: Does the generation of an audit report alter the original content or time stamp of the audit record? | F8: No | G8: Comment is required | I8: Comment is required | K8: Comment is required
A9: AU-8.1 | B9: AU-8 | D9: Time Stamps | E9: Are the audit logs time stamped? (Date and Time) | F9: Yes | G9: Comment is required | I9: Comment is required | K9: Comment is required
A10: AU-9.1 | B10: AU-9 | D10: Protection of Audit Information | E10: Does the system/application protect audit information from unauthorized access, modification, and deletion? | F10: Yes | G10: Comment is required | I10: Comment is required | K10: Comment is required
A11: AU-12.1 | B11: AU-12 | D11: Audit Generation | E11: Can the information system be configured to select which auditable events are captured in the audit log? | F11: No | G11: Comment is required | I11: Comment is required | K11: Comment is required

Sheet 5. Configuration
A1: Control Question # | B1: NIST SP800-53 R4: Control # | C1: HIPAA CFR Control Reference(s) | D1: Control Name | E1: Security Questions: | F1: =Scope!$B$4 & " Response:" -> PeriCALM Tracings Fetal monitoring application Response: | G1: =Scope!$B$4 &" Comments:" -> PeriCALM Tracings Fetal monitoring application Comments: | H1: =Scope!$D$4 & " Response:" -> Response: | I1: =Scope!$D$4 & " Comments:" -> Comments: | J1: =Scope!$F$4 & " Response:" -> Response: | K1: =Scope!$F$4 & " Comments:" -> Comments:
A2: Configuration Management
A3: CM-1.1 | B3: CM-1 | D3: Configuration Management Policy and Procedures | E3: Are there documented procedures to outline who/when and how the system/application is configured? If yes, please attach | F3: Yes | G3: Comment is required | I3: Comment is required | K3: Comment is required
A4: CM-2.1 | B4: CM-2 | D4: Baseline Configuration | E4: Do you have a current configuration baseline documented for the information system? (The baseline configuration is a documented, up-to-date specification to which the information system is built.) | F4: No | G4: Configuration is a site/customer specific. The system comes with some defaults (ex: everything is logged) but other configurations like AD/LDAP servers for authentication, interfaces, bed-configurations are all done according to customer needs. | I4: Comment is required | K4: Comment is required
A5: CM-3.1 | B5: CM-3 | D5: Configuration Change Control | E5: Are types of changes to the information system that are configuration-controlled defined? | F5: No | G5: All changes to the system are coordinated with the csustomer and require customer approval. | I5: Comment is required | K5: Comment is required
A6: CM-3.2 | E6: Does the organization review proposed configuration-controlled changes to the information system, using defined security impact analyses? | F6: Yes | G6: Comment is required | I6: Comment is required | K6: Comment is required
A7: CM-3.3 | E7: Are all configuration changes adequately documented? | F7: Yes | G7: Always coordinated with the customer | I7: Comment is required | K7: Comment is required
A8: CM-3.4 | E8: Are all approved configuration controls implemented timely? | F8: Yes | G8: Always coordinated with the customer | I8: Comment is required | K8: Comment is required
A9: CM-3.5 | E9: Does the organization retain records of configuration controlled changes? | F9: Yes | G9: Records are maintained in our corporate ticketing system or as part of formal project(s) to add/change aspects of the system | I9: Comment is required | K9: Comment is required
A10: CM-3.6 | E10: Are there auditing and monitoring activities implemented to assess the configuration-controlled changes? | F10: Partial | G10: Some changes have auditable controls associated, others do not. For example, adding a mapped field from HL7. The new field will show in the audit trail but the action of adding the field in the mapping tables in the DB do not. | I10: Comment is required | K10: Comment is required
A11: CM-4.1 | B11: CM-4 | D11: Security Impact Analysis | E11: Do you analyze changes to the information system to determine potential security impacts prior to change implementation? | F11: No | I11: Comment is required | K11: Comment is required
A12: CM-6.1 | B12: CM-6 | D12: Configuration Settings | E12: Have all the configuration settings been documented that reflect the most restrictive mode consistent with operational requirements? | F12: No | G12: common best practices are used with the limited controls offered by PeriCALM Tracings | I12: Comment is required | K12: Comment is required
A13: CM-6.2 | E13: Is there any automated or manual monitoring of configuration changes? (e.g. Tripwire, manual checklists) | F13: No | G13: Comment is required | I13: Comment is required | K13: Comment is required
A14: CM-6.3 | E14: Do you document and approve deviations from the established configuration settings? | F14: No | G14: Comment is required | I14: Comment is required | K14: Comment is required
A15: CM-7.1 | B15: CM-7 | D15: Least Functionality | E15: Do you restrict or prohibit the use of any functions, ports, protocols and/or services that are not essential to the function of the information system? | F15: Yes | G15: Comment is required | I15: Comment is required | K15: Comment is required
A16: CM-8.1 | B16: CM-8 | C16: 164.310(d)(1) 164.310(d)(2)(iii) | D16: Information System Component Inventory | E16: Do you have an accurate and current documented inventory of the components within the information system? | F16: Yes | G16: Comment is required | I16: Comment is required | K16: Comment is required
A17: CM-8.2 | E17: If yes, do you review and update the information system component inventory regularly? | F17: Yes | G17: We review all components and 3rd party tools when planning major releases | I17: Comment is required | K17: Comment is required
A18: CM-9.1 | B18: CM-9 | D18: Configuration Management Plan | E18: Does the organization develop, document, and implement a configuration management plan for the information system that addresses roles, responsibilities and configuration management processes and procedures? | F18: No | G18: This is customer responsibility | I18: Comment is required | K18: Comment is required
A19: CM-9.2 | E19: Does the organization establish a process for identifying configuration items throughout the system development life cycle? | F19: Yes | G19: All configuration and development items are tracked as part of the product development process | I19: Comment is required | K19: Comment is required
A20: CM-9.3 | E20: Does the organization define configuration items for the information system? | F20: Yes | G20: Hardware specifications, data acquisition devices are documented per release and communicated to the customer when they change | I20: Comment is required | K20: Comment is required
A21: CM-9.4 | E21: Does the organization protect the configuration management plan for unauthorized disclosures and modifications? | F21: Yes | G21: Comment is required | I21: Comment is required | K21: Comment is required
A22: CM-11.1 | B22: CM-11 | D22: User-Installed Software | E22: Is user installation of software restricted and monitored? | F22: N/A | G22: Only designated PeriGen personnel or trained customer IT personnel can install elements of the system | I22: Comment is required | K22: Comment is required
A23: CM-12.1 | B23: N/A | D23: Patch Timeliness | E23: Are patches applied to the information system in a timely manner? If so, how quickly are patches applied? | F23: Yes | G23: Customer controlled | I23: Comment is required | K23: Comment is required
A24: CM-12.2 | D24: Patch Timeliness Policy | E24: Are there standards or policies which define the timing of patching the information system? | F24: No | G24: Customer controlled | I24: Comment is required | K24: Comment is required
A25: CM-13.1 | B25: N/A | D25: Patch Management Environments | E25: Do you use Development, Test, QA, and Production environments during the patch management process? If so, describe the manner in which these environment are utilized? | F25: Yes | G25: Mostly, OS hot-fixes and patches are pushed directly to all environments. PeriGen software is always loaded on the TEST system and only pushed to PROD upon customer approval | I25: Comment is required | K25: Comment is required
A26: CM-14.1 | B26: N/A | D26: Patch Classification | E26: Do you categorize patches based on severity? If yes, please provide the categories, their definitions, and the associated time frames for deploying patches to production environments. | F26: No | G26: Case by case basis | I26: Comment is required | K26: Comment is required
A27: CM-14.2 | B27: N/A | E27: Do you implement patches categorized as "critical" within 72 hours of patch release? | F27: Partial | G27: Case by case basis | I27: Comment is required | K27: Comment is required

Sheet 7. Authentication&Authorization
A1: Control Question # | B1: NIST SP800-53 R4: Control # | C1: HIPAA CFR Control Reference(s) | D1: Control Name | E1: Security Questions: | F1: =Scope!$B$4 & " Response:" -> PeriCALM Tracings Fetal monitoring application Response: | G1: =Scope!$B$4 &" Comments:" -> PeriCALM Tracings Fetal monitoring application Comments: | H1: =Scope!$D$4 & " Response:" -> Response: | I1: =Scope!$D$4 & " Comments:" -> Comments: | J1: =Scope!$F$4 & " Response:" -> Response: | K1: =Scope!$F$4 & " Comments:" -> Comments:
A2: Identification and Authentication
A3: IA-1.1 | B3: IA-1 | D3: Identification and Authentication Policy and Procedures | E3: Does the application/system use managed LDAP services for identification and authentication? If no, detail in the comment column what is used. | F3: Yes | G3: Customer responsibility to provide. PeriCALM Tracings supports authentication via LDAP | I3: Comment is required | K3: Comment is required
A4: IA-2.1 | B4: IA-2 | C4: 164.308(a)(5)(ii)(D) 164.312(a)(2)(i) 164.312(d) | D4: Identification and Authentication (Organizational Users) | E4: Does the information system use multifactor authentication for privileged or non-privileged access? (Uses at least two of: what you have, what you know, what you are. E.g., tokens, passwords, biometrics.) | F4: No | G4: Comment is required | I4: Comment is required | K4: Comment is required
A5: IA-3.1 | B5: IA-3 | C5: 164.312(a)(2)(i) 164.312(d) | D5: Device Identification and Authentication | E5: Does the information system uniquely identify and authenticate devices before establishing a connection? (E.g., MAC, TCP/IP, IEEE 802.1x) | F5: Yes | G5: All stations must be configured for access on the server. Identification is done by hostname (DNS) | I5: Comment is required | K5: Comment is required
A6: IA-4.2 | D6: Identifier Management | E6: Does the application/system prevent reuse of user or device identifiers? | F6: Yes | G6: Comment is required | I6: Comment is required | K6: Comment is required
A7: IA-4.3 | E7: Does the application/system disable the user or device account after a pre-defined period of inactivity? | F7: Yes | G7: Comment is required | I7: Comment is required | K7: Comment is required
A8: IA-5.1 | B8: IA-5 | C8: 164.308(a)(5)(ii)(D) | D8: Authenticator Management | E8: Does the application/system comply with the password complexity as outlined in implemented policies? | F8: N/A | G8: AD controlled | I8: Comment is required | K8: Comment is required
A9: IA-5.2 | E9: Does information system force the End User to comply with the following password requirements regarding complexity, length and change? - Passwords at least 8 characters in length. - Passwords contain the following: - Mixed case alpha characters - at least one numeric digit - at least one non-alphanumeric character - Current password may not be reused - Do current passwords expire every 90 days? - Are passwords stored in an encrypted format? | F9: N/A | G9: AD controlled | I9: Comment is required | K9: Comment is required
A10: IA-5.3 | E10: Are the passwords encrypted within the information system when stored or transmitted? | F10: Yes | G10: Comment is required | I10: Comment is required | K10: Comment is required
A11: IA-5.7 | E11: Is authenticator content protected from unauthorized disclosure and modification? | F11: Yes | G11: Comment is required | I11: Comment is required | K11: Comment is required
A12: IA-5.9 | E12: Is token-based authentication utilized? | F12: Yes | G12: AD controlled | I12: Comment is required | K12: Comment is required
A13: IA-6.1 | B13: IA-6 | C13: 164.308(a)(5)(ii)(D) | D13: Authenticator Feedback | E13: Does the information system obscure the authenticator/password during the authentication process? | F13: Yes | G13: Comment is required | I13: Comment is required | K13: Comment is required
A14: IA-7.1 | B14: IA-7 | C14: 164.308(a)(5)(ii)(D) | D14: Cryptographic Module Authentication | E14: Does the information system use mechanisms for authentication to a cryptographic module? (This control is used for mostly operating systems and appliances used to encrypt something.) | F14: No | G14: Comment is required | I14: Comment is required | K14: Comment is required

Sheet 8. Incident Response
A1: Control Question # | B1: NIST SP800-53 R4: Control # | C1: HIPAA CFR Control Reference(s) | D1: Control Name | E1: Security Questions: | F1: =Scope!$B$4 & " Response:" -> PeriCALM Tracings Fetal monitoring application Response: | G1: =Scope!$B$4 &" Comments:" -> PeriCALM Tracings Fetal monitoring application Comments: | H1: =Scope!$D$4 & " Response:" -> Response: | I1: =Scope!$D$4 & " Comments:" -> Comments: | J1: =Scope!$F$4 & " Response:" -> Response: | K1: =Scope!$F$4 & " Comments:" -> Comments:
A2: Incident Response
A3: IR-1.1 | B3: IR-1 | C3: 164.308(a)(6)(i) | D3: Incident Response Policies and Procedures | E3: Are there formally documented policies and procedures for Incident Response? If yes, please attach. | F3: Yes | G3: Comment is required | I3: Comment is required | K3: Comment is required
A4: IR-2.1 | B4: IR-2 | C4: 164.308(a)(6)(i) | D4: Incident Response Training | E4: Are staff provided with incident response training? | F4: Yes | G4: Comment is required | I4: Comment is required | K4: Comment is required
A5: IR-2.2 | E5: Is incident response training unique based on the role of the individual? | F5: Yes | G5: Comment is required | I5: Comment is required | K5: Comment is required
A6: IR-3.1 | B6: IR-3 | C6: 164.308(a)(6)(i) | D6: Incident Response Testing and Exercises | E6: Are incident response tests conducted? | F6: No | G6: Comment is required | I6: Comment is required | K6: Comment is required
A7: IR-3.2 | E7: Are the incident response test results analyzed? | F7: No | G7: Comment is required | I7: Comment is required | K7: Comment is required
A8: IR-4.1 | B8: IR-4 | C8: 164.308(a)(6)(ii) | D8: Incident Handling | E8: Is there an incident handling process | F8: Yes | G8: Comment is required | I8: Comment is required | K8: Comment is required
A9: IR-5.1 | B9: IR-5 | C9: 164.308(a)(1)(ii)(D) 164.308(a)(6)(ii) | D9: Incident Monitoring | E9: Are security incidents tracked and documented? | F9: Yes | G9: Comment is required | I9: Comment is required | K9: Comment is required
A10: IR-6.1 | B10: IR-6 | C10: 164.308(a)(1)(ii)(D) 164.308(a)(6)(ii) 164.314(a)(2)(i) | D10: Incident Reporting | E10: Are security incidents timely reported to appropriate personnel/ government authorities? | F10: Yes | G10: Comment is required | I10: Comment is required | K10: Comment is required
A11: IR-7.1 | B11: IR-7 | C11: 164.308(a)(6)(ii) | D11: Incident Response Assistance | E11: Are incident response resources used outside of the incident response team? | F11: Yes | G11: If required. Case by case basis. | I11: Comment is required | K11: Comment is required
A12: IR-8.1 | B12: IR-8 | D12: Incident Response Plan | E12: Is there a comprehensive Incident Response Plan? If so, please attach. | F12: Yes | G12: see internal policy | I12: Comment is required | K12: Comment is required
A13: IR-9.1 | B13: IR-9 | D13: Information Spillage Response | E13: Does the organization respond to information spillage appropriately and timely? | F13: Yes | G13: Comment is required | I13: Comment is required | K13: Comment is required

Sheet 9. Maintenance
A1: Control Question # | B1: NIST SP800-53 R4: Control # | C1: HIPAA CFR Control Reference(s) | D1: Control Name | E1: Security Questions: | F1: =Scope!$B$4 & " Response:" -> PeriCALM Tracings Fetal monitoring application Response: | G1: =Scope!$B$4 &" Comments:" -> PeriCALM Tracings Fetal monitoring application Comments: | H1: =Scope!$D$4 & " Response:" -> Response: | I1: =Scope!$D$4 & " Comments:" -> Comments: | J1: =Scope!$F$4 & " Response:" -> Response: | K1: =Scope!$F$4 & " Comments:" -> Comments:
A2: Maintenance
A3: MA-1.1 | B3: MA-1 | C3: 164.310(a)(2)(iv) | D3: System Maintenance Policy and Procedures | E3: Are there formally documented policies and procedures for Maintenance? If yes, please attach. | F3: Yes | G3: PeriGen does not provide propriatary internal QMS documents | I3: Comment is required | K3: Comment is required
