Workbook
Name RequestedBy: Labels!$A$8:$A$9
Name ReviewType: Labels!$A$1:$A$3
Name Risk: Labels!$A$11:$A$14
Name YesNo: Labels!$A$5:$A$6

Sheet Instructions
B1: NYC Health + Hospitals (the System) Risk Assessment Questionnaire Ver. 3.0e
B4: As part of NYC Health + Hospitals (the System) RFP / Business Request process, the System reviews security and compliance controls for all applications and solutions.
B5: Application Risk Review Questionnaire
A6: 1 | B6: PM fills out header metadata
A7: 2 | B7: Business Unit Owners should fill out Section 1 of the Application Questionnaire in the column provided.
A8: 3 | B8: Third party Vendors should fill out all relevant section of the Application Questionnaire in the column provided.

Sheet ApplicationQuestionnaire
C1: NYC Health + Hospitals (the System) Application Review / Risk Assessment Questionnaire Ver. 3.0f The System's Business Owner should answer Section 1, and Vendor should answer the remaining sections Please answer all questions completely, in the appropriate cell. Where appropriate, please attach suppporting documentation. PLEASE NOTE: The name "the System" refers to NYC Health + Hospitals
B3: Application / System Name | C3: PeriGen Fetal Monitoring System | D3: Business Owner | E3: Wendy Wilcox | F3: Demand Number | G3: DMND000013259
B4: Description | C4: Software for fetal monitoring system with decision support | D4: Project Manager: | E4: Shamise Quinn | F4: ePHI Storage
D5: EITS Owner: | E5: Julio Santos | F5: ePHI Transfer
B6: Architectural Diagram Included | C6: Yes | D6: Vendor Contact: | F6: Externally Hosted
B7: Data Flow Diagram Included | C7: Yes
B8: Date Review Questionnaire Sent to Vendor: | D8: Risk Reviewer: | F8: ISRM Approval
B9: Date Review Questionnaire Received From Vendor: | C9: Feb 23 2024 | D9: Compliance Reviewer: | F9: OCC Approval
A11: Control ID | B11: Section | C11: Vendor Response | D11: Business Response | E11: Risk Assessor Notes | F11: Risk Assessor Notes | G11: OCC Notes | H11: Risk | I11: Requirements | J11: Likelihood | K11: Impact | L11: Risk | M11: Risk Score
B12: Section 1 Business
A13: BR | B13: Business Requirements
A14: BR-01 | B14: What is the primary business purpose of the solution or application? | C14: PeriWatch Surveillance is an advanced fetal surveillance and documentation system that incorporates the only automated maternal-fetal early warning system commercially available in the U.S. The systems features near real-time analytical tools and scalable workflows to help labor and delivery teams imporve productivity and efficiency, standardize communicaiton and make informed decisions. | D14: PeriWatch Surveillance is an advanced fetal surveillance and documentation system that incorporates the only automated maternal-fetal early warning system commercially available in the U.S. The systems features near real-time analytical tools and scalable workflows to help labor and delivery teams imporve productivity and efficiency, standardize communicaiton and make informed decisions.
A15: BR-02 | B15: What are the main functions of the solution or application? | C15: The main function of the application is to provide a view for clinical staff to see patient tracings, annotations and early warning alerts to help improve birthing outcomes. | D15: The main functions of the application software are to monitor the fetal heart rate and use AI generated algorithms to help the clinician interpret fetal heart classification. Additionally, communication is standardized and lessens the burden on nursing documentation. Improves productivity. Uses AI generated algorithmns to identify patients who may be at risk for adverse outcomes.
A16: BR-03 | B16: Which of the System's business units is the owner of application? | D16: Medical and Professional Affairs, Office of Women's Health, Obstetrics and Gynecology
A17: BR-04 | B17: Which of the System's facilities will the application serve? | C17: Labor and delivery units | D17: The application will serve all 11 acute care maternity hospitals.
A18: DG | B18: Data Governance | C18: Vendor Response | D18: Business Response | E18: Risk Assessor Notes | F18: Risk Assessor Notes | G18: OCC Notes | H18: Risk | I18: Requirements | J18: Likelihood | K18: Impact | L18: Risk | M18: Risk Score
A19: DG-01 | B19: Which of the System's business unit is the data owner? Are there multiple business units that own the data? | C19: N/A | D19: Medical and Professional Affairs, Office of Women's Health, Obstetrics and Gynecology
A20: DG-02 | B20: What data does the application receive, process, and / or produce? (eg. Medical (ePHI), Personnel, Financial etc.) | C20: Medical PHI is sent via HL7 interfaces from Epic to PeriWatch | D20: The application interfaces with Epic. It receives Medical PHI.
A21: DG-02a | B21: Provide details (a sample data set). | D21: n/a
A22: DG-02b | B22: Are SSNs (full or redacted) needed for the business purpose for this data transfer? If yes, why? Can a redacted format suffice? | C22: Not needed but can be interfaced. | D22: Will ask vendor. Probably not.
A23: DG-03 | B23: If data is not PHI, is it considered business sensitive or confidential? | D23: N/A
A24: DG-04 | B24: If the data in the application is compromised how does it impact the System? (eg. Breach notification required or Reputational damage, etc.) | C24: All data is stored on customer site within a DB. If the DB was compromised(encrypted by ransomware) the application would be inoperable at that time. | D24: Requires discussion with vendor.
A25: EU | B25: End Users | C25: Vendor Response | D25: Business Response | E25: Risk Assessor Notes | F25: Risk Assessor Notes | G25: OCC Notes | H25: Risk | I25: Requirements | J25: Likelihood | K25: Impact | L25: Risk | M25: Risk Score
A26: EU-01 | B26: Who are the application’s end users? (eg. business units, external users, etc.) | C26: Clinical staff | D26: Clinical providers and nurses in the obstetrical areas.
A27: EU-02 | B27: How do the end users access and interact (via web etc.) with the application? | C27: PeriWatch has a thick client that can be installed on the PC or pushed through Citrix to the users. On the Vigilance side, access is via HTTPS. | D27: The end users access and interact with the application either through Epic or through the client application.
A28: EU-03 | B28: What are the security expectations from the end users? | D28: Follow H+H policy.
A29: TP | B29: Third Party Vendor | C29: Vendor Response | D29: Business Response | E29: Risk Assessor Notes | F29: Risk Assessor Notes | G29: OCC Notes | H29: Risk | I29: Requirements | J29: Likelihood | K29: Impact | L29: Risk | M29: Risk Score
A30: TP-01 | B30: Are there any third parties that receive or process data to or from the application? If yes, Who? | C30: No | D30: Requires vendor discussion. Possibly no.
A31: TP-02 | B31: What methods or mechanisms are used to share data with third parties? (eg. FTP, SFTP, RDP, SecureLink, etc.) | C31: N/A | D31: Requires vendor discussion, if applicable.
A32: TP-03 | B32: Has the vendor signed the the System's standard BAA (Business Associate Agreement)? If yes, please provide a copy. If no, please contact Supply Chain. | C32: Not as of the filing of this questionnaire | D32: No. Information with Supply Chain department in progress.
A33: AD | B33: Administrators | C33: Vendor Response | D33: Business Response | E33: Risk Assessor Notes | F33: Risk Assessor Notes | G33: OCC Notes | H33: Risk | I33: Requirements | J33: Likelihood | K33: Impact | L33: Risk | M33: Risk Score
A34: AD-01 | B34: Does vendor retain administrative privileges to the application? | C34: Yes | D34: Yes, requires vendor discussion.
A35: AD-02 | B35: What administrative roles or functions does the application offer? | C35: Roles can be created based upon desired access. The roles are customizable on the backend. | D35: Requires vendor discussion.
A36: AD-02a | B36: Provide RBAC model for the Administrative functions. | D36: ???
A37: RG | B37: Regulations | C37: Vendor Response | D37: Business Response | E37: Risk Assessor Notes | F37: Risk Assessor Notes | G37: OCC Notes | H37: Risk | I37: Requirements | J37: Likelihood | K37: Impact | L37: Risk | M37: Risk Score
A38: RG-01 | B38: Which industries does the application pertain to? | C38: Perinatal Software Development | D38: Perinatal medicine/Women's Health
A39: RG-02 | B39: Which regulations does the application adhere to? (eg. HIPAA, HITECH, etc. ) | C39: HIPAA | D39: HIPAA
B40: Section 2 Infrastructure
A41: SN | B41: Systems & Network | C41: Vendor Response | D41: Business Response | E41: Risk Assessor Notes | F41: Risk Assessor Notes | G41: OCC Notes | H41: Risk | I41: Requirements | J41: Likelihood | K41: Impact | L41: Risk | M41: Risk Score
A42: SN-01 | B42: Does the application run on a local workstation or an on-premise server platform? | C42: Application is installed on Windows Server, on-premise to the client. | L42: =IF(M42=0,"",IF(M42<3,"Low",IF(M42<6,"Medium","High"))) | M42: =PRODUCT(N42:O42) -> 0 | N42: =IF(J42="Low",1,IF(J42="Medium",2,IF(J42="High",3,0))) -> 0 | O42: =IF(K42="Low",1,IF(K42="Medium",2,IF(K42="High",3,0))) -> 0
...

Sheet Risk Matrix
A1: H+H Standard | B1: Security Controls | C1: Likelihood | D1: Impact | E1: Risk | F1: Risk Score
B2: =ApplicationQuestionnaire!B50 -> Supported infrastructure | C2: =ApplicationQuestionnaire!J50 -> 0 | D2: =ApplicationQuestionnaire!K50 -> 0 | E2: =ApplicationQuestionnaire!L50 -> 0 | F2: =ApplicationQuestionnaire!M50 -> 0
B3: =ApplicationQuestionnaire!B55 -> Supported remote acccess | C3: =ApplicationQuestionnaire!J55 -> 0 | D3: =ApplicationQuestionnaire!K55 -> 0 | E3: =ApplicationQuestionnaire!L55 | F3: =ApplicationQuestionnaire!M55 -> 0
B4: =ApplicationQuestionnaire!B65 -> Business Continuity and Disaster Recovery plans defined and implemented | C4: =ApplicationQuestionnaire!J65 -> 0 | D4: =ApplicationQuestionnaire!K65 -> 0 | E4: =ApplicationQuestionnaire!L65 | F4: =ApplicationQuestionnaire!M65 -> 0
B5: =ApplicationQuestionnaire!B88 -> Cloud Compliance (Application is ISO 27001, ISO 27018, SOC2, FedRAMP certified) | C5: =ApplicationQuestionnaire!J88 -> 0 | D5: =ApplicationQuestionnaire!K88 -> 0 | E5: =ApplicationQuestionnaire!L88 | F5: =ApplicationQuestionnaire!M88 -> 0
B6: =ApplicationQuestionnaire!B93 -> Standard data transfer method | C6: =ApplicationQuestionnaire!J93 -> 0 | D6: =ApplicationQuestionnaire!K93 -> 0 | E6: =ApplicationQuestionnaire!L93 | F6: =ApplicationQuestionnaire!M93 -> 0
B7: =ApplicationQuestionnaire!B106 -> Industry standard Software Development Life Cycle (SDLC) methodology used | C7: =ApplicationQuestionnaire!J106 -> 0 | D7: =ApplicationQuestionnaire!K106 -> 0 | E7: =ApplicationQuestionnaire!L106 | F7: =ApplicationQuestionnaire!M106 -> 0
B8: =ApplicationQuestionnaire!B130 -> Standards compliant encryption used for data-at-rest and data-in-motion | C8: =ApplicationQuestionnaire!J130 -> 0 | D8: =ApplicationQuestionnaire!K130 -> 0 | E8: =ApplicationQuestionnaire!L130 | F8: =ApplicationQuestionnaire!M130 -> 0
B9: =ApplicationQuestionnaire!B150 -> Active Directory integration supported | C9: =ApplicationQuestionnaire!J150 -> 0 | D9: =ApplicationQuestionnaire!K150 -> 0 | E9: =ApplicationQuestionnaire!L150 | F9: =ApplicationQuestionnaire!M150 -> 0
B10: =ApplicationQuestionnaire!B163 -> Security monitoring and audit well defined (Integration with SIEM/PPM supported) | C10: =ApplicationQuestionnaire!J163 -> 0 | D10: =ApplicationQuestionnaire!K163 -> 0 | E10: =ApplicationQuestionnaire!L163 | F10: =ApplicationQuestionnaire!M163 -> 0
B11: =ApplicationQuestionnaire!B170 -> Industry standard application security guidelines followed (Eg OWASP top 10 etc) | C11: =ApplicationQuestionnaire!J170 -> 0 | D11: =ApplicationQuestionnaire!K170 -> 0 | E11: =ApplicationQuestionnaire!L170 | F11: =ApplicationQuestionnaire!M170 -> 0
B12: =ApplicationQuestionnaire!B180 -> Vulnerability scans, penetration assessment peformed, issues remediated | C12: =ApplicationQuestionnaire!J180 -> 0 | D12: =ApplicationQuestionnaire!K180 -> 0 | E12: =ApplicationQuestionnaire!L180 | F12: =ApplicationQuestionnaire!M180 -> 0
B13: =ApplicationQuestionnaire!B192 -> Data Integrity controls | C13: =ApplicationQuestionnaire!J192 -> 0 | D13: =ApplicationQuestionnaire!K192 -> 0 | E13: =ApplicationQuestionnaire!L192 | F13: =ApplicationQuestionnaire!M192 -> 0
B14: =ApplicationQuestionnaire!B200 -> Vendor has well defined change management program | C14: =ApplicationQuestionnaire!J200 -> 0 | D14: =ApplicationQuestionnaire!K200 -> 0 | E14: =ApplicationQuestionnaire!L200 | F14: =ApplicationQuestionnaire!M200 -> 0
B15: =ApplicationQuestionnaire!B203 -> Well has well defined Incident management program | C15: =ApplicationQuestionnaire!J203 -> 0 | D15: =ApplicationQuestionnaire!K203 -> 0 | E15: =ApplicationQuestionnaire!L203 | F15: =ApplicationQuestionnaire!M203 -> 0
B16: =ApplicationQuestionnaire!B213 -> Vendor has formalized information security program and undergoes third party assessments at least annually | C16: =ApplicationQuestionnaire!J213 -> 0 | D16: =ApplicationQuestionnaire!K213 -> 0 | E16: =ApplicationQuestionnaire!L213 | F16: =ApplicationQuestionnaire!M213 -> 0
C17: Max Risk Score | F17: =MAX(F2:F16) -> 0
C18: Risk Threshold | F18: 6
C19: Review Status | F19: =IF(F17<=F18,"Approved","Not Approved") -> Approved
C21: Likelihood | Impact | D21: Low | E21: Medium | F21: High
C22: High | D22: 3 | E22: 6 | F22: 9
C23: Medium | D23: 2 | E23: 4 | F23: 6
C24: Low | D24: 1 | E24: 2 | F24: 3

Sheet ApprovalRequirements
C1: NYC Health + Hospitals (the System) Risk Assessment Approval Ver. 3.0f The solution described below is approved, subject to satisfactory completion of the listed requirements.
B3: Solution Name | C3: =ApplicationQuestionnaire!C3 -> PeriGen Fetal Monitoring System | D3: Business Owner | E3: =ApplicationQuestionnaire!E3 -> Wendy Wilcox | F3: Overall Risk Rating
B4: Assessement Type | C4: Application/System | D4: Project Manager: | E4: =ApplicationQuestionnaire!E4 -> Shamise Quinn | F4: Stores ePHI | G4: =ApplicationQuestionnaire!G4 -> 0
B5: Vendor Name | D5: EITS Owner: | E5: =ApplicationQuestionnaire!E5 -> Julio Santos | F5: ePHI Transfer | G5: =ApplicationQuestionnaire!G5 -> 0
B6: Vendor Contact | C6: =ApplicationQuestionnaire!E6 -> 0 | D6: Demand Number | E6: =ApplicationQuestionnaire!G3 -> DMND000013259 | F6: Externally Hosted | G6: =ApplicationQuestionnaire!G6 -> 0
B7: Date of Risk Assessors Review: | D7: Risk Reviewer: | E7: =ApplicationQuestionnaire!E8 -> 0 | F7: ISRM Approval | G7: =ApplicationQuestionnaire!G8 -> 0
B8: Date of Compliance Review: | D8: Compliance Reviewer: | E8: =ApplicationQuestionnaire!E9 -> 0 | F8: OCC Approval | G8: =ApplicationQuestionnaire!G9 -> 0
B9: Date all Approval Requirements Completed
B11: Approval Summary Comments
A13: Control ID | B13: Requirement | C13: Owner | D13: Requested by | E13: Required before testing? | F13: Due Date | G13: Actual Completion Date
B14: Actual requirements
A15: REQ-01
A16: REQ-02
A17: REQ-03
A18: REQ-04
A19: REQ-05
A20: REQ-06
A21: REQ-07
A22: REQ-08
A23: REQ-09
A24: REQ-10
A25: REQ-11
A26: REQ-12
... A64: REQ-50

Sheet Labels
A1: Application/System
A2: Device
A3: Data Transfer
A5: Yes
A6: No
A8: ISRM
A9: OCC
A11: N/A
A12: High
A13: Medium
A14: Low
